[Sun Aug 28 22:44:39.628128 2016] [ssl:warn] [pid 1537:tid 140538240235392] AH01909: RSA certificate configured for localhost:443 does NOT include an ID which matches the server name
[Sun Aug 28 22:44:39.644979 2016] [ssl:warn] [pid 1538:tid 140538240235392] AH01909: RSA certificate configured for localhost:443 does NOT include an ID which matches the server name
[Sun Aug 28 22:44:51.981324 2016] [:error] [pid 1542:tid 140537982060288] [client 10.0.2.2:52113] mod_wsgi (pid=1542): Exception occurred processing WSGI script '/var/www/virginia/server.wsgi'.
[Sun Aug 28 22:44:51.981491 2016] [:error] [pid 1542:tid 140537982060288] [client 10.0.2.2:52113] Traceback (most recent call last):
[Sun Aug 28 22:44:51.981625 2016] [:error] [pid 1542:tid 140537982060288] [client 10.0.2.2:52113]   File "/usr/local/lib/python2.7/dist-packages/flask/app.py", line 2000, in __call__
[Sun Aug 28 22:44:51.982439 2016] [:error] [pid 1542:tid 140537982060288] [client 10.0.2.2:52113]     return self.wsgi_app(environ, start_response)
[Sun Aug 28 22:44:51.982523 2016] [:error] [pid 1542:tid 140537982060288] [client 10.0.2.2:52113]   File "/usr/local/lib/python2.7/dist-packages/flask/app.py", line 1991, in wsgi_app
[Sun Aug 28 22:44:51.982601 2016] [:error] [pid 1542:tid 140537982060288] [client 10.0.2.2:52113]     response = self.make_response(self.handle_exception(e))
[Sun Aug 28 22:44:51.982689 2016] [:error] [pid 1542:tid 140537982060288] [client 10.0.2.2:52113]   File "/usr/local/lib/python2.7/dist-packages/flask_restful/__init__.py", line 271, in error_router
[Sun Aug 28 22:44:51.983241 2016] [:error] [pid 1542:tid 140537982060288] [client 10.0.2.2:52113]     return original_handler(e)
[Sun Aug 28 22:44:51.983324 2016] [:error] [pid 1542:tid 140537982060288] [client 10.0.2.2:52113]   File "/usr/local/lib/python2.7/dist-packages/flask/app.py", line 1567, in handle_exception
[Sun Aug 28 22:44:51.983413 2016] [:error] [pid 1542:tid 140537982060288] [client 10.0.2.2:52113]     reraise(exc_type, exc_value, tb)
[Sun Aug 28 22:44:51.983528 2016] [:error] [pid 1542:tid 140537982060288] [client 10.0.2.2:52113]   File "/usr/local/lib/python2.7/dist-packages/flask_restful/__init__.py", line 268, in error_router
[Sun Aug 28 22:44:51.983605 2016] [:error] [pid 1542:tid 140537982060288] [client 10.0.2.2:52113]     return self.handle_error(e)
[Sun Aug 28 22:44:51.983714 2016] [:error] [pid 1542:tid 140537982060288] [client 10.0.2.2:52113]   File "/usr/local/lib/python2.7/dist-packages/flask/app.py", line 1988, in wsgi_app
[Sun Aug 28 22:44:51.983807 2016] [:error] [pid 1542:tid 140537982060288] [client 10.0.2.2:52113]     response = self.full_dispatch_request()
[Sun Aug 28 22:44:51.983922 2016] [:error] [pid 1542:tid 140537982060288] [client 10.0.2.2:52113]   File "/usr/local/lib/python2.7/dist-packages/flask/app.py", line 1641, in full_dispatch_request
[Sun Aug 28 22:44:51.984040 2016] [:error] [pid 1542:tid 140537982060288] [client 10.0.2.2:52113]     rv = self.handle_user_exception(e)
[Sun Aug 28 22:44:51.984155 2016] [:error] [pid 1542:tid 140537982060288] [client 10.0.2.2:52113]   File "/usr/local/lib/python2.7/dist-packages/flask_restful/__init__.py", line 271, in error_router
[Sun Aug 28 22:44:51.984233 2016] [:error] [pid 1542:tid 140537982060288] [client 10.0.2.2:52113]     return original_handler(e)
[Sun Aug 28 22:44:51.984342 2016] [:error] [pid 1542:tid 140537982060288] [client 10.0.2.2:52113]   File "/usr/local/lib/python2.7/dist-packages/flask/app.py", line 1544, in handle_user_exception
[Sun Aug 28 22:44:51.984455 2016] [:error] [pid 1542:tid 140537982060288] [client 10.0.2.2:52113]     reraise(exc_type, exc_value, tb)
[Sun Aug 28 22:44:51.984525 2016] [:error] [pid 1542:tid 140537982060288] [client 10.0.2.2:52113]   File "/usr/local/lib/python2.7/dist-packages/flask_restful/__init__.py", line 268, in error_router
[Sun Aug 28 22:44:51.984596 2016] [:error] [pid 1542:tid 140537982060288] [client 10.0.2.2:52113]     return self.handle_error(e)
[Sun Aug 28 22:44:51.984662 2016] [:error] [pid 1542:tid 140537982060288] [client 10.0.2.2:52113]   File "/usr/local/lib/python2.7/dist-packages/flask/app.py", line 1639, in full_dispatch_request
[Sun Aug 28 22:44:51.984805 2016] [:error] [pid 1542:tid 140537982060288] [client 10.0.2.2:52113]     rv = self.dispatch_request()
[Sun Aug 28 22:44:51.984889 2016] [:error] [pid 1542:tid 140537982060288] [client 10.0.2.2:52113]   File "/usr/local/lib/python2.7/dist-packages/flask/app.py", line 1625, in dispatch_request
[Sun Aug 28 22:44:51.984972 2016] [:error] [pid 1542:tid 140537982060288] [client 10.0.2.2:52113]     return self.view_functions[rule.endpoint](**req.view_args)
[Sun Aug 28 22:44:51.985051 2016] [:error] [pid 1542:tid 140537982060288] [client 10.0.2.2:52113]   File "/usr/local/lib/python2.7/dist-packages/flask_restful/__init__.py", line 477, in wrapper
[Sun Aug 28 22:44:51.985130 2016] [:error] [pid 1542:tid 140537982060288] [client 10.0.2.2:52113]     resp = resource(*args, **kwargs)
[Sun Aug 28 22:44:51.985206 2016] [:error] [pid 1542:tid 140537982060288] [client 10.0.2.2:52113]   File "/usr/local/lib/python2.7/dist-packages/flask/views.py", line 84, in view
[Sun Aug 28 22:44:51.985545 2016] [:error] [pid 1542:tid 140537982060288] [client 10.0.2.2:52113]     return self.dispatch_request(*args, **kwargs)
[Sun Aug 28 22:44:51.985625 2016] [:error] [pid 1542:tid 140537982060288] [client 10.0.2.2:52113]   File "/usr/local/lib/python2.7/dist-packages/flask_restful/__init__.py", line 587, in dispatch_request
[Sun Aug 28 22:44:51.985707 2016] [:error] [pid 1542:tid 140537982060288] [client 10.0.2.2:52113]     resp = meth(*args, **kwargs)
[Sun Aug 28 22:44:51.985782 2016] [:error] [pid 1542:tid 140537982060288] [client 10.0.2.2:52113]   File "/var/www/virginia/resources/monologue.py", line 68, in post
[Sun Aug 28 22:44:51.987259 2016] [:error] [pid 1542:tid 140537982060288] [client 10.0.2.2:52113]     return json.dumps(self.processor.process(plot, json_data['monologue']))
[Sun Aug 28 22:44:51.987361 2016] [:error] [pid 1542:tid 140537982060288] [client 10.0.2.2:52113]   File "/var/www/virginia/processors/stanford_processor.py", line 41, in process
[Sun Aug 28 22:44:51.988519 2016] [:error] [pid 1542:tid 140537982060288] [client 10.0.2.2:52113]     self.result['out'] = self._strategy.apply(plot,self._context)
[Sun Aug 28 22:44:51.988590 2016] [:error] [pid 1542:tid 140537982060288] [client 10.0.2.2:52113]   File "/var/www/virginia/strategy/weighted_match.py", line 22, in apply
[Sun Aug 28 22:44:51.989624 2016] [:error] [pid 1542:tid 140537982060288] [client 10.0.2.2:52113]     self.__generatePipeline()
[Sun Aug 28 22:44:51.989693 2016] [:error] [pid 1542:tid 140537982060288] [client 10.0.2.2:52113]   File "/var/www/virginia/strategy/weighted_match.py", line 28, in __generatePipeline
[Sun Aug 28 22:44:51.990013 2016] [:error] [pid 1542:tid 140537982060288] [client 10.0.2.2:52113]     self._pipeline['remaining'] = self._plot.all()
[Sun Aug 28 22:44:51.990081 2016] [:error] [pid 1542:tid 140537982060288] [client 10.0.2.2:52113]   File "/var/www/virginia/narrative/plot.py", line 75, in all
[Sun Aug 28 22:44:51.991094 2016] [:error] [pid 1542:tid 140537982060288] [client 10.0.2.2:52113]     tupl = (character,self.__underlyingPlot['identification'][idx],self.__underlyingPlot['synesthesia'][idx])
[Sun Aug 28 22:44:51.991182 2016] [:error] [pid 1542:tid 140537982060288] [client 10.0.2.2:52113] NameError: global name 'idx' is not defined
[Sun Aug 28 22:46:00.035569 2016] [ssl:warn] [pid 1538:tid 140538240235392] AH01909: RSA certificate configured for localhost:443 does NOT include an ID which matches the server name
[Sun Aug 28 22:48:01.238231 2016] [ssl:warn] [pid 1538:tid 140538240235392] AH01909: RSA certificate configured for localhost:443 does NOT include an ID which matches the server name
[Sun Aug 28 22:49:01.049641 2016] [ssl:warn] [pid 1538:tid 140538240235392] AH01909: RSA certificate configured for localhost:443 does NOT include an ID which matches the server name
[Sun Aug 28 22:50:36.739610 2016] [ssl:warn] [pid 1538:tid 140538240235392] AH01909: RSA certificate configured for localhost:443 does NOT include an ID which matches the server name
[Sun Aug 28 22:54:30.969248 2016] [ssl:warn] [pid 1538:tid 140538240235392] AH01909: RSA certificate configured for localhost:443 does NOT include an ID which matches the server name
[Sun Aug 28 22:57:22.222028 2016] [ssl:warn] [pid 1538:tid 140538240235392] AH01909: RSA certificate configured for localhost:443 does NOT include an ID which matches the server name
[Sun Aug 28 22:57:31.935631 2016] [:error] [pid 2168:tid 140538007238400] [client 10.0.2.2:54595] mod_wsgi (pid=2168): Exception occurred processing WSGI script '/var/www/virginia/server.wsgi'.
[Sun Aug 28 22:57:31.935824 2016] [:error] [pid 2168:tid 140538007238400] [client 10.0.2.2:54595] Traceback (most recent call last):
[Sun Aug 28 22:57:31.935941 2016] [:error] [pid 2168:tid 140538007238400] [client 10.0.2.2:54595]   File "/usr/local/lib/python2.7/dist-packages/flask/app.py", line 2000, in __call__
[Sun Aug 28 22:57:31.936730 2016] [:error] [pid 2168:tid 140538007238400] [client 10.0.2.2:54595]     return self.wsgi_app(environ, start_response)
[Sun Aug 28 22:57:31.936809 2016] [:error] [pid 2168:tid 140538007238400] [client 10.0.2.2:54595]   File "/usr/local/lib/python2.7/dist-packages/flask/app.py", line 1991, in wsgi_app
[Sun Aug 28 22:57:31.936886 2016] [:error] [pid 2168:tid 140538007238400] [client 10.0.2.2:54595]     response = self.make_response(self.handle_exception(e))
[Sun Aug 28 22:57:31.936955 2016] [:error] [pid 2168:tid 140538007238400] [client 10.0.2.2:54595]   File "/usr/local/lib/python2.7/dist-packages/flask_restful/__init__.py", line 271, in error_router
[Sun Aug 28 22:57:31.938049 2016] [:error] [pid 2168:tid 140538007238400] [client 10.0.2.2:54595]     return original_handler(e)
[Sun Aug 28 22:57:31.938122 2016] [:error] [pid 2168:tid 140538007238400] [client 10.0.2.2:54595]   File "/usr/local/lib/python2.7/dist-packages/flask/app.py", line 1567, in handle_exception
[Sun Aug 28 22:57:31.938196 2016] [:error] [pid 2168:tid 140538007238400] [client 10.0.2.2:54595]     reraise(exc_type, exc_value, tb)
[Sun Aug 28 22:57:31.938262 2016] [:error] [pid 2168:tid 140538007238400] [client 10.0.2.2:54595]   File "/usr/local/lib/python2.7/dist-packages/flask_restful/__init__.py", line 268, in error_router
[Sun Aug 28 22:57:31.938335 2016] [:error] [pid 2168:tid 140538007238400] [client 10.0.2.2:54595]     return self.handle_error(e)
[Sun Aug 28 22:57:31.938403 2016] [:error] [pid 2168:tid 140538007238400] [client 10.0.2.2:54595]   File "/usr/local/lib/python2.7/dist-packages/flask/app.py", line 1988, in wsgi_app
[Sun Aug 28 22:57:31.938476 2016] [:error] [pid 2168:tid 140538007238400] [client 10.0.2.2:54595]     response = self.full_dispatch_request()
[Sun Aug 28 22:57:31.938543 2016] [:error] [pid 2168:tid 140538007238400] [client 10.0.2.2:54595]   File "/usr/local/lib/python2.7/dist-packages/flask/app.py", line 1641, in full_dispatch_request
[Sun Aug 28 22:57:31.938614 2016] [:error] [pid 2168:tid 140538007238400] [client 10.0.2.2:54595]     rv = self.handle_user_exception(e)
[Sun Aug 28 22:57:31.938680 2016] [:error] [pid 2168:tid 140538007238400] [client 10.0.2.2:54595]   File "/usr/local/lib/python2.7/dist-packages/flask_restful/__init__.py", line 271, in error_router
[Sun Aug 28 22:57:31.938784 2016] [:error] [pid 2168:tid 140538007238400] [client 10.0.2.2:54595]     return original_handler(e)
[Sun Aug 28 22:57:31.938853 2016] [:error] [pid 2168:tid 140538007238400] [client 10.0.2.2:54595]   File "/usr/local/lib/python2.7/dist-packages/flask/app.py", line 1544, in handle_user_exception
[Sun Aug 28 22:57:31.938924 2016] [:error] [pid 2168:tid 140538007238400] [client 10.0.2.2:54595]     reraise(exc_type, exc_value, tb)
[Sun Aug 28 22:57:31.938989 2016] [:error] [pid 2168:tid 140538007238400] [client 10.0.2.2:54595]   File "/usr/local/lib/python2.7/dist-packages/flask_restful/__init__.py", line 268, in error_router
[Sun Aug 28 22:57:31.939059 2016] [:error] [pid 2168:tid 140538007238400] [client 10.0.2.2:54595]     return self.handle_error(e)
[Sun Aug 28 22:57:31.939124 2016] [:error] [pid 2168:tid 140538007238400] [client 10.0.2.2:54595]   File "/usr/local/lib/python2.7/dist-packages/flask/app.py", line 1639, in full_dispatch_request
[Sun Aug 28 22:57:31.939259 2016] [:error] [pid 2168:tid 140538007238400] [client 10.0.2.2:54595]     rv = self.dispatch_request()
[Sun Aug 28 22:57:31.939326 2016] [:error] [pid 2168:tid 140538007238400] [client 10.0.2.2:54595]   File "/usr/local/lib/python2.7/dist-packages/flask/app.py", line 1625, in dispatch_request
[Sun Aug 28 22:57:31.939400 2016] [:error] [pid 2168:tid 140538007238400] [client 10.0.2.2:54595]     return self.view_functions[rule.endpoint](**req.view_args)
[Sun Aug 28 22:57:31.939467 2016] [:error] [pid 2168:tid 140538007238400] [client 10.0.2.2:54595]   File "/usr/local/lib/python2.7/dist-packages/flask_restful/__init__.py", line 477, in wrapper
[Sun Aug 28 22:57:31.939537 2016] [:error] [pid 2168:tid 140538007238400] [client 10.0.2.2:54595]     resp = resource(*args, **kwargs)
[Sun Aug 28 22:57:31.939605 2016] [:error] [pid 2168:tid 140538007238400] [client 10.0.2.2:54595]   File "/usr/local/lib/python2.7/dist-packages/flask/views.py", line 84, in view
[Sun Aug 28 22:57:31.939876 2016] [:error] [pid 2168:tid 140538007238400] [client 10.0.2.2:54595]     return self.dispatch_request(*args, **kwargs)
[Sun Aug 28 22:57:31.939946 2016] [:error] [pid 2168:tid 140538007238400] [client 10.0.2.2:54595]   File "/usr/local/lib/python2.7/dist-packages/flask_restful/__init__.py", line 587, in dispatch_request
[Sun Aug 28 22:57:31.940020 2016] [:error] [pid 2168:tid 140538007238400] [client 10.0.2.2:54595]     resp = meth(*args, **kwargs)
[Sun Aug 28 22:57:31.940089 2016] [:error] [pid 2168:tid 140538007238400] [client 10.0.2.2:54595]   File "/var/www/virginia/resources/monologue.py", line 68, in post
[Sun Aug 28 22:57:31.941465 2016] [:error] [pid 2168:tid 140538007238400] [client 10.0.2.2:54595]     return json.dumps(self.processor.process(plot, json_data['monologue']))
[Sun Aug 28 22:57:31.941536 2016] [:error] [pid 2168:tid 140538007238400] [client 10.0.2.2:54595]   File "/var/www/virginia/processors/stanford_processor.py", line 41, in process
[Sun Aug 28 22:57:31.942520 2016] [:error] [pid 2168:tid 140538007238400] [client 10.0.2.2:54595]     self.result['out'] = self._strategy.apply(plot,self._context)
[Sun Aug 28 22:57:31.942590 2016] [:error] [pid 2168:tid 140538007238400] [client 10.0.2.2:54595]   File "/var/www/virginia/strategy/weighted_match.py", line 22, in apply
[Sun Aug 28 22:57:31.943677 2016] [:error] [pid 2168:tid 140538007238400] [client 10.0.2.2:54595]     self.__generatePipeline()
[Sun Aug 28 22:57:31.943747 2016] [:error] [pid 2168:tid 140538007238400] [client 10.0.2.2:54595]   File "/var/www/virginia/strategy/weighted_match.py", line 29, in __generatePipeline
[Sun Aug 28 22:57:31.944026 2016] [:error] [pid 2168:tid 140538007238400] [client 10.0.2.2:54595]     self._inputstack = self._context.all()
[Sun Aug 28 22:57:31.944094 2016] [:error] [pid 2168:tid 140538007238400] [client 10.0.2.2:54595]   File "/var/www/virginia/context/stanford_processor_context.py", line 47, in all
[Sun Aug 28 22:57:31.945148 2016] [:error] [pid 2168:tid 140538007238400] [client 10.0.2.2:54595]     logger.debug(token + ' = ' + ner + ',' + pos)
[Sun Aug 28 22:57:31.945234 2016] [:error] [pid 2168:tid 140538007238400] [client 10.0.2.2:54595] TypeError: coercing to Unicode: need string or buffer, NoneType found
[Sun Aug 28 22:59:17.708782 2016] [ssl:warn] [pid 1538:tid 140538240235392] AH01909: RSA certificate configured for localhost:443 does NOT include an ID which matches the server name
[Sun Aug 28 23:01:30.689479 2016] [ssl:warn] [pid 1538:tid 140538240235392] AH01909: RSA certificate configured for localhost:443 does NOT include an ID which matches the server name
[Sun Aug 28 23:03:40.765509 2016] [ssl:warn] [pid 1538:tid 140538240235392] AH01909: RSA certificate configured for localhost:443 does NOT include an ID which matches the server name
[Mon Aug 29 06:40:35.118267 2016] [ssl:warn] [pid 1738:tid 140161439115136] AH01909: RSA certificate configured for localhost:443 does NOT include an ID which matches the server name
[Mon Aug 29 06:40:35.132291 2016] [ssl:warn] [pid 1739:tid 140161439115136] AH01909: RSA certificate configured for localhost:443 does NOT include an ID which matches the server name
[Mon Aug 29 06:43:34.885107 2016] [ssl:warn] [pid 1739:tid 140161439115136] AH01909: RSA certificate configured for localhost:443 does NOT include an ID which matches the server name
[Mon Aug 29 07:39:12.773442 2016] [ssl:warn] [pid 1739:tid 140161439115136] AH01909: RSA certificate configured for localhost:443 does NOT include an ID which matches the server name
[Mon Aug 29 07:39:18.236833 2016] [:error] [pid 2397:tid 140161149003520] [client 10.0.2.2:50938] mod_wsgi (pid=2397): Exception occurred processing WSGI script '/var/www/virginia/server.wsgi'.
[Mon Aug 29 07:39:18.237053 2016] [:error] [pid 2397:tid 140161149003520] [client 10.0.2.2:50938] Traceback (most recent call last):
[Mon Aug 29 07:39:18.237163 2016] [:error] [pid 2397:tid 140161149003520] [client 10.0.2.2:50938]   File "/usr/local/lib/python2.7/dist-packages/flask/app.py", line 2000, in __call__
[Mon Aug 29 07:39:18.237896 2016] [:error] [pid 2397:tid 140161149003520] [client 10.0.2.2:50938]     return self.wsgi_app(environ, start_response)
[Mon Aug 29 07:39:18.237995 2016] [:error] [pid 2397:tid 140161149003520] [client 10.0.2.2:50938]   File "/usr/local/lib/python2.7/dist-packages/flask/app.py", line 1991, in wsgi_app
[Mon Aug 29 07:39:18.238095 2016] [:error] [pid 2397:tid 140161149003520] [client 10.0.2.2:50938]     response = self.make_response(self.handle_exception(e))
[Mon Aug 29 07:39:18.238182 2016] [:error] [pid 2397:tid 140161149003520] [client 10.0.2.2:50938]   File "/usr/local/lib/python2.7/dist-packages/flask_restful/__init__.py", line 271, in error_router
[Mon Aug 29 07:39:18.238565 2016] [:error] [pid 2397:tid 140161149003520] [client 10.0.2.2:50938]     return original_handler(e)
[Mon Aug 29 07:39:18.238778 2016] [:error] [pid 2397:tid 140161149003520] [client 10.0.2.2:50938]   File "/usr/local/lib/python2.7/dist-packages/flask/app.py", line 1567, in handle_exception
[Mon Aug 29 07:39:18.238881 2016] [:error] [pid 2397:tid 140161149003520] [client 10.0.2.2:50938]     reraise(exc_type, exc_value, tb)
[Mon Aug 29 07:39:18.238948 2016] [:error] [pid 2397:tid 140161149003520] [client 10.0.2.2:50938]   File "/usr/local/lib/python2.7/dist-packages/flask_restful/__init__.py", line 268, in error_router
[Mon Aug 29 07:39:18.239021 2016] [:error] [pid 2397:tid 140161149003520] [client 10.0.2.2:50938]     return self.handle_error(e)
[Mon Aug 29 07:39:18.239089 2016] [:error] [pid 2397:tid 140161149003520] [client 10.0.2.2:50938]   File "/usr/local/lib/python2.7/dist-packages/flask/app.py", line 1988, in wsgi_app
[Mon Aug 29 07:39:18.239162 2016] [:error] [pid 2397:tid 140161149003520] [client 10.0.2.2:50938]     response = self.full_dispatch_request()
[Mon Aug 29 07:39:18.239229 2016] [:error] [pid 2397:tid 140161149003520] [client 10.0.2.2:50938]   File "/usr/local/lib/python2.7/dist-packages/flask/app.py", line 1641, in full_dispatch_request
[Mon Aug 29 07:39:18.239301 2016] [:error] [pid 2397:tid 140161149003520] [client 10.0.2.2:50938]     rv = self.handle_user_exception(e)
[Mon Aug 29 07:39:18.239369 2016] [:error] [pid 2397:tid 140161149003520] [client 10.0.2.2:50938]   File "/usr/local/lib/python2.7/dist-packages/flask_restful/__init__.py", line 271, in error_router
[Mon Aug 29 07:39:18.239442 2016] [:error] [pid 2397:tid 140161149003520] [client 10.0.2.2:50938]     return original_handler(e)
[Mon Aug 29 07:39:18.239508 2016] [:error] [pid 2397:tid 140161149003520] [client 10.0.2.2:50938]   File "/usr/local/lib/python2.7/dist-packages/flask/app.py", line 1544, in handle_user_exception
[Mon Aug 29 07:39:18.239581 2016] [:error] [pid 2397:tid 140161149003520] [client 10.0.2.2:50938]     reraise(exc_type, exc_value, tb)
[Mon Aug 29 07:39:18.239647 2016] [:error] [pid 2397:tid 140161149003520] [client 10.0.2.2:50938]   File "/usr/local/lib/python2.7/dist-packages/flask_restful/__init__.py", line 268, in error_router
[Mon Aug 29 07:39:18.239719 2016] [:error] [pid 2397:tid 140161149003520] [client 10.0.2.2:50938]     return self.handle_error(e)
[Mon Aug 29 07:39:18.239834 2016] [:error] [pid 2397:tid 140161149003520] [client 10.0.2.2:50938]   File "/usr/local/lib/python2.7/dist-packages/flask/app.py", line 1639, in full_dispatch_request
[Mon Aug 29 07:39:18.239950 2016] [:error] [pid 2397:tid 140161149003520] [client 10.0.2.2:50938]     rv = self.dispatch_request()
[Mon Aug 29 07:39:18.240041 2016] [:error] [pid 2397:tid 140161149003520] [client 10.0.2.2:50938]   File "/usr/local/lib/python2.7/dist-packages/flask/app.py", line 1625, in dispatch_request
[Mon Aug 29 07:39:18.240138 2016] [:error] [pid 2397:tid 140161149003520] [client 10.0.2.2:50938]     return self.view_functions[rule.endpoint](**req.view_args)
[Mon Aug 29 07:39:18.240227 2016] [:error] [pid 2397:tid 140161149003520] [client 10.0.2.2:50938]   File "/usr/local/lib/python2.7/dist-packages/flask_restful/__init__.py", line 477, in wrapper
[Mon Aug 29 07:39:18.240335 2016] [:error] [pid 2397:tid 140161149003520] [client 10.0.2.2:50938]     resp = resource(*args, **kwargs)
[Mon Aug 29 07:39:18.240429 2016] [:error] [pid 2397:tid 140161149003520] [client 10.0.2.2:50938]   File "/usr/local/lib/python2.7/dist-packages/flask/views.py", line 83, in view
[Mon Aug 29 07:39:18.240659 2016] [:error] [pid 2397:tid 140161149003520] [client 10.0.2.2:50938]     self = view.view_class(*class_args, **class_kwargs)
[Mon Aug 29 07:39:18.240752 2016] [:error] [pid 2397:tid 140161149003520] [client 10.0.2.2:50938]   File "/var/www/virginia/resources/monologue.py", line 36, in __init__
[Mon Aug 29 07:39:18.242045 2016] [:error] [pid 2397:tid 140161149003520] [client 10.0.2.2:50938]     self.processor = TextBlobProcessor()
[Mon Aug 29 07:39:18.242115 2016] [:error] [pid 2397:tid 140161149003520] [client 10.0.2.2:50938]   File "/var/www/virginia/processors/textblob_processor.py", line 13, in __init__
[Mon Aug 29 07:39:18.243218 2016] [:error] [pid 2397:tid 140161149003520] [client 10.0.2.2:50938]     nltk.data.path.append('/var/www/virginia/nltk_data/')
[Mon Aug 29 07:39:18.243297 2016] [:error] [pid 2397:tid 140161149003520] [client 10.0.2.2:50938] NameError: global name 'nltk' is not defined
[Mon Aug 29 07:39:58.089251 2016] [ssl:warn] [pid 1739:tid 140161439115136] AH01909: RSA certificate configured for localhost:443 does NOT include an ID which matches the server name
[Mon Aug 29 07:40:05.134461 2016] [:error] [pid 2481:tid 140161305589504] [client 10.0.2.2:50944] mod_wsgi (pid=2481): Exception occurred processing WSGI script '/var/www/virginia/server.wsgi'.
[Mon Aug 29 07:40:05.134648 2016] [:error] [pid 2481:tid 140161305589504] [client 10.0.2.2:50944] Traceback (most recent call last):
[Mon Aug 29 07:40:05.134977 2016] [:error] [pid 2481:tid 140161305589504] [client 10.0.2.2:50944]   File "/usr/local/lib/python2.7/dist-packages/flask/app.py", line 2000, in __call__
[Mon Aug 29 07:40:05.137023 2016] [:error] [pid 2481:tid 140161305589504] [client 10.0.2.2:50944]     return self.wsgi_app(environ, start_response)
[Mon Aug 29 07:40:05.137156 2016] [:error] [pid 2481:tid 140161305589504] [client 10.0.2.2:50944]   File "/usr/local/lib/python2.7/dist-packages/flask/app.py", line 1991, in wsgi_app
[Mon Aug 29 07:40:05.137297 2016] [:error] [pid 2481:tid 140161305589504] [client 10.0.2.2:50944]     response = self.make_response(self.handle_exception(e))
[Mon Aug 29 07:40:05.137427 2016] [:error] [pid 2481:tid 140161305589504] [client 10.0.2.2:50944]   File "/usr/local/lib/python2.7/dist-packages/flask_restful/__init__.py", line 271, in error_router
[Mon Aug 29 07:40:05.138873 2016] [:error] [pid 2481:tid 140161305589504] [client 10.0.2.2:50944]     return original_handler(e)
[Mon Aug 29 07:40:05.138881 2016] [:error] [pid 2481:tid 140161305589504] [client 10.0.2.2:50944]   File "/usr/local/lib/python2.7/dist-packages/flask/app.py", line 1567, in handle_exception
[Mon Aug 29 07:40:05.138986 2016] [:error] [pid 2481:tid 140161305589504] [client 10.0.2.2:50944]     reraise(exc_type, exc_value, tb)
[Mon Aug 29 07:40:05.139077 2016] [:error] [pid 2481:tid 140161305589504] [client 10.0.2.2:50944]   File "/usr/local/lib/python2.7/dist-packages/flask_restful/__init__.py", line 268, in error_router
[Mon Aug 29 07:40:05.139223 2016] [:error] [pid 2481:tid 140161305589504] [client 10.0.2.2:50944]     return self.handle_error(e)
[Mon Aug 29 07:40:05.139317 2016] [:error] [pid 2481:tid 140161305589504] [client 10.0.2.2:50944]   File "/usr/local/lib/python2.7/dist-packages/flask/app.py", line 1988, in wsgi_app
[Mon Aug 29 07:40:05.139414 2016] [:error] [pid 2481:tid 140161305589504] [client 10.0.2.2:50944]     response = self.full_dispatch_request()
[Mon Aug 29 07:40:05.139504 2016] [:error] [pid 2481:tid 140161305589504] [client 10.0.2.2:50944]   File "/usr/local/lib/python2.7/dist-packages/flask/app.py", line 1641, in full_dispatch_request
[Mon Aug 29 07:40:05.139691 2016] [:error] [pid 2481:tid 140161305589504] [client 10.0.2.2:50944]     rv = self.handle_user_exception(e)
[Mon Aug 29 07:40:05.139904 2016] [:error] [pid 2481:tid 140161305589504] [client 10.0.2.2:50944]   File "/usr/local/lib/python2.7/dist-packages/flask_restful/__init__.py", line 271, in error_router
[Mon Aug 29 07:40:05.140110 2016] [:error] [pid 2481:tid 140161305589504] [client 10.0.2.2:50944]     return original_handler(e)
[Mon Aug 29 07:40:05.140278 2016] [:error] [pid 2481:tid 140161305589504] [client 10.0.2.2:50944]   File "/usr/local/lib/python2.7/dist-packages/flask/app.py", line 1544, in handle_user_exception
[Mon Aug 29 07:40:05.140425 2016] [:error] [pid 2481:tid 140161305589504] [client 10.0.2.2:50944]     reraise(exc_type, exc_value, tb)
[Mon Aug 29 07:40:05.140498 2016] [:error] [pid 2481:tid 140161305589504] [client 10.0.2.2:50944]   File "/usr/local/lib/python2.7/dist-packages/flask_restful/__init__.py", line 268, in error_router
[Mon Aug 29 07:40:05.140577 2016] [:error] [pid 2481:tid 140161305589504] [client 10.0.2.2:50944]     return self.handle_error(e)
[Mon Aug 29 07:40:05.140649 2016] [:error] [pid 2481:tid 140161305589504] [client 10.0.2.2:50944]   File "/usr/local/lib/python2.7/dist-packages/flask/app.py", line 1639, in full_dispatch_request
[Mon Aug 29 07:40:05.140727 2016] [:error] [pid 2481:tid 140161305589504] [client 10.0.2.2:50944]     rv = self.dispatch_request()
[Mon Aug 29 07:40:05.140799 2016] [:error] [pid 2481:tid 140161305589504] [client 10.0.2.2:50944]   File "/usr/local/lib/python2.7/dist-packages/flask/app.py", line 1625, in dispatch_request
[Mon Aug 29 07:40:05.140879 2016] [:error] [pid 2481:tid 140161305589504] [client 10.0.2.2:50944]     return self.view_functions[rule.endpoint](**req.view_args)
[Mon Aug 29 07:40:05.140951 2016] [:error] [pid 2481:tid 140161305589504] [client 10.0.2.2:50944]   File "/usr/local/lib/python2.7/dist-packages/flask_restful/__init__.py", line 477, in wrapper
[Mon Aug 29 07:40:05.141029 2016] [:error] [pid 2481:tid 140161305589504] [client 10.0.2.2:50944]     resp = resource(*args, **kwargs)
[Mon Aug 29 07:40:05.141104 2016] [:error] [pid 2481:tid 140161305589504] [client 10.0.2.2:50944]   File "/usr/local/lib/python2.7/dist-packages/flask/views.py", line 84, in view
[Mon Aug 29 07:40:05.141363 2016] [:error] [pid 2481:tid 140161305589504] [client 10.0.2.2:50944]     return self.dispatch_request(*args, **kwargs)
[Mon Aug 29 07:40:05.141440 2016] [:error] [pid 2481:tid 140161305589504] [client 10.0.2.2:50944]   File "/usr/local/lib/python2.7/dist-packages/flask_restful/__init__.py", line 587, in dispatch_request
[Mon Aug 29 07:40:05.141521 2016] [:error] [pid 2481:tid 140161305589504] [client 10.0.2.2:50944]     resp = meth(*args, **kwargs)
[Mon Aug 29 07:40:05.141597 2016] [:error] [pid 2481:tid 140161305589504] [client 10.0.2.2:50944]   File "/var/www/virginia/resources/monologue.py", line 67, in post
[Mon Aug 29 07:40:05.143271 2016] [:error] [pid 2481:tid 140161305589504] [client 10.0.2.2:50944]     return json.dumps(self.processor.process(plot, json_data['monologue']))
[Mon Aug 29 07:40:05.143349 2016] [:error] [pid 2481:tid 140161305589504] [client 10.0.2.2:50944]   File "/var/www/virginia/processors/textblob_processor.py", line 40, in process
[Mon Aug 29 07:40:05.144540 2016] [:error] [pid 2481:tid 140161305589504] [client 10.0.2.2:50944]     self.__processingPreflight(monologue)
[Mon Aug 29 07:40:05.144618 2016] [:error] [pid 2481:tid 140161305589504] [client 10.0.2.2:50944]   File "/var/www/virginia/processors/textblob_processor.py", line 25, in __processingPreflight
[Mon Aug 29 07:40:05.144915 2016] [:error] [pid 2481:tid 140161305589504] [client 10.0.2.2:50944]     self.__updateprocessorContext()
[Mon Aug 29 07:40:05.144990 2016] [:error] [pid 2481:tid 140161305589504] [client 10.0.2.2:50944]   File "/var/www/virginia/processors/textblob_processor.py", line 37, in __updateprocessorContext
[Mon Aug 29 07:40:05.145295 2016] [:error] [pid 2481:tid 140161305589504] [client 10.0.2.2:50944]     self._context.create(self.tokens,self._tagEntities(),self._tagPartOfSpeech())
[Mon Aug 29 07:40:05.145371 2016] [:error] [pid 2481:tid 140161305589504] [client 10.0.2.2:50944]   File "/var/www/virginia/processors/textblob_processor.py", line 28, in _tagEntities
[Mon Aug 29 07:40:05.145679 2016] [:error] [pid 2481:tid 140161305589504] [client 10.0.2.2:50944]     return self.nerTagger.tag(self.tokens)
[Mon Aug 29 07:40:05.145755 2016] [:error] [pid 2481:tid 140161305589504] [client 10.0.2.2:50944]   File "/usr/local/lib/python2.7/dist-packages/nltk/tag/stanford.py", line 71, in tag
[Mon Aug 29 07:40:05.146165 2016] [:error] [pid 2481:tid 140161305589504] [client 10.0.2.2:50944]     return sum(self.tag_sents([tokens]), [])
[Mon Aug 29 07:40:05.146243 2016] [:error] [pid 2481:tid 140161305589504] [client 10.0.2.2:50944]   File "/usr/local/lib/python2.7/dist-packages/nltk/tag/stanford.py", line 94, in tag_sents
[Mon Aug 29 07:40:05.146323 2016] [:error] [pid 2481:tid 140161305589504] [client 10.0.2.2:50944]     stdout=PIPE, stderr=PIPE)
[Mon Aug 29 07:40:05.146406 2016] [:error] [pid 2481:tid 140161305589504] [client 10.0.2.2:50944]   File "/usr/local/lib/python2.7/dist-packages/nltk/internals.py", line 134, in java
[Mon Aug 29 07:40:05.147403 2016] [:error] [pid 2481:tid 140161305589504] [client 10.0.2.2:50944]     raise OSError('Java command failed : ' + str(cmd))
[Mon Aug 29 07:40:05.147403 2016] [:error] [pid 2481:tid 140161305589504] [client 10.0.2.2:50944] OSError: Java command failed : ['/usr/lib/jvm/java-8-openjdk-amd64/bin/java', '-mx1000m', '-cp', '/home/vagrant/stanfordnlp/stanford-ner-2015-12-09/stanford-ner-3.6.0-javadoc.jar:/home/vagrant/stanfordnlp/stanford-ner-2015-12-09/stanford-ner-3.6.0-sources.jar:/home/vagrant/stanfordnlp/stanford-ner-2015-12-09/stanford-ner.jar:/home/vagrant/stanfordnlp/stanford-ner-2015-12-09/stanford-ner-3.6.0.jar:/home/vagrant/stanfordnlp/stanford-ner-2015-12-09/lib/slf4j-api.jar:/home/vagrant/stanfordnlp/stanford-ner-2015-12-09/lib/joda-time.jar:/home/vagrant/stanfordnlp/stanford-ner-2015-12-09/lib/stanford-ner-resources.jar:/home/vagrant/stanfordnlp/stanford-ner-2015-12-09/lib/jollyday-0.4.7.jar:/home/vagrant/stanfordnlp/stanford-ner-2015-12-09/lib/slf4j-simple.jar', 'edu.stanford.nlp.ie.crf.CRFClassifier', '-loadClassifier', '/home/vagrant/stanfordnlp/stanford-ner-2015-12-09/classifiers/english.all.3class.distsim.crf.ser.gz', '-textFile', '/tmp/tmpvOM39G', '-outputFormat', 'slashTags', '-tokenizerFactory', 'edu.stanford.nlp.process.WhitespaceTokenizer', '-tokenizerOptions', '"tokenizeNLs=false"', '-encoding', 'utf8']
[Mon Aug 29 07:42:51.201408 2016] [ssl:warn] [pid 1739:tid 140161439115136] AH01909: RSA certificate configured for localhost:443 does NOT include an ID which matches the server name
[Mon Aug 29 07:42:58.897799 2016] [:error] [pid 2701:tid 140161216145152] [client 10.0.2.2:50954] mod_wsgi (pid=2701): Exception occurred processing WSGI script '/var/www/virginia/server.wsgi'.
[Mon Aug 29 07:42:58.898055 2016] [:error] [pid 2701:tid 140161216145152] [client 10.0.2.2:50954] Traceback (most recent call last):
[Mon Aug 29 07:42:58.898448 2016] [:error] [pid 2701:tid 140161216145152] [client 10.0.2.2:50954]   File "/usr/local/lib/python2.7/dist-packages/flask/app.py", line 2000, in __call__
[Mon Aug 29 07:42:58.916789 2016] [:error] [pid 2701:tid 140161216145152] [client 10.0.2.2:50954]     return self.wsgi_app(environ, start_response)
[Mon Aug 29 07:42:58.916985 2016] [:error] [pid 2701:tid 140161216145152] [client 10.0.2.2:50954]   File "/usr/local/lib/python2.7/dist-packages/flask/app.py", line 1991, in wsgi_app
[Mon Aug 29 07:42:58.917148 2016] [:error] [pid 2701:tid 140161216145152] [client 10.0.2.2:50954]     response = self.make_response(self.handle_exception(e))
[Mon Aug 29 07:42:58.917253 2016] [:error] [pid 2701:tid 140161216145152] [client 10.0.2.2:50954]   File "/usr/local/lib/python2.7/dist-packages/flask_restful/__init__.py", line 271, in error_router
[Mon Aug 29 07:42:58.918770 2016] [:error] [pid 2701:tid 140161216145152] [client 10.0.2.2:50954]     return original_handler(e)
[Mon Aug 29 07:42:58.918798 2016] [:error] [pid 2701:tid 140161216145152] [client 10.0.2.2:50954]   File "/usr/local/lib/python2.7/dist-packages/flask/app.py", line 1567, in handle_exception
[Mon Aug 29 07:42:58.918888 2016] [:error] [pid 2701:tid 140161216145152] [client 10.0.2.2:50954]     reraise(exc_type, exc_value, tb)
[Mon Aug 29 07:42:58.918962 2016] [:error] [pid 2701:tid 140161216145152] [client 10.0.2.2:50954]   File "/usr/local/lib/python2.7/dist-packages/flask_restful/__init__.py", line 268, in error_router
[Mon Aug 29 07:42:58.919045 2016] [:error] [pid 2701:tid 140161216145152] [client 10.0.2.2:50954]     return self.handle_error(e)
[Mon Aug 29 07:42:58.919122 2016] [:error] [pid 2701:tid 140161216145152] [client 10.0.2.2:50954]   File "/usr/local/lib/python2.7/dist-packages/flask/app.py", line 1988, in wsgi_app
[Mon Aug 29 07:42:58.919204 2016] [:error] [pid 2701:tid 140161216145152] [client 10.0.2.2:50954]     response = self.full_dispatch_request()
[Mon Aug 29 07:42:58.919277 2016] [:error] [pid 2701:tid 140161216145152] [client 10.0.2.2:50954]   File "/usr/local/lib/python2.7/dist-packages/flask/app.py", line 1641, in full_dispatch_request
[Mon Aug 29 07:42:58.919356 2016] [:error] [pid 2701:tid 140161216145152] [client 10.0.2.2:50954]     rv = self.handle_user_exception(e)
[Mon Aug 29 07:42:58.919428 2016] [:error] [pid 2701:tid 140161216145152] [client 10.0.2.2:50954]   File "/usr/local/lib/python2.7/dist-packages/flask_restful/__init__.py", line 271, in error_router
[Mon Aug 29 07:42:58.919506 2016] [:error] [pid 2701:tid 140161216145152] [client 10.0.2.2:50954]     return original_handler(e)
[Mon Aug 29 07:42:58.919586 2016] [:error] [pid 2701:tid 140161216145152] [client 10.0.2.2:50954]   File "/usr/local/lib/python2.7/dist-packages/flask/app.py", line 1544, in handle_user_exception
[Mon Aug 29 07:42:58.919665 2016] [:error] [pid 2701:tid 140161216145152] [client 10.0.2.2:50954]     reraise(exc_type, exc_value, tb)
[Mon Aug 29 07:42:58.919736 2016] [:error] [pid 2701:tid 140161216145152] [client 10.0.2.2:50954]   File "/usr/local/lib/python2.7/dist-packages/flask_restful/__init__.py", line 268, in error_router
[Mon Aug 29 07:42:58.919815 2016] [:error] [pid 2701:tid 140161216145152] [client 10.0.2.2:50954]     return self.handle_error(e)
[Mon Aug 29 07:42:58.919886 2016] [:error] [pid 2701:tid 140161216145152] [client 10.0.2.2:50954]   File "/usr/local/lib/python2.7/dist-packages/flask/app.py", line 1639, in full_dispatch_request
[Mon Aug 29 07:42:58.919965 2016] [:error] [pid 2701:tid 140161216145152] [client 10.0.2.2:50954]     rv = self.dispatch_request()
[Mon Aug 29 07:42:58.920037 2016] [:error] [pid 2701:tid 140161216145152] [client 10.0.2.2:50954]   File "/usr/local/lib/python2.7/dist-packages/flask/app.py", line 1625, in dispatch_request
[Mon Aug 29 07:42:58.920122 2016] [:error] [pid 2701:tid 140161216145152] [client 10.0.2.2:50954]     return self.view_functions[rule.endpoint](**req.view_args)
[Mon Aug 29 07:42:58.920195 2016] [:error] [pid 2701:tid 140161216145152] [client 10.0.2.2:50954]   File "/usr/local/lib/python2.7/dist-packages/flask_restful/__init__.py", line 477, in wrapper
[Mon Aug 29 07:42:58.920273 2016] [:error] [pid 2701:tid 140161216145152] [client 10.0.2.2:50954]     resp = resource(*args, **kwargs)
[Mon Aug 29 07:42:58.920349 2016] [:error] [pid 2701:tid 140161216145152] [client 10.0.2.2:50954]   File "/usr/local/lib/python2.7/dist-packages/flask/views.py", line 84, in view
[Mon Aug 29 07:42:58.920599 2016] [:error] [pid 2701:tid 140161216145152] [client 10.0.2.2:50954]     return self.dispatch_request(*args, **kwargs)
[Mon Aug 29 07:42:58.920678 2016] [:error] [pid 2701:tid 140161216145152] [client 10.0.2.2:50954]   File "/usr/local/lib/python2.7/dist-packages/flask_restful/__init__.py", line 587, in dispatch_request
[Mon Aug 29 07:42:58.920759 2016] [:error] [pid 2701:tid 140161216145152] [client 10.0.2.2:50954]     resp = meth(*args, **kwargs)
[Mon Aug 29 07:42:58.920835 2016] [:error] [pid 2701:tid 140161216145152] [client 10.0.2.2:50954]   File "/var/www/virginia/resources/monologue.py", line 67, in post
[Mon Aug 29 07:42:58.923476 2016] [:error] [pid 2701:tid 140161216145152] [client 10.0.2.2:50954]     return json.dumps(self.processor.process(plot, json_data['monologue']))
[Mon Aug 29 07:42:58.923555 2016] [:error] [pid 2701:tid 140161216145152] [client 10.0.2.2:50954]   File "/var/www/virginia/processors/textblob_processor.py", line 40, in process
[Mon Aug 29 07:42:58.924706 2016] [:error] [pid 2701:tid 140161216145152] [client 10.0.2.2:50954]     self.__processingPreflight(monologue)
[Mon Aug 29 07:42:58.924792 2016] [:error] [pid 2701:tid 140161216145152] [client 10.0.2.2:50954]   File "/var/www/virginia/processors/textblob_processor.py", line 24, in __processingPreflight
[Mon Aug 29 07:42:58.925092 2016] [:error] [pid 2701:tid 140161216145152] [client 10.0.2.2:50954]     self.__updateprocessorContext()
[Mon Aug 29 07:42:58.925165 2016] [:error] [pid 2701:tid 140161216145152] [client 10.0.2.2:50954]   File "/var/www/virginia/processors/textblob_processor.py", line 37, in __updateprocessorContext
[Mon Aug 29 07:42:58.925493 2016] [:error] [pid 2701:tid 140161216145152] [client 10.0.2.2:50954]     self._context.create(self.tokens,self._tagEntities(),self._tagPartOfSpeech())
[Mon Aug 29 07:42:58.925569 2016] [:error] [pid 2701:tid 140161216145152] [client 10.0.2.2:50954]   File "/var/www/virginia/processors/textblob_processor.py", line 27, in _tagEntities
[Mon Aug 29 07:42:58.925883 2016] [:error] [pid 2701:tid 140161216145152] [client 10.0.2.2:50954]     return self.nerTagger.tag(self.tokens)
[Mon Aug 29 07:42:58.925960 2016] [:error] [pid 2701:tid 140161216145152] [client 10.0.2.2:50954]   File "/usr/local/lib/python2.7/dist-packages/nltk/tag/stanford.py", line 71, in tag
[Mon Aug 29 07:42:58.926378 2016] [:error] [pid 2701:tid 140161216145152] [client 10.0.2.2:50954]     return sum(self.tag_sents([tokens]), [])
[Mon Aug 29 07:42:58.926456 2016] [:error] [pid 2701:tid 140161216145152] [client 10.0.2.2:50954]   File "/usr/local/lib/python2.7/dist-packages/nltk/tag/stanford.py", line 94, in tag_sents
[Mon Aug 29 07:42:58.926537 2016] [:error] [pid 2701:tid 140161216145152] [client 10.0.2.2:50954]     stdout=PIPE, stderr=PIPE)
[Mon Aug 29 07:42:58.926613 2016] [:error] [pid 2701:tid 140161216145152] [client 10.0.2.2:50954]   File "/usr/local/lib/python2.7/dist-packages/nltk/internals.py", line 134, in java
[Mon Aug 29 07:42:58.928058 2016] [:error] [pid 2701:tid 140161216145152] [client 10.0.2.2:50954]     raise OSError('Java command failed : ' + str(cmd))
[Mon Aug 29 07:42:58.928163 2016] [:error] [pid 2701:tid 140161216145152] [client 10.0.2.2:50954] OSError: Java command failed : ['/usr/lib/jvm/java-8-openjdk-amd64/bin/java', '-mx1000m', '-cp', '/home/vagrant/stanfordnlp/stanford-ner-2015-12-09/stanford-ner-3.6.0-javadoc.jar:/home/vagrant/stanfordnlp/stanford-ner-2015-12-09/stanford-ner-3.6.0-sources.jar:/home/vagrant/stanfordnlp/stanford-ner-2015-12-09/stanford-ner.jar:/home/vagrant/stanfordnlp/stanford-ner-2015-12-09/stanford-ner-3.6.0.jar:/home/vagrant/stanfordnlp/stanford-ner-2015-12-09/lib/slf4j-api.jar:/home/vagrant/stanfordnlp/stanford-ner-2015-12-09/lib/joda-time.jar:/home/vagrant/stanfordnlp/stanford-ner-2015-12-09/lib/stanford-ner-resources.jar:/home/vagrant/stanfordnlp/stanford-ner-2015-12-09/lib/jollyday-0.4.7.jar:/home/vagrant/stanfordnlp/stanford-ner-2015-12-09/lib/slf4j-simple.jar', 'edu.stanford.nlp.ie.crf.CRFClassifier', '-loadClassifier', '/home/vagrant/stanfordnlp/stanford-ner-2015-12-09/classifiers/english.all.3class.distsim.crf.ser.gz', '-textFile', '/tmp/tmpHoqQ3z', '-outputFormat', 'slashTags', '-tokenizerFactory', 'edu.stanford.nlp.process.WhitespaceTokenizer', '-tokenizerOptions', '"tokenizeNLs=false"', '-encoding', 'utf8']
[Mon Aug 29 07:43:17.250302 2016] [ssl:warn] [pid 2808:tid 140159275054976] AH01909: RSA certificate configured for localhost:443 does NOT include an ID which matches the server name
[Mon Aug 29 07:43:17.263264 2016] [ssl:warn] [pid 2809:tid 140159275054976] AH01909: RSA certificate configured for localhost:443 does NOT include an ID which matches the server name
[Mon Aug 29 07:43:26.930811 2016] [:error] [pid 2813:tid 140158984734464] [client 10.0.2.2:50958] mod_wsgi (pid=2813): Exception occurred processing WSGI script '/var/www/virginia/server.wsgi'.
[Mon Aug 29 07:43:26.931011 2016] [:error] [pid 2813:tid 140158984734464] [client 10.0.2.2:50958] Traceback (most recent call last):
[Mon Aug 29 07:43:26.931274 2016] [:error] [pid 2813:tid 140158984734464] [client 10.0.2.2:50958]   File "/usr/local/lib/python2.7/dist-packages/flask/app.py", line 2000, in __call__
[Mon Aug 29 07:43:26.933213 2016] [:error] [pid 2813:tid 140158984734464] [client 10.0.2.2:50958]     return self.wsgi_app(environ, start_response)
[Mon Aug 29 07:43:26.933325 2016] [:error] [pid 2813:tid 140158984734464] [client 10.0.2.2:50958]   File "/usr/local/lib/python2.7/dist-packages/flask/app.py", line 1991, in wsgi_app
[Mon Aug 29 07:43:26.933416 2016] [:error] [pid 2813:tid 140158984734464] [client 10.0.2.2:50958]     response = self.make_response(self.handle_exception(e))
[Mon Aug 29 07:43:26.933488 2016] [:error] [pid 2813:tid 140158984734464] [client 10.0.2.2:50958]   File "/usr/local/lib/python2.7/dist-packages/flask_restful/__init__.py", line 271, in error_router
[Mon Aug 29 07:43:26.934822 2016] [:error] [pid 2813:tid 140158984734464] [client 10.0.2.2:50958]     return original_handler(e)
[Mon Aug 29 07:43:26.934829 2016] [:error] [pid 2813:tid 140158984734464] [client 10.0.2.2:50958]   File "/usr/local/lib/python2.7/dist-packages/flask/app.py", line 1567, in handle_exception
[Mon Aug 29 07:43:26.934905 2016] [:error] [pid 2813:tid 140158984734464] [client 10.0.2.2:50958]     reraise(exc_type, exc_value, tb)
[Mon Aug 29 07:43:26.934978 2016] [:error] [pid 2813:tid 140158984734464] [client 10.0.2.2:50958]   File "/usr/local/lib/python2.7/dist-packages/flask_restful/__init__.py", line 268, in error_router
[Mon Aug 29 07:43:26.935060 2016] [:error] [pid 2813:tid 140158984734464] [client 10.0.2.2:50958]     return self.handle_error(e)
[Mon Aug 29 07:43:26.935134 2016] [:error] [pid 2813:tid 140158984734464] [client 10.0.2.2:50958]   File "/usr/local/lib/python2.7/dist-packages/flask/app.py", line 1988, in wsgi_app
[Mon Aug 29 07:43:26.935227 2016] [:error] [pid 2813:tid 140158984734464] [client 10.0.2.2:50958]     response = self.full_dispatch_request()
[Mon Aug 29 07:43:26.935300 2016] [:error] [pid 2813:tid 140158984734464] [client 10.0.2.2:50958]   File "/usr/local/lib/python2.7/dist-packages/flask/app.py", line 1641, in full_dispatch_request
[Mon Aug 29 07:43:26.935379 2016] [:error] [pid 2813:tid 140158984734464] [client 10.0.2.2:50958]     rv = self.handle_user_exception(e)
[Mon Aug 29 07:43:26.935451 2016] [:error] [pid 2813:tid 140158984734464] [client 10.0.2.2:50958]   File "/usr/local/lib/python2.7/dist-packages/flask_restful/__init__.py", line 271, in error_router
[Mon Aug 29 07:43:26.935529 2016] [:error] [pid 2813:tid 140158984734464] [client 10.0.2.2:50958]     return original_handler(e)
[Mon Aug 29 07:43:26.935601 2016] [:error] [pid 2813:tid 140158984734464] [client 10.0.2.2:50958]   File "/usr/local/lib/python2.7/dist-packages/flask/app.py", line 1544, in handle_user_exception
[Mon Aug 29 07:43:26.935680 2016] [:error] [pid 2813:tid 140158984734464] [client 10.0.2.2:50958]     reraise(exc_type, exc_value, tb)
[Mon Aug 29 07:43:26.935814 2016] [:error] [pid 2813:tid 140158984734464] [client 10.0.2.2:50958]   File "/usr/local/lib/python2.7/dist-packages/flask_restful/__init__.py", line 268, in error_router
[Mon Aug 29 07:43:26.935896 2016] [:error] [pid 2813:tid 140158984734464] [client 10.0.2.2:50958]     return self.handle_error(e)
[Mon Aug 29 07:43:26.935968 2016] [:error] [pid 2813:tid 140158984734464] [client 10.0.2.2:50958]   File "/usr/local/lib/python2.7/dist-packages/flask/app.py", line 1639, in full_dispatch_request
[Mon Aug 29 07:43:26.936047 2016] [:error] [pid 2813:tid 140158984734464] [client 10.0.2.2:50958]     rv = self.dispatch_request()
[Mon Aug 29 07:43:26.936119 2016] [:error] [pid 2813:tid 140158984734464] [client 10.0.2.2:50958]   File "/usr/local/lib/python2.7/dist-packages/flask/app.py", line 1625, in dispatch_request
[Mon Aug 29 07:43:26.936198 2016] [:error] [pid 2813:tid 140158984734464] [client 10.0.2.2:50958]     return self.view_functions[rule.endpoint](**req.view_args)
[Mon Aug 29 07:43:26.936271 2016] [:error] [pid 2813:tid 140158984734464] [client 10.0.2.2:50958]   File "/usr/local/lib/python2.7/dist-packages/flask_restful/__init__.py", line 477, in wrapper
[Mon Aug 29 07:43:26.936350 2016] [:error] [pid 2813:tid 140158984734464] [client 10.0.2.2:50958]     resp = resource(*args, **kwargs)
[Mon Aug 29 07:43:26.936425 2016] [:error] [pid 2813:tid 140158984734464] [client 10.0.2.2:50958]   File "/usr/local/lib/python2.7/dist-packages/flask/views.py", line 84, in view
[Mon Aug 29 07:43:26.936666 2016] [:error] [pid 2813:tid 140158984734464] [client 10.0.2.2:50958]     return self.dispatch_request(*args, **kwargs)
[Mon Aug 29 07:43:26.936752 2016] [:error] [pid 2813:tid 140158984734464] [client 10.0.2.2:50958]   File "/usr/local/lib/python2.7/dist-packages/flask_restful/__init__.py", line 587, in dispatch_request
[Mon Aug 29 07:43:26.936832 2016] [:error] [pid 2813:tid 140158984734464] [client 10.0.2.2:50958]     resp = meth(*args, **kwargs)
[Mon Aug 29 07:43:26.936907 2016] [:error] [pid 2813:tid 140158984734464] [client 10.0.2.2:50958]   File "/var/www/virginia/resources/monologue.py", line 67, in post
[Mon Aug 29 07:43:26.938487 2016] [:error] [pid 2813:tid 140158984734464] [client 10.0.2.2:50958]     return json.dumps(self.processor.process(plot, json_data['monologue']))
[Mon Aug 29 07:43:26.938565 2016] [:error] [pid 2813:tid 140158984734464] [client 10.0.2.2:50958]   File "/var/www/virginia/processors/textblob_processor.py", line 40, in process
[Mon Aug 29 07:43:26.939719 2016] [:error] [pid 2813:tid 140158984734464] [client 10.0.2.2:50958]     self.__processingPreflight(monologue)
[Mon Aug 29 07:43:26.939799 2016] [:error] [pid 2813:tid 140158984734464] [client 10.0.2.2:50958]   File "/var/www/virginia/processors/textblob_processor.py", line 24, in __processingPreflight
[Mon Aug 29 07:43:26.940106 2016] [:error] [pid 2813:tid 140158984734464] [client 10.0.2.2:50958]     self.__updateprocessorContext()
[Mon Aug 29 07:43:26.940183 2016] [:error] [pid 2813:tid 140158984734464] [client 10.0.2.2:50958]   File "/var/www/virginia/processors/textblob_processor.py", line 37, in __updateprocessorContext
[Mon Aug 29 07:43:26.940495 2016] [:error] [pid 2813:tid 140158984734464] [client 10.0.2.2:50958]     self._context.create(self.tokens,self._tagEntities(),self._tagPartOfSpeech())
[Mon Aug 29 07:43:26.940572 2016] [:error] [pid 2813:tid 140158984734464] [client 10.0.2.2:50958]   File "/var/www/virginia/processors/textblob_processor.py", line 27, in _tagEntities
[Mon Aug 29 07:43:26.941006 2016] [:error] [pid 2813:tid 140158984734464] [client 10.0.2.2:50958]     return self.nerTagger.tag(self.tokens)
[Mon Aug 29 07:43:26.941085 2016] [:error] [pid 2813:tid 140158984734464] [client 10.0.2.2:50958]   File "/usr/local/lib/python2.7/dist-packages/nltk/tag/stanford.py", line 71, in tag
[Mon Aug 29 07:43:26.942379 2016] [:error] [pid 2813:tid 140158984734464] [client 10.0.2.2:50958]     return sum(self.tag_sents([tokens]), [])
[Mon Aug 29 07:43:26.942466 2016] [:error] [pid 2813:tid 140158984734464] [client 10.0.2.2:50958]   File "/usr/local/lib/python2.7/dist-packages/nltk/tag/stanford.py", line 94, in tag_sents
[Mon Aug 29 07:43:26.942564 2016] [:error] [pid 2813:tid 140158984734464] [client 10.0.2.2:50958]     stdout=PIPE, stderr=PIPE)
[Mon Aug 29 07:43:26.942640 2016] [:error] [pid 2813:tid 140158984734464] [client 10.0.2.2:50958]   File "/usr/local/lib/python2.7/dist-packages/nltk/internals.py", line 134, in java
[Mon Aug 29 07:43:26.943116 2016] [:error] [pid 2813:tid 140158984734464] [client 10.0.2.2:50958]     raise OSError('Java command failed : ' + str(cmd))
[Mon Aug 29 07:43:26.943227 2016] [:error] [pid 2813:tid 140158984734464] [client 10.0.2.2:50958] OSError: Java command failed : ['/usr/lib/jvm/java-8-openjdk-amd64/bin/java', '-mx1000m', '-cp', '/home/vagrant/stanfordnlp/stanford-ner-2015-12-09/stanford-ner-3.6.0-javadoc.jar:/home/vagrant/stanfordnlp/stanford-ner-2015-12-09/stanford-ner-3.6.0-sources.jar:/home/vagrant/stanfordnlp/stanford-ner-2015-12-09/stanford-ner.jar:/home/vagrant/stanfordnlp/stanford-ner-2015-12-09/stanford-ner-3.6.0.jar:/home/vagrant/stanfordnlp/stanford-ner-2015-12-09/lib/slf4j-api.jar:/home/vagrant/stanfordnlp/stanford-ner-2015-12-09/lib/joda-time.jar:/home/vagrant/stanfordnlp/stanford-ner-2015-12-09/lib/stanford-ner-resources.jar:/home/vagrant/stanfordnlp/stanford-ner-2015-12-09/lib/jollyday-0.4.7.jar:/home/vagrant/stanfordnlp/stanford-ner-2015-12-09/lib/slf4j-simple.jar', 'edu.stanford.nlp.ie.crf.CRFClassifier', '-loadClassifier', '/home/vagrant/stanfordnlp/stanford-ner-2015-12-09/classifiers/english.all.3class.distsim.crf.ser.gz', '-textFile', '/tmp/tmpDXVrhz', '-outputFormat', 'slashTags', '-tokenizerFactory', 'edu.stanford.nlp.process.WhitespaceTokenizer', '-tokenizerOptions', '"tokenizeNLs=false"', '-encoding', 'utf8']
[Mon Aug 29 07:44:11.788196 2016] [ssl:warn] [pid 2809:tid 140159275054976] AH01909: RSA certificate configured for localhost:443 does NOT include an ID which matches the server name
[Mon Aug 29 07:44:16.492324 2016] [:error] [pid 2910:tid 140158984734464] [client 10.0.2.2:51105] mod_wsgi (pid=2910): Exception occurred processing WSGI script '/var/www/virginia/server.wsgi'.
[Mon Aug 29 07:44:16.492615 2016] [:error] [pid 2910:tid 140158984734464] [client 10.0.2.2:51105] Traceback (most recent call last):
[Mon Aug 29 07:44:16.492755 2016] [:error] [pid 2910:tid 140158984734464] [client 10.0.2.2:51105]   File "/usr/local/lib/python2.7/dist-packages/flask/app.py", line 2000, in __call__
[Mon Aug 29 07:44:16.493235 2016] [:error] [pid 2910:tid 140158984734464] [client 10.0.2.2:51105]     return self.wsgi_app(environ, start_response)
[Mon Aug 29 07:44:16.493334 2016] [:error] [pid 2910:tid 140158984734464] [client 10.0.2.2:51105]   File "/usr/local/lib/python2.7/dist-packages/flask/app.py", line 1991, in wsgi_app
[Mon Aug 29 07:44:16.493438 2016] [:error] [pid 2910:tid 140158984734464] [client 10.0.2.2:51105]     response = self.make_response(self.handle_exception(e))
[Mon Aug 29 07:44:16.493530 2016] [:error] [pid 2910:tid 140158984734464] [client 10.0.2.2:51105]   File "/usr/local/lib/python2.7/dist-packages/flask_restful/__init__.py", line 271, in error_router
[Mon Aug 29 07:44:16.493754 2016] [:error] [pid 2910:tid 140158984734464] [client 10.0.2.2:51105]     return original_handler(e)
[Mon Aug 29 07:44:16.493848 2016] [:error] [pid 2910:tid 140158984734464] [client 10.0.2.2:51105]   File "/usr/local/lib/python2.7/dist-packages/flask/app.py", line 1567, in handle_exception
[Mon Aug 29 07:44:16.493948 2016] [:error] [pid 2910:tid 140158984734464] [client 10.0.2.2:51105]     reraise(exc_type, exc_value, tb)
[Mon Aug 29 07:44:16.494036 2016] [:error] [pid 2910:tid 140158984734464] [client 10.0.2.2:51105]   File "/usr/local/lib/python2.7/dist-packages/flask_restful/__init__.py", line 268, in error_router
[Mon Aug 29 07:44:16.494129 2016] [:error] [pid 2910:tid 140158984734464] [client 10.0.2.2:51105]     return self.handle_error(e)
[Mon Aug 29 07:44:16.494215 2016] [:error] [pid 2910:tid 140158984734464] [client 10.0.2.2:51105]   File "/usr/local/lib/python2.7/dist-packages/flask/app.py", line 1988, in wsgi_app
[Mon Aug 29 07:44:16.494312 2016] [:error] [pid 2910:tid 140158984734464] [client 10.0.2.2:51105]     response = self.full_dispatch_request()
[Mon Aug 29 07:44:16.494401 2016] [:error] [pid 2910:tid 140158984734464] [client 10.0.2.2:51105]   File "/usr/local/lib/python2.7/dist-packages/flask/app.py", line 1641, in full_dispatch_request
[Mon Aug 29 07:44:16.494526 2016] [:error] [pid 2910:tid 140158984734464] [client 10.0.2.2:51105]     rv = self.handle_user_exception(e)
[Mon Aug 29 07:44:16.494593 2016] [:error] [pid 2910:tid 140158984734464] [client 10.0.2.2:51105]   File "/usr/local/lib/python2.7/dist-packages/flask_restful/__init__.py", line 271, in error_router
[Mon Aug 29 07:44:16.494666 2016] [:error] [pid 2910:tid 140158984734464] [client 10.0.2.2:51105]     return original_handler(e)
[Mon Aug 29 07:44:16.494732 2016] [:error] [pid 2910:tid 140158984734464] [client 10.0.2.2:51105]   File "/usr/local/lib/python2.7/dist-packages/flask/app.py", line 1544, in handle_user_exception
[Mon Aug 29 07:44:16.494811 2016] [:error] [pid 2910:tid 140158984734464] [client 10.0.2.2:51105]     reraise(exc_type, exc_value, tb)
[Mon Aug 29 07:44:16.494879 2016] [:error] [pid 2910:tid 140158984734464] [client 10.0.2.2:51105]   File "/usr/local/lib/python2.7/dist-packages/flask_restful/__init__.py", line 268, in error_router
[Mon Aug 29 07:44:16.494952 2016] [:error] [pid 2910:tid 140158984734464] [client 10.0.2.2:51105]     return self.handle_error(e)
[Mon Aug 29 07:44:16.495020 2016] [:error] [pid 2910:tid 140158984734464] [client 10.0.2.2:51105]   File "/usr/local/lib/python2.7/dist-packages/flask/app.py", line 1639, in full_dispatch_request
[Mon Aug 29 07:44:16.495095 2016] [:error] [pid 2910:tid 140158984734464] [client 10.0.2.2:51105]     rv = self.dispatch_request()
[Mon Aug 29 07:44:16.495161 2016] [:error] [pid 2910:tid 140158984734464] [client 10.0.2.2:51105]   File "/usr/local/lib/python2.7/dist-packages/flask/app.py", line 1625, in dispatch_request
[Mon Aug 29 07:44:16.495235 2016] [:error] [pid 2910:tid 140158984734464] [client 10.0.2.2:51105]     return self.view_functions[rule.endpoint](**req.view_args)
[Mon Aug 29 07:44:16.495301 2016] [:error] [pid 2910:tid 140158984734464] [client 10.0.2.2:51105]   File "/usr/local/lib/python2.7/dist-packages/flask_restful/__init__.py", line 477, in wrapper
[Mon Aug 29 07:44:16.495374 2016] [:error] [pid 2910:tid 140158984734464] [client 10.0.2.2:51105]     resp = resource(*args, **kwargs)
[Mon Aug 29 07:44:16.495441 2016] [:error] [pid 2910:tid 140158984734464] [client 10.0.2.2:51105]   File "/usr/local/lib/python2.7/dist-packages/flask/views.py", line 83, in view
[Mon Aug 29 07:44:16.495564 2016] [:error] [pid 2910:tid 140158984734464] [client 10.0.2.2:51105]     self = view.view_class(*class_args, **class_kwargs)
[Mon Aug 29 07:44:16.495633 2016] [:error] [pid 2910:tid 140158984734464] [client 10.0.2.2:51105]   File "/var/www/virginia/resources/monologue.py", line 36, in __init__
[Mon Aug 29 07:44:16.496916 2016] [:error] [pid 2910:tid 140158984734464] [client 10.0.2.2:51105]     self.processor = TextBlobProcessor()
[Mon Aug 29 07:44:16.496993 2016] [:error] [pid 2910:tid 140158984734464] [client 10.0.2.2:51105]   File "/var/www/virginia/processors/textblob_processor.py", line 12, in __init__
[Mon Aug 29 07:44:16.497994 2016] [:error] [pid 2910:tid 140158984734464] [client 10.0.2.2:51105]     nltk.data.path.append('/var/www/virginia/nltk_data/')
[Mon Aug 29 07:44:16.498107 2016] [:error] [pid 2910:tid 140158984734464] [client 10.0.2.2:51105] NameError: global name 'nltk' is not defined
[Mon Aug 29 07:44:53.789194 2016] [ssl:warn] [pid 2809:tid 140159275054976] AH01909: RSA certificate configured for localhost:443 does NOT include an ID which matches the server name
[Mon Aug 29 07:45:14.059911 2016] [:error] [pid 2994:tid 140158984734464] [client 10.0.2.2:51255] mod_wsgi (pid=2994): Exception occurred processing WSGI script '/var/www/virginia/server.wsgi'.
[Mon Aug 29 07:45:14.060378 2016] [:error] [pid 2994:tid 140158984734464] [client 10.0.2.2:51255] Traceback (most recent call last):
[Mon Aug 29 07:45:14.060697 2016] [:error] [pid 2994:tid 140158984734464] [client 10.0.2.2:51255]   File "/usr/local/lib/python2.7/dist-packages/flask/app.py", line 2000, in __call__
[Mon Aug 29 07:45:14.062692 2016] [:error] [pid 2994:tid 140158984734464] [client 10.0.2.2:51255]     return self.wsgi_app(environ, start_response)
[Mon Aug 29 07:45:14.062809 2016] [:error] [pid 2994:tid 140158984734464] [client 10.0.2.2:51255]   File "/usr/local/lib/python2.7/dist-packages/flask/app.py", line 1991, in wsgi_app
[Mon Aug 29 07:45:14.062909 2016] [:error] [pid 2994:tid 140158984734464] [client 10.0.2.2:51255]     response = self.make_response(self.handle_exception(e))
[Mon Aug 29 07:45:14.062988 2016] [:error] [pid 2994:tid 140158984734464] [client 10.0.2.2:51255]   File "/usr/local/lib/python2.7/dist-packages/flask_restful/__init__.py", line 271, in error_router
[Mon Aug 29 07:45:14.064423 2016] [:error] [pid 2994:tid 140158984734464] [client 10.0.2.2:51255]     return original_handler(e)
[Mon Aug 29 07:45:14.064505 2016] [:error] [pid 2994:tid 140158984734464] [client 10.0.2.2:51255]   File "/usr/local/lib/python2.7/dist-packages/flask/app.py", line 1567, in handle_exception
[Mon Aug 29 07:45:14.064591 2016] [:error] [pid 2994:tid 140158984734464] [client 10.0.2.2:51255]     reraise(exc_type, exc_value, tb)
[Mon Aug 29 07:45:14.064665 2016] [:error] [pid 2994:tid 140158984734464] [client 10.0.2.2:51255]   File "/usr/local/lib/python2.7/dist-packages/flask_restful/__init__.py", line 268, in error_router
[Mon Aug 29 07:45:14.064747 2016] [:error] [pid 2994:tid 140158984734464] [client 10.0.2.2:51255]     return self.handle_error(e)
[Mon Aug 29 07:45:14.064834 2016] [:error] [pid 2994:tid 140158984734464] [client 10.0.2.2:51255]   File "/usr/local/lib/python2.7/dist-packages/flask/app.py", line 1988, in wsgi_app
[Mon Aug 29 07:45:14.064915 2016] [:error] [pid 2994:tid 140158984734464] [client 10.0.2.2:51255]     response = self.full_dispatch_request()
[Mon Aug 29 07:45:14.064990 2016] [:error] [pid 2994:tid 140158984734464] [client 10.0.2.2:51255]   File "/usr/local/lib/python2.7/dist-packages/flask/app.py", line 1641, in full_dispatch_request
[Mon Aug 29 07:45:14.065070 2016] [:error] [pid 2994:tid 140158984734464] [client 10.0.2.2:51255]     rv = self.handle_user_exception(e)
[Mon Aug 29 07:45:14.065143 2016] [:error] [pid 2994:tid 140158984734464] [client 10.0.2.2:51255]   File "/usr/local/lib/python2.7/dist-packages/flask_restful/__init__.py", line 271, in error_router
[Mon Aug 29 07:45:14.065222 2016] [:error] [pid 2994:tid 140158984734464] [client 10.0.2.2:51255]     return original_handler(e)
[Mon Aug 29 07:45:14.065295 2016] [:error] [pid 2994:tid 140158984734464] [client 10.0.2.2:51255]   File "/usr/local/lib/python2.7/dist-packages/flask/app.py", line 1544, in handle_user_exception
[Mon Aug 29 07:45:14.065375 2016] [:error] [pid 2994:tid 140158984734464] [client 10.0.2.2:51255]     reraise(exc_type, exc_value, tb)
[Mon Aug 29 07:45:14.065447 2016] [:error] [pid 2994:tid 140158984734464] [client 10.0.2.2:51255]   File "/usr/local/lib/python2.7/dist-packages/flask_restful/__init__.py", line 268, in error_router
[Mon Aug 29 07:45:14.065527 2016] [:error] [pid 2994:tid 140158984734464] [client 10.0.2.2:51255]     return self.handle_error(e)
[Mon Aug 29 07:45:14.065600 2016] [:error] [pid 2994:tid 140158984734464] [client 10.0.2.2:51255]   File "/usr/local/lib/python2.7/dist-packages/flask/app.py", line 1639, in full_dispatch_request
[Mon Aug 29 07:45:14.065679 2016] [:error] [pid 2994:tid 140158984734464] [client 10.0.2.2:51255]     rv = self.dispatch_request()
[Mon Aug 29 07:45:14.065752 2016] [:error] [pid 2994:tid 140158984734464] [client 10.0.2.2:51255]   File "/usr/local/lib/python2.7/dist-packages/flask/app.py", line 1625, in dispatch_request
[Mon Aug 29 07:45:14.065833 2016] [:error] [pid 2994:tid 140158984734464] [client 10.0.2.2:51255]     return self.view_functions[rule.endpoint](**req.view_args)
[Mon Aug 29 07:45:14.065933 2016] [:error] [pid 2994:tid 140158984734464] [client 10.0.2.2:51255]   File "/usr/local/lib/python2.7/dist-packages/flask_restful/__init__.py", line 477, in wrapper
[Mon Aug 29 07:45:14.066042 2016] [:error] [pid 2994:tid 140158984734464] [client 10.0.2.2:51255]     resp = resource(*args, **kwargs)
[Mon Aug 29 07:45:14.066118 2016] [:error] [pid 2994:tid 140158984734464] [client 10.0.2.2:51255]   File "/usr/local/lib/python2.7/dist-packages/flask/views.py", line 84, in view
[Mon Aug 29 07:45:14.066363 2016] [:error] [pid 2994:tid 140158984734464] [client 10.0.2.2:51255]     return self.dispatch_request(*args, **kwargs)
[Mon Aug 29 07:45:14.066441 2016] [:error] [pid 2994:tid 140158984734464] [client 10.0.2.2:51255]   File "/usr/local/lib/python2.7/dist-packages/flask_restful/__init__.py", line 587, in dispatch_request
[Mon Aug 29 07:45:14.066523 2016] [:error] [pid 2994:tid 140158984734464] [client 10.0.2.2:51255]     resp = meth(*args, **kwargs)
[Mon Aug 29 07:45:14.066599 2016] [:error] [pid 2994:tid 140158984734464] [client 10.0.2.2:51255]   File "/var/www/virginia/resources/monologue.py", line 67, in post
[Mon Aug 29 07:45:14.068197 2016] [:error] [pid 2994:tid 140158984734464] [client 10.0.2.2:51255]     return json.dumps(self.processor.process(plot, json_data['monologue']))
[Mon Aug 29 07:45:14.068276 2016] [:error] [pid 2994:tid 140158984734464] [client 10.0.2.2:51255]   File "/var/www/virginia/processors/textblob_processor.py", line 38, in process
[Mon Aug 29 07:45:14.069379 2016] [:error] [pid 2994:tid 140158984734464] [client 10.0.2.2:51255]     self.__processingPreflight(monologue)
[Mon Aug 29 07:45:14.069457 2016] [:error] [pid 2994:tid 140158984734464] [client 10.0.2.2:51255]   File "/var/www/virginia/processors/textblob_processor.py", line 22, in __processingPreflight
[Mon Aug 29 07:45:14.069747 2016] [:error] [pid 2994:tid 140158984734464] [client 10.0.2.2:51255]     self.__updateprocessorContext()
[Mon Aug 29 07:45:14.069820 2016] [:error] [pid 2994:tid 140158984734464] [client 10.0.2.2:51255]   File "/var/www/virginia/processors/textblob_processor.py", line 35, in __updateprocessorContext
[Mon Aug 29 07:45:14.070105 2016] [:error] [pid 2994:tid 140158984734464] [client 10.0.2.2:51255]     self._context.create(self.tokens,self._tagEntities(),self._tagPartOfSpeech())
[Mon Aug 29 07:45:14.070177 2016] [:error] [pid 2994:tid 140158984734464] [client 10.0.2.2:51255]   File "/var/www/virginia/processors/textblob_processor.py", line 25, in _tagEntities
[Mon Aug 29 07:45:14.070478 2016] [:error] [pid 2994:tid 140158984734464] [client 10.0.2.2:51255]     return self.nerTagger.tag(self.tokens)
[Mon Aug 29 07:45:14.070552 2016] [:error] [pid 2994:tid 140158984734464] [client 10.0.2.2:51255]   File "/usr/local/lib/python2.7/dist-packages/nltk/tag/stanford.py", line 71, in tag
[Mon Aug 29 07:45:14.071033 2016] [:error] [pid 2994:tid 140158984734464] [client 10.0.2.2:51255]     return sum(self.tag_sents([tokens]), [])
[Mon Aug 29 07:45:14.071114 2016] [:error] [pid 2994:tid 140158984734464] [client 10.0.2.2:51255]   File "/usr/local/lib/python2.7/dist-packages/nltk/tag/stanford.py", line 94, in tag_sents
[Mon Aug 29 07:45:14.071196 2016] [:error] [pid 2994:tid 140158984734464] [client 10.0.2.2:51255]     stdout=PIPE, stderr=PIPE)
[Mon Aug 29 07:45:14.071274 2016] [:error] [pid 2994:tid 140158984734464] [client 10.0.2.2:51255]   File "/usr/local/lib/python2.7/dist-packages/nltk/internals.py", line 134, in java
[Mon Aug 29 07:45:14.072604 2016] [:error] [pid 2994:tid 140158984734464] [client 10.0.2.2:51255]     raise OSError('Java command failed : ' + str(cmd))
[Mon Aug 29 07:45:14.072708 2016] [:error] [pid 2994:tid 140158984734464] [client 10.0.2.2:51255] OSError: Java command failed : ['/usr/lib/jvm/java-8-openjdk-amd64/bin/java', '-mx1000m', '-cp', '/home/vagrant/stanfordnlp/stanford-ner-2015-12-09/stanford-ner-3.6.0-javadoc.jar:/home/vagrant/stanfordnlp/stanford-ner-2015-12-09/stanford-ner-3.6.0-sources.jar:/home/vagrant/stanfordnlp/stanford-ner-2015-12-09/stanford-ner.jar:/home/vagrant/stanfordnlp/stanford-ner-2015-12-09/stanford-ner-3.6.0.jar:/home/vagrant/stanfordnlp/stanford-ner-2015-12-09/lib/slf4j-api.jar:/home/vagrant/stanfordnlp/stanford-ner-2015-12-09/lib/joda-time.jar:/home/vagrant/stanfordnlp/stanford-ner-2015-12-09/lib/stanford-ner-resources.jar:/home/vagrant/stanfordnlp/stanford-ner-2015-12-09/lib/jollyday-0.4.7.jar:/home/vagrant/stanfordnlp/stanford-ner-2015-12-09/lib/slf4j-simple.jar', 'edu.stanford.nlp.ie.crf.CRFClassifier', '-loadClassifier', '/home/vagrant/stanfordnlp/stanford-ner-2015-12-09/classifiers/english.all.3class.distsim.crf.ser.gz', '-textFile', '/tmp/tmpl5rzHa', '-outputFormat', 'slashTags', '-tokenizerFactory', 'edu.stanford.nlp.process.WhitespaceTokenizer', '-tokenizerOptions', '"tokenizeNLs=false"', '-encoding', 'utf8']
[Mon Aug 29 07:48:36.196470 2016] [ssl:warn] [pid 2809:tid 140159275054976] AH01909: RSA certificate configured for localhost:443 does NOT include an ID which matches the server name
[Mon Aug 29 07:48:39.740865 2016] [:error] [pid 3129:tid 140159051876096] [client 10.0.2.2:51293] mod_wsgi (pid=3129): Exception occurred processing WSGI script '/var/www/virginia/server.wsgi'.
[Mon Aug 29 07:48:39.741037 2016] [:error] [pid 3129:tid 140159051876096] [client 10.0.2.2:51293] Traceback (most recent call last):
[Mon Aug 29 07:48:39.741166 2016] [:error] [pid 3129:tid 140159051876096] [client 10.0.2.2:51293]   File "/usr/local/lib/python2.7/dist-packages/flask/app.py", line 2000, in __call__
[Mon Aug 29 07:48:39.741665 2016] [:error] [pid 3129:tid 140159051876096] [client 10.0.2.2:51293]     return self.wsgi_app(environ, start_response)
[Mon Aug 29 07:48:39.741784 2016] [:error] [pid 3129:tid 140159051876096] [client 10.0.2.2:51293]   File "/usr/local/lib/python2.7/dist-packages/flask/app.py", line 1991, in wsgi_app
[Mon Aug 29 07:48:39.741911 2016] [:error] [pid 3129:tid 140159051876096] [client 10.0.2.2:51293]     response = self.make_response(self.handle_exception(e))
[Mon Aug 29 07:48:39.742026 2016] [:error] [pid 3129:tid 140159051876096] [client 10.0.2.2:51293]   File "/usr/local/lib/python2.7/dist-packages/flask_restful/__init__.py", line 271, in error_router
[Mon Aug 29 07:48:39.742264 2016] [:error] [pid 3129:tid 140159051876096] [client 10.0.2.2:51293]     return original_handler(e)
[Mon Aug 29 07:48:39.742355 2016] [:error] [pid 3129:tid 140159051876096] [client 10.0.2.2:51293]   File "/usr/local/lib/python2.7/dist-packages/flask/app.py", line 1567, in handle_exception
[Mon Aug 29 07:48:39.742452 2016] [:error] [pid 3129:tid 140159051876096] [client 10.0.2.2:51293]     reraise(exc_type, exc_value, tb)
[Mon Aug 29 07:48:39.742541 2016] [:error] [pid 3129:tid 140159051876096] [client 10.0.2.2:51293]   File "/usr/local/lib/python2.7/dist-packages/flask_restful/__init__.py", line 268, in error_router
[Mon Aug 29 07:48:39.742636 2016] [:error] [pid 3129:tid 140159051876096] [client 10.0.2.2:51293]     return self.handle_error(e)
[Mon Aug 29 07:48:39.742703 2016] [:error] [pid 3129:tid 140159051876096] [client 10.0.2.2:51293]   File "/usr/local/lib/python2.7/dist-packages/flask/app.py", line 1988, in wsgi_app
[Mon Aug 29 07:48:39.742792 2016] [:error] [pid 3129:tid 140159051876096] [client 10.0.2.2:51293]     response = self.full_dispatch_request()
[Mon Aug 29 07:48:39.742861 2016] [:error] [pid 3129:tid 140159051876096] [client 10.0.2.2:51293]   File "/usr/local/lib/python2.7/dist-packages/flask/app.py", line 1641, in full_dispatch_request
[Mon Aug 29 07:48:39.742934 2016] [:error] [pid 3129:tid 140159051876096] [client 10.0.2.2:51293]     rv = self.handle_user_exception(e)
[Mon Aug 29 07:48:39.743002 2016] [:error] [pid 3129:tid 140159051876096] [client 10.0.2.2:51293]   File "/usr/local/lib/python2.7/dist-packages/flask_restful/__init__.py", line 271, in error_router
[Mon Aug 29 07:48:39.743075 2016] [:error] [pid 3129:tid 140159051876096] [client 10.0.2.2:51293]     return original_handler(e)
[Mon Aug 29 07:48:39.743141 2016] [:error] [pid 3129:tid 140159051876096] [client 10.0.2.2:51293]   File "/usr/local/lib/python2.7/dist-packages/flask/app.py", line 1544, in handle_user_exception
[Mon Aug 29 07:48:39.743216 2016] [:error] [pid 3129:tid 140159051876096] [client 10.0.2.2:51293]     reraise(exc_type, exc_value, tb)
[Mon Aug 29 07:48:39.743282 2016] [:error] [pid 3129:tid 140159051876096] [client 10.0.2.2:51293]   File "/usr/local/lib/python2.7/dist-packages/flask_restful/__init__.py", line 268, in error_router
[Mon Aug 29 07:48:39.743355 2016] [:error] [pid 3129:tid 140159051876096] [client 10.0.2.2:51293]     return self.handle_error(e)
[Mon Aug 29 07:48:39.743421 2016] [:error] [pid 3129:tid 140159051876096] [client 10.0.2.2:51293]   File "/usr/local/lib/python2.7/dist-packages/flask/app.py", line 1639, in full_dispatch_request
[Mon Aug 29 07:48:39.743494 2016] [:error] [pid 3129:tid 140159051876096] [client 10.0.2.2:51293]     rv = self.dispatch_request()
[Mon Aug 29 07:48:39.743560 2016] [:error] [pid 3129:tid 140159051876096] [client 10.0.2.2:51293]   File "/usr/local/lib/python2.7/dist-packages/flask/app.py", line 1625, in dispatch_request
[Mon Aug 29 07:48:39.743633 2016] [:error] [pid 3129:tid 140159051876096] [client 10.0.2.2:51293]     return self.view_functions[rule.endpoint](**req.view_args)
[Mon Aug 29 07:48:39.743700 2016] [:error] [pid 3129:tid 140159051876096] [client 10.0.2.2:51293]   File "/usr/local/lib/python2.7/dist-packages/flask_restful/__init__.py", line 477, in wrapper
[Mon Aug 29 07:48:39.743772 2016] [:error] [pid 3129:tid 140159051876096] [client 10.0.2.2:51293]     resp = resource(*args, **kwargs)
[Mon Aug 29 07:48:39.743839 2016] [:error] [pid 3129:tid 140159051876096] [client 10.0.2.2:51293]   File "/usr/local/lib/python2.7/dist-packages/flask/views.py", line 83, in view
[Mon Aug 29 07:48:39.743966 2016] [:error] [pid 3129:tid 140159051876096] [client 10.0.2.2:51293]     self = view.view_class(*class_args, **class_kwargs)
[Mon Aug 29 07:48:39.744043 2016] [:error] [pid 3129:tid 140159051876096] [client 10.0.2.2:51293]   File "/var/www/virginia/resources/monologue.py", line 36, in __init__
[Mon Aug 29 07:48:39.745374 2016] [:error] [pid 3129:tid 140159051876096] [client 10.0.2.2:51293]     self.processor = TextBlobProcessor()
[Mon Aug 29 07:48:39.745751 2016] [:error] [pid 3129:tid 140159051876096] [client 10.0.2.2:51293]   File "/var/www/virginia/processors/textblob_processor.py", line 9, in __init__
[Mon Aug 29 07:48:39.747432 2016] [:error] [pid 3129:tid 140159051876096] [client 10.0.2.2:51293]     self.nerTagger = StanfordNERTagger('english.all.3class.distsim.crf.ser.gz')
[Mon Aug 29 07:48:39.747587 2016] [:error] [pid 3129:tid 140159051876096] [client 10.0.2.2:51293] NameError: global name 'StanfordNERTagger' is not defined
[Mon Aug 29 07:49:44.242722 2016] [ssl:warn] [pid 2809:tid 140159275054976] AH01909: RSA certificate configured for localhost:443 does NOT include an ID which matches the server name
[Mon Aug 29 07:49:49.036298 2016] [:error] [pid 3212:tid 140159166707456] [client 10.0.2.2:51300] mod_wsgi (pid=3212): Exception occurred processing WSGI script '/var/www/virginia/server.wsgi'.
[Mon Aug 29 07:49:49.036408 2016] [:error] [pid 3212:tid 140159166707456] [client 10.0.2.2:51300] Traceback (most recent call last):
[Mon Aug 29 07:49:49.036485 2016] [:error] [pid 3212:tid 140159166707456] [client 10.0.2.2:51300]   File "/usr/local/lib/python2.7/dist-packages/flask/app.py", line 2000, in __call__
[Mon Aug 29 07:49:49.036893 2016] [:error] [pid 3212:tid 140159166707456] [client 10.0.2.2:51300]     return self.wsgi_app(environ, start_response)
[Mon Aug 29 07:49:49.036967 2016] [:error] [pid 3212:tid 140159166707456] [client 10.0.2.2:51300]   File "/usr/local/lib/python2.7/dist-packages/flask/app.py", line 1991, in wsgi_app
[Mon Aug 29 07:49:49.037045 2016] [:error] [pid 3212:tid 140159166707456] [client 10.0.2.2:51300]     response = self.make_response(self.handle_exception(e))
[Mon Aug 29 07:49:49.037114 2016] [:error] [pid 3212:tid 140159166707456] [client 10.0.2.2:51300]   File "/usr/local/lib/python2.7/dist-packages/flask_restful/__init__.py", line 271, in error_router
[Mon Aug 29 07:49:49.037322 2016] [:error] [pid 3212:tid 140159166707456] [client 10.0.2.2:51300]     return original_handler(e)
[Mon Aug 29 07:49:49.037421 2016] [:error] [pid 3212:tid 140159166707456] [client 10.0.2.2:51300]   File "/usr/local/lib/python2.7/dist-packages/flask/app.py", line 1567, in handle_exception
[Mon Aug 29 07:49:49.037498 2016] [:error] [pid 3212:tid 140159166707456] [client 10.0.2.2:51300]     reraise(exc_type, exc_value, tb)
[Mon Aug 29 07:49:49.037566 2016] [:error] [pid 3212:tid 140159166707456] [client 10.0.2.2:51300]   File "/usr/local/lib/python2.7/dist-packages/flask_restful/__init__.py", line 268, in error_router
[Mon Aug 29 07:49:49.037640 2016] [:error] [pid 3212:tid 140159166707456] [client 10.0.2.2:51300]     return self.handle_error(e)
[Mon Aug 29 07:49:49.037716 2016] [:error] [pid 3212:tid 140159166707456] [client 10.0.2.2:51300]   File "/usr/local/lib/python2.7/dist-packages/flask/app.py", line 1988, in wsgi_app
[Mon Aug 29 07:49:49.037791 2016] [:error] [pid 3212:tid 140159166707456] [client 10.0.2.2:51300]     response = self.full_dispatch_request()
[Mon Aug 29 07:49:49.037858 2016] [:error] [pid 3212:tid 140159166707456] [client 10.0.2.2:51300]   File "/usr/local/lib/python2.7/dist-packages/flask/app.py", line 1641, in full_dispatch_request
[Mon Aug 29 07:49:49.037931 2016] [:error] [pid 3212:tid 140159166707456] [client 10.0.2.2:51300]     rv = self.handle_user_exception(e)
[Mon Aug 29 07:49:49.037998 2016] [:error] [pid 3212:tid 140159166707456] [client 10.0.2.2:51300]   File "/usr/local/lib/python2.7/dist-packages/flask_restful/__init__.py", line 271, in error_router
[Mon Aug 29 07:49:49.038071 2016] [:error] [pid 3212:tid 140159166707456] [client 10.0.2.2:51300]     return original_handler(e)
[Mon Aug 29 07:49:49.038138 2016] [:error] [pid 3212:tid 140159166707456] [client 10.0.2.2:51300]   File "/usr/local/lib/python2.7/dist-packages/flask/app.py", line 1544, in handle_user_exception
[Mon Aug 29 07:49:49.038218 2016] [:error] [pid 3212:tid 140159166707456] [client 10.0.2.2:51300]     reraise(exc_type, exc_value, tb)
[Mon Aug 29 07:49:49.038284 2016] [:error] [pid 3212:tid 140159166707456] [client 10.0.2.2:51300]   File "/usr/local/lib/python2.7/dist-packages/flask_restful/__init__.py", line 268, in error_router
[Mon Aug 29 07:49:49.038358 2016] [:error] [pid 3212:tid 140159166707456] [client 10.0.2.2:51300]     return self.handle_error(e)
[Mon Aug 29 07:49:49.038424 2016] [:error] [pid 3212:tid 140159166707456] [client 10.0.2.2:51300]   File "/usr/local/lib/python2.7/dist-packages/flask/app.py", line 1639, in full_dispatch_request
[Mon Aug 29 07:49:49.038497 2016] [:error] [pid 3212:tid 140159166707456] [client 10.0.2.2:51300]     rv = self.dispatch_request()
[Mon Aug 29 07:49:49.038564 2016] [:error] [pid 3212:tid 140159166707456] [client 10.0.2.2:51300]   File "/usr/local/lib/python2.7/dist-packages/flask/app.py", line 1625, in dispatch_request
[Mon Aug 29 07:49:49.038637 2016] [:error] [pid 3212:tid 140159166707456] [client 10.0.2.2:51300]     return self.view_functions[rule.endpoint](**req.view_args)
[Mon Aug 29 07:49:49.038756 2016] [:error] [pid 3212:tid 140159166707456] [client 10.0.2.2:51300]   File "/usr/local/lib/python2.7/dist-packages/flask_restful/__init__.py", line 477, in wrapper
[Mon Aug 29 07:49:49.038832 2016] [:error] [pid 3212:tid 140159166707456] [client 10.0.2.2:51300]     resp = resource(*args, **kwargs)
[Mon Aug 29 07:49:49.038899 2016] [:error] [pid 3212:tid 140159166707456] [client 10.0.2.2:51300]   File "/usr/local/lib/python2.7/dist-packages/flask/views.py", line 84, in view
[Mon Aug 29 07:49:49.039019 2016] [:error] [pid 3212:tid 140159166707456] [client 10.0.2.2:51300]     return self.dispatch_request(*args, **kwargs)
[Mon Aug 29 07:49:49.039089 2016] [:error] [pid 3212:tid 140159166707456] [client 10.0.2.2:51300]   File "/usr/local/lib/python2.7/dist-packages/flask_restful/__init__.py", line 587, in dispatch_request
[Mon Aug 29 07:49:49.039164 2016] [:error] [pid 3212:tid 140159166707456] [client 10.0.2.2:51300]     resp = meth(*args, **kwargs)
[Mon Aug 29 07:49:49.039239 2016] [:error] [pid 3212:tid 140159166707456] [client 10.0.2.2:51300]   File "/var/www/virginia/resources/monologue.py", line 67, in post
[Mon Aug 29 07:49:49.040459 2016] [:error] [pid 3212:tid 140159166707456] [client 10.0.2.2:51300]     return json.dumps(self.processor.process(plot, json_data['monologue']))
[Mon Aug 29 07:49:49.040534 2016] [:error] [pid 3212:tid 140159166707456] [client 10.0.2.2:51300]   File "/var/www/virginia/processors/textblob_processor.py", line 40, in process
[Mon Aug 29 07:49:49.041588 2016] [:error] [pid 3212:tid 140159166707456] [client 10.0.2.2:51300]     self.__processingPreflight(monologue)
[Mon Aug 29 07:49:49.041659 2016] [:error] [pid 3212:tid 140159166707456] [client 10.0.2.2:51300]   File "/var/www/virginia/processors/textblob_processor.py", line 24, in __processingPreflight
[Mon Aug 29 07:49:49.041958 2016] [:error] [pid 3212:tid 140159166707456] [client 10.0.2.2:51300]     self.__updateprocessorContext()
[Mon Aug 29 07:49:49.042026 2016] [:error] [pid 3212:tid 140159166707456] [client 10.0.2.2:51300]   File "/var/www/virginia/processors/textblob_processor.py", line 37, in __updateprocessorContext
[Mon Aug 29 07:49:49.042314 2016] [:error] [pid 3212:tid 140159166707456] [client 10.0.2.2:51300]     self._context.create(self.tokens,self._tagEntities(),self._tagPartOfSpeech())
[Mon Aug 29 07:49:49.042384 2016] [:error] [pid 3212:tid 140159166707456] [client 10.0.2.2:51300]   File "/var/www/virginia/processors/textblob_processor.py", line 32, in _tagPartOfSpeech
[Mon Aug 29 07:49:49.042669 2016] [:error] [pid 3212:tid 140159166707456] [client 10.0.2.2:51300]     posTags = blob(self.monologue,self.posTagger)
[Mon Aug 29 07:49:49.042754 2016] [:error] [pid 3212:tid 140159166707456] [client 10.0.2.2:51300]   File "/usr/local/lib/python2.7/dist-packages/textblob/blob.py", line 352, in __init__
[Mon Aug 29 07:49:49.044147 2016] [:error] [pid 3212:tid 140159166707456] [client 10.0.2.2:51300]     parser, classifier)
[Mon Aug 29 07:49:49.044212 2016] [:error] [pid 3212:tid 140159166707456] [client 10.0.2.2:51300]   File "/usr/local/lib/python2.7/dist-packages/textblob/blob.py", line 299, in _initialize_models
[Mon Aug 29 07:49:49.044298 2016] [:error] [pid 3212:tid 140159166707456] [client 10.0.2.2:51300]     base_class_name="BaseTokenizer")
[Mon Aug 29 07:49:49.044373 2016] [:error] [pid 3212:tid 140159166707456] [client 10.0.2.2:51300]   File "/usr/local/lib/python2.7/dist-packages/textblob/blob.py", line 288, in _validated_param
[Mon Aug 29 07:49:49.044454 2016] [:error] [pid 3212:tid 140159166707456] [client 10.0.2.2:51300]     .format(name=name, cls=base_class_name))
[Mon Aug 29 07:49:49.044540 2016] [:error] [pid 3212:tid 140159166707456] [client 10.0.2.2:51300] ValueError: tokenizer must be an instance of BaseTokenizer
[Mon Aug 29 08:01:34.144095 2016] [ssl:warn] [pid 2809:tid 140159275054976] AH01909: RSA certificate configured for localhost:443 does NOT include an ID which matches the server name
[Mon Aug 29 08:08:29.022949 2016] [ssl:warn] [pid 1544:tid 140716694882176] AH01909: RSA certificate configured for localhost:443 does NOT include an ID which matches the server name
[Mon Aug 29 08:08:29.035745 2016] [ssl:warn] [pid 1545:tid 140716694882176] AH01909: RSA certificate configured for localhost:443 does NOT include an ID which matches the server name
[Mon Aug 29 08:09:35.902136 2016] [:error] [pid 1548:tid 140716374173440] [client 10.0.2.2:52298] mod_wsgi (pid=1548): Exception occurred processing WSGI script '/var/www/virginia/server.wsgi'.
[Mon Aug 29 08:09:35.902238 2016] [:error] [pid 1548:tid 140716374173440] [client 10.0.2.2:52298] Traceback (most recent call last):
[Mon Aug 29 08:09:35.902317 2016] [:error] [pid 1548:tid 140716374173440] [client 10.0.2.2:52298]   File "/usr/local/lib/python2.7/dist-packages/flask/app.py", line 2000, in __call__
[Mon Aug 29 08:09:35.902985 2016] [:error] [pid 1548:tid 140716374173440] [client 10.0.2.2:52298]     return self.wsgi_app(environ, start_response)
[Mon Aug 29 08:09:35.903066 2016] [:error] [pid 1548:tid 140716374173440] [client 10.0.2.2:52298]   File "/usr/local/lib/python2.7/dist-packages/flask/app.py", line 1991, in wsgi_app
[Mon Aug 29 08:09:35.903175 2016] [:error] [pid 1548:tid 140716374173440] [client 10.0.2.2:52298]     response = self.make_response(self.handle_exception(e))
[Mon Aug 29 08:09:35.903242 2016] [:error] [pid 1548:tid 140716374173440] [client 10.0.2.2:52298]   File "/usr/local/lib/python2.7/dist-packages/flask_restful/__init__.py", line 271, in error_router
[Mon Aug 29 08:09:35.903587 2016] [:error] [pid 1548:tid 140716374173440] [client 10.0.2.2:52298]     return original_handler(e)
[Mon Aug 29 08:09:35.903656 2016] [:error] [pid 1548:tid 140716374173440] [client 10.0.2.2:52298]   File "/usr/local/lib/python2.7/dist-packages/flask/app.py", line 1567, in handle_exception
[Mon Aug 29 08:09:35.903728 2016] [:error] [pid 1548:tid 140716374173440] [client 10.0.2.2:52298]     reraise(exc_type, exc_value, tb)
[Mon Aug 29 08:09:35.903793 2016] [:error] [pid 1548:tid 140716374173440] [client 10.0.2.2:52298]   File "/usr/local/lib/python2.7/dist-packages/flask_restful/__init__.py", line 268, in error_router
[Mon Aug 29 08:09:35.903863 2016] [:error] [pid 1548:tid 140716374173440] [client 10.0.2.2:52298]     return self.handle_error(e)
[Mon Aug 29 08:09:35.903928 2016] [:error] [pid 1548:tid 140716374173440] [client 10.0.2.2:52298]   File "/usr/local/lib/python2.7/dist-packages/flask/app.py", line 1988, in wsgi_app
[Mon Aug 29 08:09:35.903999 2016] [:error] [pid 1548:tid 140716374173440] [client 10.0.2.2:52298]     response = self.full_dispatch_request()
[Mon Aug 29 08:09:35.904070 2016] [:error] [pid 1548:tid 140716374173440] [client 10.0.2.2:52298]   File "/usr/local/lib/python2.7/dist-packages/flask/app.py", line 1641, in full_dispatch_request
[Mon Aug 29 08:09:35.904140 2016] [:error] [pid 1548:tid 140716374173440] [client 10.0.2.2:52298]     rv = self.handle_user_exception(e)
[Mon Aug 29 08:09:35.904205 2016] [:error] [pid 1548:tid 140716374173440] [client 10.0.2.2:52298]   File "/usr/local/lib/python2.7/dist-packages/flask_restful/__init__.py", line 271, in error_router
[Mon Aug 29 08:09:35.904274 2016] [:error] [pid 1548:tid 140716374173440] [client 10.0.2.2:52298]     return original_handler(e)
[Mon Aug 29 08:09:35.904340 2016] [:error] [pid 1548:tid 140716374173440] [client 10.0.2.2:52298]   File "/usr/local/lib/python2.7/dist-packages/flask/app.py", line 1544, in handle_user_exception
[Mon Aug 29 08:09:35.904410 2016] [:error] [pid 1548:tid 140716374173440] [client 10.0.2.2:52298]     reraise(exc_type, exc_value, tb)
[Mon Aug 29 08:09:35.904473 2016] [:error] [pid 1548:tid 140716374173440] [client 10.0.2.2:52298]   File "/usr/local/lib/python2.7/dist-packages/flask_restful/__init__.py", line 268, in error_router
[Mon Aug 29 08:09:35.904543 2016] [:error] [pid 1548:tid 140716374173440] [client 10.0.2.2:52298]     return self.handle_error(e)
[Mon Aug 29 08:09:35.904595 2016] [:error] [pid 1548:tid 140716374173440] [client 10.0.2.2:52298]   File "/usr/local/lib/python2.7/dist-packages/flask/app.py", line 1639, in full_dispatch_request
[Mon Aug 29 08:09:35.904665 2016] [:error] [pid 1548:tid 140716374173440] [client 10.0.2.2:52298]     rv = self.dispatch_request()
[Mon Aug 29 08:09:35.904728 2016] [:error] [pid 1548:tid 140716374173440] [client 10.0.2.2:52298]   File "/usr/local/lib/python2.7/dist-packages/flask/app.py", line 1625, in dispatch_request
[Mon Aug 29 08:09:35.904798 2016] [:error] [pid 1548:tid 140716374173440] [client 10.0.2.2:52298]     return self.view_functions[rule.endpoint](**req.view_args)
[Mon Aug 29 08:09:35.904864 2016] [:error] [pid 1548:tid 140716374173440] [client 10.0.2.2:52298]   File "/usr/local/lib/python2.7/dist-packages/flask_restful/__init__.py", line 477, in wrapper
[Mon Aug 29 08:09:35.904934 2016] [:error] [pid 1548:tid 140716374173440] [client 10.0.2.2:52298]     resp = resource(*args, **kwargs)
[Mon Aug 29 08:09:35.904998 2016] [:error] [pid 1548:tid 140716374173440] [client 10.0.2.2:52298]   File "/usr/local/lib/python2.7/dist-packages/flask/views.py", line 84, in view
[Mon Aug 29 08:09:35.905216 2016] [:error] [pid 1548:tid 140716374173440] [client 10.0.2.2:52298]     return self.dispatch_request(*args, **kwargs)
[Mon Aug 29 08:09:35.905320 2016] [:error] [pid 1548:tid 140716374173440] [client 10.0.2.2:52298]   File "/usr/local/lib/python2.7/dist-packages/flask_restful/__init__.py", line 587, in dispatch_request
[Mon Aug 29 08:09:35.905393 2016] [:error] [pid 1548:tid 140716374173440] [client 10.0.2.2:52298]     resp = meth(*args, **kwargs)
[Mon Aug 29 08:09:35.905479 2016] [:error] [pid 1548:tid 140716374173440] [client 10.0.2.2:52298]   File "/var/www/virginia/resources/monologue.py", line 67, in post
[Mon Aug 29 08:09:35.906645 2016] [:error] [pid 1548:tid 140716374173440] [client 10.0.2.2:52298]     return json.dumps(self.processor.process(plot, json_data['monologue']))
[Mon Aug 29 08:09:35.906718 2016] [:error] [pid 1548:tid 140716374173440] [client 10.0.2.2:52298]   File "/var/www/virginia/processors/textblob_processor.py", line 40, in process
[Mon Aug 29 08:09:35.907771 2016] [:error] [pid 1548:tid 140716374173440] [client 10.0.2.2:52298]     self.__processingPreflight(monologue)
[Mon Aug 29 08:09:35.907843 2016] [:error] [pid 1548:tid 140716374173440] [client 10.0.2.2:52298]   File "/var/www/virginia/processors/textblob_processor.py", line 24, in __processingPreflight
[Mon Aug 29 08:09:35.908125 2016] [:error] [pid 1548:tid 140716374173440] [client 10.0.2.2:52298]     self.__updateprocessorContext()
[Mon Aug 29 08:09:35.908190 2016] [:error] [pid 1548:tid 140716374173440] [client 10.0.2.2:52298]   File "/var/www/virginia/processors/textblob_processor.py", line 37, in __updateprocessorContext
[Mon Aug 29 08:09:35.908465 2016] [:error] [pid 1548:tid 140716374173440] [client 10.0.2.2:52298]     self._context.create(self.tokens,self._tagEntities(),self._tagPartOfSpeech())
[Mon Aug 29 08:09:35.908539 2016] [:error] [pid 1548:tid 140716374173440] [client 10.0.2.2:52298]   File "/var/www/virginia/processors/textblob_processor.py", line 32, in _tagPartOfSpeech
[Mon Aug 29 08:09:35.908811 2016] [:error] [pid 1548:tid 140716374173440] [client 10.0.2.2:52298]     posTags = tb(self.monologue,self.posTagger)
[Mon Aug 29 08:09:35.908876 2016] [:error] [pid 1548:tid 140716374173440] [client 10.0.2.2:52298]   File "/usr/local/lib/python2.7/dist-packages/textblob/blob.py", line 352, in __init__
[Mon Aug 29 08:09:35.909213 2016] [:error] [pid 1548:tid 140716374173440] [client 10.0.2.2:52298]     parser, classifier)
[Mon Aug 29 08:09:35.909284 2016] [:error] [pid 1548:tid 140716374173440] [client 10.0.2.2:52298]   File "/usr/local/lib/python2.7/dist-packages/textblob/blob.py", line 299, in _initialize_models
[Mon Aug 29 08:09:35.909356 2016] [:error] [pid 1548:tid 140716374173440] [client 10.0.2.2:52298]     base_class_name="BaseTokenizer")
[Mon Aug 29 08:09:35.909421 2016] [:error] [pid 1548:tid 140716374173440] [client 10.0.2.2:52298]   File "/usr/local/lib/python2.7/dist-packages/textblob/blob.py", line 288, in _validated_param
[Mon Aug 29 08:09:35.909492 2016] [:error] [pid 1548:tid 140716374173440] [client 10.0.2.2:52298]     .format(name=name, cls=base_class_name))
[Mon Aug 29 08:09:35.909572 2016] [:error] [pid 1548:tid 140716374173440] [client 10.0.2.2:52298] ValueError: tokenizer must be an instance of BaseTokenizer
[Mon Aug 29 08:13:21.237979 2016] [ssl:warn] [pid 1545:tid 140716694882176] AH01909: RSA certificate configured for localhost:443 does NOT include an ID which matches the server name
[Mon Aug 29 08:13:27.363998 2016] [:error] [pid 1705:tid 140716474885888] [client 10.0.2.2:52598] mod_wsgi (pid=1705): Exception occurred processing WSGI script '/var/www/virginia/server.wsgi'.
[Mon Aug 29 08:13:27.364118 2016] [:error] [pid 1705:tid 140716474885888] [client 10.0.2.2:52598] Traceback (most recent call last):
[Mon Aug 29 08:13:27.364201 2016] [:error] [pid 1705:tid 140716474885888] [client 10.0.2.2:52598]   File "/usr/local/lib/python2.7/dist-packages/flask/app.py", line 2000, in __call__
[Mon Aug 29 08:13:27.364631 2016] [:error] [pid 1705:tid 140716474885888] [client 10.0.2.2:52598]     return self.wsgi_app(environ, start_response)
[Mon Aug 29 08:13:27.364705 2016] [:error] [pid 1705:tid 140716474885888] [client 10.0.2.2:52598]   File "/usr/local/lib/python2.7/dist-packages/flask/app.py", line 1991, in wsgi_app
[Mon Aug 29 08:13:27.364782 2016] [:error] [pid 1705:tid 140716474885888] [client 10.0.2.2:52598]     response = self.make_response(self.handle_exception(e))
[Mon Aug 29 08:13:27.364851 2016] [:error] [pid 1705:tid 140716474885888] [client 10.0.2.2:52598]   File "/usr/local/lib/python2.7/dist-packages/flask_restful/__init__.py", line 271, in error_router
[Mon Aug 29 08:13:27.365048 2016] [:error] [pid 1705:tid 140716474885888] [client 10.0.2.2:52598]     return original_handler(e)
[Mon Aug 29 08:13:27.365117 2016] [:error] [pid 1705:tid 140716474885888] [client 10.0.2.2:52598]   File "/usr/local/lib/python2.7/dist-packages/flask/app.py", line 1567, in handle_exception
[Mon Aug 29 08:13:27.365191 2016] [:error] [pid 1705:tid 140716474885888] [client 10.0.2.2:52598]     reraise(exc_type, exc_value, tb)
[Mon Aug 29 08:13:27.365256 2016] [:error] [pid 1705:tid 140716474885888] [client 10.0.2.2:52598]   File "/usr/local/lib/python2.7/dist-packages/flask_restful/__init__.py", line 268, in error_router
[Mon Aug 29 08:13:27.365339 2016] [:error] [pid 1705:tid 140716474885888] [client 10.0.2.2:52598]     return self.handle_error(e)
[Mon Aug 29 08:13:27.365404 2016] [:error] [pid 1705:tid 140716474885888] [client 10.0.2.2:52598]   File "/usr/local/lib/python2.7/dist-packages/flask/app.py", line 1988, in wsgi_app
[Mon Aug 29 08:13:27.365483 2016] [:error] [pid 1705:tid 140716474885888] [client 10.0.2.2:52598]     response = self.full_dispatch_request()
[Mon Aug 29 08:13:27.365550 2016] [:error] [pid 1705:tid 140716474885888] [client 10.0.2.2:52598]   File "/usr/local/lib/python2.7/dist-packages/flask/app.py", line 1641, in full_dispatch_request
[Mon Aug 29 08:13:27.365621 2016] [:error] [pid 1705:tid 140716474885888] [client 10.0.2.2:52598]     rv = self.handle_user_exception(e)
[Mon Aug 29 08:13:27.365687 2016] [:error] [pid 1705:tid 140716474885888] [client 10.0.2.2:52598]   File "/usr/local/lib/python2.7/dist-packages/flask_restful/__init__.py", line 271, in error_router
[Mon Aug 29 08:13:27.365757 2016] [:error] [pid 1705:tid 140716474885888] [client 10.0.2.2:52598]     return original_handler(e)
[Mon Aug 29 08:13:27.365822 2016] [:error] [pid 1705:tid 140716474885888] [client 10.0.2.2:52598]   File "/usr/local/lib/python2.7/dist-packages/flask/app.py", line 1544, in handle_user_exception
[Mon Aug 29 08:13:27.365895 2016] [:error] [pid 1705:tid 140716474885888] [client 10.0.2.2:52598]     reraise(exc_type, exc_value, tb)
[Mon Aug 29 08:13:27.365959 2016] [:error] [pid 1705:tid 140716474885888] [client 10.0.2.2:52598]   File "/usr/local/lib/python2.7/dist-packages/flask_restful/__init__.py", line 268, in error_router
[Mon Aug 29 08:13:27.366030 2016] [:error] [pid 1705:tid 140716474885888] [client 10.0.2.2:52598]     return self.handle_error(e)
[Mon Aug 29 08:13:27.366094 2016] [:error] [pid 1705:tid 140716474885888] [client 10.0.2.2:52598]   File "/usr/local/lib/python2.7/dist-packages/flask/app.py", line 1639, in full_dispatch_request
[Mon Aug 29 08:13:27.366165 2016] [:error] [pid 1705:tid 140716474885888] [client 10.0.2.2:52598]     rv = self.dispatch_request()
[Mon Aug 29 08:13:27.366229 2016] [:error] [pid 1705:tid 140716474885888] [client 10.0.2.2:52598]   File "/usr/local/lib/python2.7/dist-packages/flask/app.py", line 1625, in dispatch_request
[Mon Aug 29 08:13:27.366299 2016] [:error] [pid 1705:tid 140716474885888] [client 10.0.2.2:52598]     return self.view_functions[rule.endpoint](**req.view_args)
[Mon Aug 29 08:13:27.366366 2016] [:error] [pid 1705:tid 140716474885888] [client 10.0.2.2:52598]   File "/usr/local/lib/python2.7/dist-packages/flask_restful/__init__.py", line 477, in wrapper
[Mon Aug 29 08:13:27.366437 2016] [:error] [pid 1705:tid 140716474885888] [client 10.0.2.2:52598]     resp = resource(*args, **kwargs)
[Mon Aug 29 08:13:27.366501 2016] [:error] [pid 1705:tid 140716474885888] [client 10.0.2.2:52598]   File "/usr/local/lib/python2.7/dist-packages/flask/views.py", line 84, in view
[Mon Aug 29 08:13:27.366618 2016] [:error] [pid 1705:tid 140716474885888] [client 10.0.2.2:52598]     return self.dispatch_request(*args, **kwargs)
[Mon Aug 29 08:13:27.366687 2016] [:error] [pid 1705:tid 140716474885888] [client 10.0.2.2:52598]   File "/usr/local/lib/python2.7/dist-packages/flask_restful/__init__.py", line 587, in dispatch_request
[Mon Aug 29 08:13:27.366761 2016] [:error] [pid 1705:tid 140716474885888] [client 10.0.2.2:52598]     resp = meth(*args, **kwargs)
[Mon Aug 29 08:13:27.366826 2016] [:error] [pid 1705:tid 140716474885888] [client 10.0.2.2:52598]   File "/var/www/virginia/resources/monologue.py", line 67, in post
[Mon Aug 29 08:13:27.368145 2016] [:error] [pid 1705:tid 140716474885888] [client 10.0.2.2:52598]     return json.dumps(self.processor.process(plot, json_data['monologue']))
[Mon Aug 29 08:13:27.368213 2016] [:error] [pid 1705:tid 140716474885888] [client 10.0.2.2:52598]   File "/var/www/virginia/processors/textblob_processor.py", line 40, in process
[Mon Aug 29 08:13:27.369161 2016] [:error] [pid 1705:tid 140716474885888] [client 10.0.2.2:52598]     self.__processingPreflight(monologue)
[Mon Aug 29 08:13:27.369229 2016] [:error] [pid 1705:tid 140716474885888] [client 10.0.2.2:52598]   File "/var/www/virginia/processors/textblob_processor.py", line 24, in __processingPreflight
[Mon Aug 29 08:13:27.369533 2016] [:error] [pid 1705:tid 140716474885888] [client 10.0.2.2:52598]     self.__updateprocessorContext()
[Mon Aug 29 08:13:27.369598 2016] [:error] [pid 1705:tid 140716474885888] [client 10.0.2.2:52598]   File "/var/www/virginia/processors/textblob_processor.py", line 37, in __updateprocessorContext
[Mon Aug 29 08:13:27.369872 2016] [:error] [pid 1705:tid 140716474885888] [client 10.0.2.2:52598]     self._context.create(self.tokens,self._tagEntities(),self._tagPartOfSpeech())
[Mon Aug 29 08:13:27.369939 2016] [:error] [pid 1705:tid 140716474885888] [client 10.0.2.2:52598]   File "/var/www/virginia/processors/textblob_processor.py", line 33, in _tagPartOfSpeech
[Mon Aug 29 08:13:27.370219 2016] [:error] [pid 1705:tid 140716474885888] [client 10.0.2.2:52598]     return posTags.tags
[Mon Aug 29 08:13:27.370286 2016] [:error] [pid 1705:tid 140716474885888] [client 10.0.2.2:52598]   File "/usr/local/lib/python2.7/dist-packages/textblob/decorators.py", line 24, in __get__
[Mon Aug 29 08:13:27.370535 2016] [:error] [pid 1705:tid 140716474885888] [client 10.0.2.2:52598]     value = obj.__dict__[self.func.__name__] = self.func(obj)
[Mon Aug 29 08:13:27.370607 2016] [:error] [pid 1705:tid 140716474885888] [client 10.0.2.2:52598]   File "/usr/local/lib/python2.7/dist-packages/textblob/blob.py", line 445, in pos_tags
[Mon Aug 29 08:13:27.370796 2016] [:error] [pid 1705:tid 140716474885888] [client 10.0.2.2:52598]     for word, t in self.pos_tagger.tag(self.raw)
[Mon Aug 29 08:13:27.370866 2016] [:error] [pid 1705:tid 140716474885888] [client 10.0.2.2:52598]   File "/usr/local/lib/python2.7/dist-packages/textblob_aptagger/taggers.py", line 49, in tag
[Mon Aug 29 08:13:27.371109 2016] [:error] [pid 1705:tid 140716474885888] [client 10.0.2.2:52598]     for words in split_sents(corpus):
[Mon Aug 29 08:13:27.371178 2016] [:error] [pid 1705:tid 140716474885888] [client 10.0.2.2:52598]   File "/usr/local/lib/python2.7/dist-packages/textblob_aptagger/taggers.py", line 44, in split_sents
[Mon Aug 29 08:13:27.371251 2016] [:error] [pid 1705:tid 140716474885888] [client 10.0.2.2:52598]     for s in s_split(corpus):
[Mon Aug 29 08:13:27.371315 2016] [:error] [pid 1705:tid 140716474885888] [client 10.0.2.2:52598]   File "/usr/local/lib/python2.7/dist-packages/textblob/decorators.py", line 38, in decorated
[Mon Aug 29 08:13:27.371387 2016] [:error] [pid 1705:tid 140716474885888] [client 10.0.2.2:52598]     raise MissingCorpusError()
[Mon Aug 29 08:13:27.371460 2016] [:error] [pid 1705:tid 140716474885888] [client 10.0.2.2:52598] MissingCorpusError: 
[Mon Aug 29 08:13:27.371520 2016] [:error] [pid 1705:tid 140716474885888] [client 10.0.2.2:52598] Looks like you are missing some required data for this feature.
[Mon Aug 29 08:13:27.371636 2016] [:error] [pid 1705:tid 140716474885888] [client 10.0.2.2:52598] 
[Mon Aug 29 08:13:27.371697 2016] [:error] [pid 1705:tid 140716474885888] [client 10.0.2.2:52598] To download the necessary data, simply run
[Mon Aug 29 08:13:27.371752 2016] [:error] [pid 1705:tid 140716474885888] [client 10.0.2.2:52598] 
[Mon Aug 29 08:13:27.371807 2016] [:error] [pid 1705:tid 140716474885888] [client 10.0.2.2:52598]     python -m textblob.download_corpora
[Mon Aug 29 08:13:27.371861 2016] [:error] [pid 1705:tid 140716474885888] [client 10.0.2.2:52598] 
[Mon Aug 29 08:13:27.371915 2016] [:error] [pid 1705:tid 140716474885888] [client 10.0.2.2:52598] or use the NLTK downloader to download the missing data: http://nltk.org/data.html
[Mon Aug 29 08:13:27.371970 2016] [:error] [pid 1705:tid 140716474885888] [client 10.0.2.2:52598] If this doesn't fix the problem, file an issue at https://github.com/sloria/TextBlob/issues.
[Mon Aug 29 08:13:27.372030 2016] [:error] [pid 1705:tid 140716474885888] [client 10.0.2.2:52598] 
[Mon Aug 29 08:15:46.451781 2016] [ssl:warn] [pid 1545:tid 140716694882176] AH01909: RSA certificate configured for localhost:443 does NOT include an ID which matches the server name
[Mon Aug 29 08:16:42.701967 2016] [ssl:warn] [pid 1545:tid 140716694882176] AH01909: RSA certificate configured for localhost:443 does NOT include an ID which matches the server name
[Mon Aug 29 08:16:49.673799 2016] [:error] [pid 1873:tid 140716374173440] [client 10.0.2.2:52661] mod_wsgi (pid=1873): Exception occurred processing WSGI script '/var/www/virginia/server.wsgi'.
[Mon Aug 29 08:16:49.674015 2016] [:error] [pid 1873:tid 140716374173440] [client 10.0.2.2:52661] Traceback (most recent call last):
[Mon Aug 29 08:16:49.674116 2016] [:error] [pid 1873:tid 140716374173440] [client 10.0.2.2:52661]   File "/usr/local/lib/python2.7/dist-packages/flask/app.py", line 2000, in __call__
[Mon Aug 29 08:16:49.675159 2016] [:error] [pid 1873:tid 140716374173440] [client 10.0.2.2:52661]     return self.wsgi_app(environ, start_response)
[Mon Aug 29 08:16:49.675244 2016] [:error] [pid 1873:tid 140716374173440] [client 10.0.2.2:52661]   File "/usr/local/lib/python2.7/dist-packages/flask/app.py", line 1991, in wsgi_app
[Mon Aug 29 08:16:49.675342 2016] [:error] [pid 1873:tid 140716374173440] [client 10.0.2.2:52661]     response = self.make_response(self.handle_exception(e))
[Mon Aug 29 08:16:49.675421 2016] [:error] [pid 1873:tid 140716374173440] [client 10.0.2.2:52661]   File "/usr/local/lib/python2.7/dist-packages/flask_restful/__init__.py", line 271, in error_router
[Mon Aug 29 08:16:49.675980 2016] [:error] [pid 1873:tid 140716374173440] [client 10.0.2.2:52661]     return original_handler(e)
[Mon Aug 29 08:16:49.676064 2016] [:error] [pid 1873:tid 140716374173440] [client 10.0.2.2:52661]   File "/usr/local/lib/python2.7/dist-packages/flask/app.py", line 1567, in handle_exception
[Mon Aug 29 08:16:49.676153 2016] [:error] [pid 1873:tid 140716374173440] [client 10.0.2.2:52661]     reraise(exc_type, exc_value, tb)
[Mon Aug 29 08:16:49.676226 2016] [:error] [pid 1873:tid 140716374173440] [client 10.0.2.2:52661]   File "/usr/local/lib/python2.7/dist-packages/flask_restful/__init__.py", line 268, in error_router
[Mon Aug 29 08:16:49.676316 2016] [:error] [pid 1873:tid 140716374173440] [client 10.0.2.2:52661]     return self.handle_error(e)
[Mon Aug 29 08:16:49.676389 2016] [:error] [pid 1873:tid 140716374173440] [client 10.0.2.2:52661]   File "/usr/local/lib/python2.7/dist-packages/flask/app.py", line 1988, in wsgi_app
[Mon Aug 29 08:16:49.676471 2016] [:error] [pid 1873:tid 140716374173440] [client 10.0.2.2:52661]     response = self.full_dispatch_request()
[Mon Aug 29 08:16:49.676550 2016] [:error] [pid 1873:tid 140716374173440] [client 10.0.2.2:52661]   File "/usr/local/lib/python2.7/dist-packages/flask/app.py", line 1641, in full_dispatch_request
[Mon Aug 29 08:16:49.676637 2016] [:error] [pid 1873:tid 140716374173440] [client 10.0.2.2:52661]     rv = self.handle_user_exception(e)
[Mon Aug 29 08:16:49.676767 2016] [:error] [pid 1873:tid 140716374173440] [client 10.0.2.2:52661]   File "/usr/local/lib/python2.7/dist-packages/flask_restful/__init__.py", line 271, in error_router
[Mon Aug 29 08:16:49.676844 2016] [:error] [pid 1873:tid 140716374173440] [client 10.0.2.2:52661]     return original_handler(e)
[Mon Aug 29 08:16:49.676914 2016] [:error] [pid 1873:tid 140716374173440] [client 10.0.2.2:52661]   File "/usr/local/lib/python2.7/dist-packages/flask/app.py", line 1544, in handle_user_exception
[Mon Aug 29 08:16:49.677001 2016] [:error] [pid 1873:tid 140716374173440] [client 10.0.2.2:52661]     reraise(exc_type, exc_value, tb)
[Mon Aug 29 08:16:49.677080 2016] [:error] [pid 1873:tid 140716374173440] [client 10.0.2.2:52661]   File "/usr/local/lib/python2.7/dist-packages/flask_restful/__init__.py", line 268, in error_router
[Mon Aug 29 08:16:49.677156 2016] [:error] [pid 1873:tid 140716374173440] [client 10.0.2.2:52661]     return self.handle_error(e)
[Mon Aug 29 08:16:49.677226 2016] [:error] [pid 1873:tid 140716374173440] [client 10.0.2.2:52661]   File "/usr/local/lib/python2.7/dist-packages/flask/app.py", line 1639, in full_dispatch_request
[Mon Aug 29 08:16:49.677302 2016] [:error] [pid 1873:tid 140716374173440] [client 10.0.2.2:52661]     rv = self.dispatch_request()
[Mon Aug 29 08:16:49.677372 2016] [:error] [pid 1873:tid 140716374173440] [client 10.0.2.2:52661]   File "/usr/local/lib/python2.7/dist-packages/flask/app.py", line 1625, in dispatch_request
[Mon Aug 29 08:16:49.677475 2016] [:error] [pid 1873:tid 140716374173440] [client 10.0.2.2:52661]     return self.view_functions[rule.endpoint](**req.view_args)
[Mon Aug 29 08:16:49.677548 2016] [:error] [pid 1873:tid 140716374173440] [client 10.0.2.2:52661]   File "/usr/local/lib/python2.7/dist-packages/flask_restful/__init__.py", line 477, in wrapper
[Mon Aug 29 08:16:49.677637 2016] [:error] [pid 1873:tid 140716374173440] [client 10.0.2.2:52661]     resp = resource(*args, **kwargs)
[Mon Aug 29 08:16:49.677712 2016] [:error] [pid 1873:tid 140716374173440] [client 10.0.2.2:52661]   File "/usr/local/lib/python2.7/dist-packages/flask/views.py", line 84, in view
[Mon Aug 29 08:16:49.677945 2016] [:error] [pid 1873:tid 140716374173440] [client 10.0.2.2:52661]     return self.dispatch_request(*args, **kwargs)
[Mon Aug 29 08:16:49.678023 2016] [:error] [pid 1873:tid 140716374173440] [client 10.0.2.2:52661]   File "/usr/local/lib/python2.7/dist-packages/flask_restful/__init__.py", line 587, in dispatch_request
[Mon Aug 29 08:16:49.678102 2016] [:error] [pid 1873:tid 140716374173440] [client 10.0.2.2:52661]     resp = meth(*args, **kwargs)
[Mon Aug 29 08:16:49.678176 2016] [:error] [pid 1873:tid 140716374173440] [client 10.0.2.2:52661]   File "/var/www/virginia/resources/monologue.py", line 67, in post
[Mon Aug 29 08:16:49.679591 2016] [:error] [pid 1873:tid 140716374173440] [client 10.0.2.2:52661]     return json.dumps(self.processor.process(plot, json_data['monologue']))
[Mon Aug 29 08:16:49.679669 2016] [:error] [pid 1873:tid 140716374173440] [client 10.0.2.2:52661]   File "/var/www/virginia/processors/textblob_processor.py", line 41, in process
[Mon Aug 29 08:16:49.680713 2016] [:error] [pid 1873:tid 140716374173440] [client 10.0.2.2:52661]     self.__processingPreflight(monologue)
[Mon Aug 29 08:16:49.680791 2016] [:error] [pid 1873:tid 140716374173440] [client 10.0.2.2:52661]   File "/var/www/virginia/processors/textblob_processor.py", line 26, in __processingPreflight
[Mon Aug 29 08:16:49.681092 2016] [:error] [pid 1873:tid 140716374173440] [client 10.0.2.2:52661]     self.__updateprocessorContext()
[Mon Aug 29 08:16:49.681165 2016] [:error] [pid 1873:tid 140716374173440] [client 10.0.2.2:52661]   File "/var/www/virginia/processors/textblob_processor.py", line 38, in __updateprocessorContext
[Mon Aug 29 08:16:49.681486 2016] [:error] [pid 1873:tid 140716374173440] [client 10.0.2.2:52661]     self._context.create(self.tokens,self._tagEntities(),self._tagPartOfSpeech())
[Mon Aug 29 08:16:49.681570 2016] [:error] [pid 1873:tid 140716374173440] [client 10.0.2.2:52661]   File "/var/www/virginia/processors/textblob_processor.py", line 29, in _tagEntities
[Mon Aug 29 08:16:49.681895 2016] [:error] [pid 1873:tid 140716374173440] [client 10.0.2.2:52661]     return self.nerTagger.tag(self.tokens)
[Mon Aug 29 08:16:49.681971 2016] [:error] [pid 1873:tid 140716374173440] [client 10.0.2.2:52661]   File "/usr/local/lib/python2.7/dist-packages/nltk/tag/stanford.py", line 71, in tag
[Mon Aug 29 08:16:49.682374 2016] [:error] [pid 1873:tid 140716374173440] [client 10.0.2.2:52661]     return sum(self.tag_sents([tokens]), [])
[Mon Aug 29 08:16:49.682451 2016] [:error] [pid 1873:tid 140716374173440] [client 10.0.2.2:52661]   File "/usr/local/lib/python2.7/dist-packages/nltk/tag/stanford.py", line 94, in tag_sents
[Mon Aug 29 08:16:49.682529 2016] [:error] [pid 1873:tid 140716374173440] [client 10.0.2.2:52661]     stdout=PIPE, stderr=PIPE)
[Mon Aug 29 08:16:49.682604 2016] [:error] [pid 1873:tid 140716374173440] [client 10.0.2.2:52661]   File "/usr/local/lib/python2.7/dist-packages/nltk/internals.py", line 134, in java
[Mon Aug 29 08:16:49.683014 2016] [:error] [pid 1873:tid 140716374173440] [client 10.0.2.2:52661]     raise OSError('Java command failed : ' + str(cmd))
[Mon Aug 29 08:16:49.683114 2016] [:error] [pid 1873:tid 140716374173440] [client 10.0.2.2:52661] OSError: Java command failed : ['/usr/lib/jvm/java-8-openjdk-amd64/bin/java', '-mx1000m', '-cp', '/home/vagrant/stanfordnlp/stanford-ner-2015-12-09/stanford-ner-3.6.0-javadoc.jar:/home/vagrant/stanfordnlp/stanford-ner-2015-12-09/stanford-ner-3.6.0-sources.jar:/home/vagrant/stanfordnlp/stanford-ner-2015-12-09/stanford-ner.jar:/home/vagrant/stanfordnlp/stanford-ner-2015-12-09/stanford-ner-3.6.0.jar:/home/vagrant/stanfordnlp/stanford-ner-2015-12-09/lib/slf4j-api.jar:/home/vagrant/stanfordnlp/stanford-ner-2015-12-09/lib/joda-time.jar:/home/vagrant/stanfordnlp/stanford-ner-2015-12-09/lib/stanford-ner-resources.jar:/home/vagrant/stanfordnlp/stanford-ner-2015-12-09/lib/jollyday-0.4.7.jar:/home/vagrant/stanfordnlp/stanford-ner-2015-12-09/lib/slf4j-simple.jar', 'edu.stanford.nlp.ie.crf.CRFClassifier', '-loadClassifier', '/home/vagrant/stanfordnlp/stanford-ner-2015-12-09/classifiers/english.all.3class.distsim.crf.ser.gz', '-textFile', '/tmp/tmpW8GlUp', '-outputFormat', 'slashTags', '-tokenizerFactory', 'edu.stanford.nlp.process.WhitespaceTokenizer', '-tokenizerOptions', '"tokenizeNLs=false"', '-encoding', 'utf8']
[Mon Aug 29 08:18:57.177983 2016] [ssl:warn] [pid 1545:tid 140716694882176] AH01909: RSA certificate configured for localhost:443 does NOT include an ID which matches the server name
[Tue Aug 30 12:52:27.010389 2016] [ssl:warn] [pid 1585:tid 139891038173056] AH01909: RSA certificate configured for default:443 does NOT include an ID which matches the server name
[Tue Aug 30 12:52:27.023307 2016] [ssl:warn] [pid 1586:tid 139891038173056] AH01909: RSA certificate configured for default:443 does NOT include an ID which matches the server name
[Tue Aug 30 20:11:50.906394 2016] [ssl:warn] [pid 5689:tid 140634432448384] AH01909: RSA certificate configured for default:443 does NOT include an ID which matches the server name
[Tue Aug 30 20:11:50.919017 2016] [ssl:warn] [pid 5690:tid 140634432448384] AH01909: RSA certificate configured for default:443 does NOT include an ID which matches the server name
[Wed Aug 31 19:24:57.548553 2016] [ssl:warn] [pid 2173:tid 139906149447552] AH01909: RSA certificate configured for default:443 does NOT include an ID which matches the server name
[Wed Aug 31 19:24:57.562017 2016] [ssl:warn] [pid 2174:tid 139906149447552] AH01909: RSA certificate configured for default:443 does NOT include an ID which matches the server name
[Wed Aug 31 19:37:29.112170 2016] [ssl:warn] [pid 2174:tid 139906149447552] AH01909: RSA certificate configured for default:443 does NOT include an ID which matches the server name
[Fri Sep 02 08:24:54.020301 2016] [ssl:warn] [pid 1819:tid 140205179881344] AH01909: RSA certificate configured for default:443 does NOT include an ID which matches the server name
[Fri Sep 02 08:24:54.033932 2016] [ssl:warn] [pid 1820:tid 140205179881344] AH01909: RSA certificate configured for default:443 does NOT include an ID which matches the server name
[Fri Sep 02 08:26:02.081236 2016] [:error] [pid 1824:tid 140204971124480] [client 10.0.2.2:54597] mod_wsgi (pid=1824): Target WSGI script '/var/www/virginia/server.wsgi' cannot be loaded as Python module.
[Fri Sep 02 08:26:02.081320 2016] [:error] [pid 1824:tid 140204971124480] [client 10.0.2.2:54597] mod_wsgi (pid=1824): Exception occurred processing WSGI script '/var/www/virginia/server.wsgi'.
[Fri Sep 02 08:26:02.081411 2016] [:error] [pid 1824:tid 140204971124480] [client 10.0.2.2:54597] Traceback (most recent call last):
[Fri Sep 02 08:26:02.081498 2016] [:error] [pid 1824:tid 140204971124480] [client 10.0.2.2:54597]   File "/var/www/virginia/server.wsgi", line 13, in <module>
[Fri Sep 02 08:26:02.082663 2016] [:error] [pid 1824:tid 140204971124480] [client 10.0.2.2:54597]     from virginia import monologue_svc as application
[Fri Sep 02 08:26:02.082752 2016] [:error] [pid 1824:tid 140204971124480] [client 10.0.2.2:54597]   File "/var/www/virginia/virginia.py", line 6, in <module>
[Fri Sep 02 08:26:02.083790 2016] [:error] [pid 1824:tid 140204971124480] [client 10.0.2.2:54597]     from resources.monologue import Monologue
[Fri Sep 02 08:26:02.083868 2016] [:error] [pid 1824:tid 140204971124480] [client 10.0.2.2:54597]   File "/var/www/virginia/resources/monologue.py", line 4, in <module>
[Fri Sep 02 08:26:02.085209 2016] [:error] [pid 1824:tid 140204971124480] [client 10.0.2.2:54597]     from narrative.plot import Plot
[Fri Sep 02 08:26:02.085292 2016] [:error] [pid 1824:tid 140204971124480] [client 10.0.2.2:54597]   File "/var/www/virginia/narrative/plot.py", line 4, in <module>
[Fri Sep 02 08:26:02.086416 2016] [:error] [pid 1824:tid 140204971124480] [client 10.0.2.2:54597]     from processors.processor_factory import ProcessorFactory
[Fri Sep 02 08:26:02.086500 2016] [:error] [pid 1824:tid 140204971124480] [client 10.0.2.2:54597]   File "/var/www/virginia/processors/processor_factory.py", line 3, in <module>
[Fri Sep 02 08:26:02.087833 2016] [:error] [pid 1824:tid 140204971124480] [client 10.0.2.2:54597]     from processors.ctakes_processor import CTakesProcessor
[Fri Sep 02 08:26:02.087927 2016] [:error] [pid 1824:tid 140204971124480] [client 10.0.2.2:54597]   File "/var/www/virginia/processors/ctakes_processor.py", line 5, in <module>
[Fri Sep 02 08:26:02.089275 2016] [:error] [pid 1824:tid 140204971124480] [client 10.0.2.2:54597]     from strategy.weighted_match import AggregatedMatchStrategy
[Fri Sep 02 08:26:02.089406 2016] [:error] [pid 1824:tid 140204971124480] [client 10.0.2.2:54597] ImportError: cannot import name AggregatedMatchStrategy
[Fri Sep 02 08:28:02.657747 2016] [ssl:warn] [pid 1937:tid 139883512928128] AH01909: RSA certificate configured for default:443 does NOT include an ID which matches the server name
[Fri Sep 02 08:28:02.669453 2016] [ssl:warn] [pid 1938:tid 139883512928128] AH01909: RSA certificate configured for default:443 does NOT include an ID which matches the server name
[Fri Sep 02 08:28:09.177691 2016] [:error] [pid 1941:tid 139883284768512] [client 10.0.2.2:54604] mod_wsgi (pid=1941): Exception occurred processing WSGI script '/var/www/virginia/server.wsgi'.
[Fri Sep 02 08:28:09.177800 2016] [:error] [pid 1941:tid 139883284768512] [client 10.0.2.2:54604] Traceback (most recent call last):
[Fri Sep 02 08:28:09.177880 2016] [:error] [pid 1941:tid 139883284768512] [client 10.0.2.2:54604]   File "/usr/local/lib/python2.7/dist-packages/flask/app.py", line 2000, in __call__
[Fri Sep 02 08:28:09.179005 2016] [:error] [pid 1941:tid 139883284768512] [client 10.0.2.2:54604]     return self.wsgi_app(environ, start_response)
[Fri Sep 02 08:28:09.179089 2016] [:error] [pid 1941:tid 139883284768512] [client 10.0.2.2:54604]   File "/usr/local/lib/python2.7/dist-packages/flask/app.py", line 1991, in wsgi_app
[Fri Sep 02 08:28:09.179172 2016] [:error] [pid 1941:tid 139883284768512] [client 10.0.2.2:54604]     response = self.make_response(self.handle_exception(e))
[Fri Sep 02 08:28:09.179294 2016] [:error] [pid 1941:tid 139883284768512] [client 10.0.2.2:54604]   File "/usr/local/lib/python2.7/dist-packages/flask_restful/__init__.py", line 271, in error_router
[Fri Sep 02 08:28:09.180451 2016] [:error] [pid 1941:tid 139883284768512] [client 10.0.2.2:54604]     return original_handler(e)
[Fri Sep 02 08:28:09.180591 2016] [:error] [pid 1941:tid 139883284768512] [client 10.0.2.2:54604]   File "/usr/local/lib/python2.7/dist-packages/flask/app.py", line 1567, in handle_exception
[Fri Sep 02 08:28:09.180691 2016] [:error] [pid 1941:tid 139883284768512] [client 10.0.2.2:54604]     reraise(exc_type, exc_value, tb)
[Fri Sep 02 08:28:09.180764 2016] [:error] [pid 1941:tid 139883284768512] [client 10.0.2.2:54604]   File "/usr/local/lib/python2.7/dist-packages/flask_restful/__init__.py", line 268, in error_router
[Fri Sep 02 08:28:09.180843 2016] [:error] [pid 1941:tid 139883284768512] [client 10.0.2.2:54604]     return self.handle_error(e)
[Fri Sep 02 08:28:09.180914 2016] [:error] [pid 1941:tid 139883284768512] [client 10.0.2.2:54604]   File "/usr/local/lib/python2.7/dist-packages/flask/app.py", line 1988, in wsgi_app
[Fri Sep 02 08:28:09.180993 2016] [:error] [pid 1941:tid 139883284768512] [client 10.0.2.2:54604]     response = self.full_dispatch_request()
[Fri Sep 02 08:28:09.181061 2016] [:error] [pid 1941:tid 139883284768512] [client 10.0.2.2:54604]   File "/usr/local/lib/python2.7/dist-packages/flask/app.py", line 1641, in full_dispatch_request
[Fri Sep 02 08:28:09.181134 2016] [:error] [pid 1941:tid 139883284768512] [client 10.0.2.2:54604]     rv = self.handle_user_exception(e)
[Fri Sep 02 08:28:09.181208 2016] [:error] [pid 1941:tid 139883284768512] [client 10.0.2.2:54604]   File "/usr/local/lib/python2.7/dist-packages/flask_restful/__init__.py", line 271, in error_router
[Fri Sep 02 08:28:09.181318 2016] [:error] [pid 1941:tid 139883284768512] [client 10.0.2.2:54604]     return original_handler(e)
[Fri Sep 02 08:28:09.181414 2016] [:error] [pid 1941:tid 139883284768512] [client 10.0.2.2:54604]   File "/usr/local/lib/python2.7/dist-packages/flask/app.py", line 1544, in handle_user_exception
[Fri Sep 02 08:28:09.181496 2016] [:error] [pid 1941:tid 139883284768512] [client 10.0.2.2:54604]     reraise(exc_type, exc_value, tb)
[Fri Sep 02 08:28:09.181568 2016] [:error] [pid 1941:tid 139883284768512] [client 10.0.2.2:54604]   File "/usr/local/lib/python2.7/dist-packages/flask_restful/__init__.py", line 268, in error_router
[Fri Sep 02 08:28:09.181692 2016] [:error] [pid 1941:tid 139883284768512] [client 10.0.2.2:54604]     return self.handle_error(e)
[Fri Sep 02 08:28:09.181778 2016] [:error] [pid 1941:tid 139883284768512] [client 10.0.2.2:54604]   File "/usr/local/lib/python2.7/dist-packages/flask/app.py", line 1639, in full_dispatch_request
[Fri Sep 02 08:28:09.181860 2016] [:error] [pid 1941:tid 139883284768512] [client 10.0.2.2:54604]     rv = self.dispatch_request()
[Fri Sep 02 08:28:09.181954 2016] [:error] [pid 1941:tid 139883284768512] [client 10.0.2.2:54604]   File "/usr/local/lib/python2.7/dist-packages/flask/app.py", line 1625, in dispatch_request
[Fri Sep 02 08:28:09.182038 2016] [:error] [pid 1941:tid 139883284768512] [client 10.0.2.2:54604]     return self.view_functions[rule.endpoint](**req.view_args)
[Fri Sep 02 08:28:09.182117 2016] [:error] [pid 1941:tid 139883284768512] [client 10.0.2.2:54604]   File "/usr/local/lib/python2.7/dist-packages/flask_restful/__init__.py", line 477, in wrapper
[Fri Sep 02 08:28:09.182194 2016] [:error] [pid 1941:tid 139883284768512] [client 10.0.2.2:54604]     resp = resource(*args, **kwargs)
[Fri Sep 02 08:28:09.182270 2016] [:error] [pid 1941:tid 139883284768512] [client 10.0.2.2:54604]   File "/usr/local/lib/python2.7/dist-packages/flask/views.py", line 84, in view
[Fri Sep 02 08:28:09.182616 2016] [:error] [pid 1941:tid 139883284768512] [client 10.0.2.2:54604]     return self.dispatch_request(*args, **kwargs)
[Fri Sep 02 08:28:09.182698 2016] [:error] [pid 1941:tid 139883284768512] [client 10.0.2.2:54604]   File "/usr/local/lib/python2.7/dist-packages/flask_restful/__init__.py", line 587, in dispatch_request
[Fri Sep 02 08:28:09.182863 2016] [:error] [pid 1941:tid 139883284768512] [client 10.0.2.2:54604]     resp = meth(*args, **kwargs)
[Fri Sep 02 08:28:09.183013 2016] [:error] [pid 1941:tid 139883284768512] [client 10.0.2.2:54604]   File "/var/www/virginia/resources/monologue.py", line 60, in post
[Fri Sep 02 08:28:09.184764 2016] [:error] [pid 1941:tid 139883284768512] [client 10.0.2.2:54604]     plot = self.__generatePlot(json_data)
[Fri Sep 02 08:28:09.184909 2016] [:error] [pid 1941:tid 139883284768512] [client 10.0.2.2:54604]   File "/var/www/virginia/resources/monologue.py", line 73, in __generatePlot
[Fri Sep 02 08:28:09.185242 2016] [:error] [pid 1941:tid 139883284768512] [client 10.0.2.2:54604]     return Plot(data['seed'])
[Fri Sep 02 08:28:09.185324 2016] [:error] [pid 1941:tid 139883284768512] [client 10.0.2.2:54604]   File "/var/www/virginia/narrative/plot.py", line 42, in __init__
[Fri Sep 02 08:28:09.186506 2016] [:error] [pid 1941:tid 139883284768512] [client 10.0.2.2:54604]     self._processor = ProcessorFactory.getProcessor(self.__underlyingPlot['processor'])
[Fri Sep 02 08:28:09.186585 2016] [:error] [pid 1941:tid 139883284768512] [client 10.0.2.2:54604]   File "/var/www/virginia/processors/processor_factory.py", line 13, in getProcessor
[Fri Sep 02 08:28:09.187689 2016] [:error] [pid 1941:tid 139883284768512] [client 10.0.2.2:54604]     if processor_type in instances:
[Fri Sep 02 08:28:09.187795 2016] [:error] [pid 1941:tid 139883284768512] [client 10.0.2.2:54604] NameError: global name 'instances' is not defined
[Fri Sep 02 08:29:56.075890 2016] [ssl:warn] [pid 1938:tid 139883512928128] AH01909: RSA certificate configured for default:443 does NOT include an ID which matches the server name
[Fri Sep 02 08:30:00.830440 2016] [:error] [pid 2033:tid 139883284768512] [client 10.0.2.2:54614] mod_wsgi (pid=2033): Exception occurred processing WSGI script '/var/www/virginia/server.wsgi'.
[Fri Sep 02 08:30:00.830540 2016] [:error] [pid 2033:tid 139883284768512] [client 10.0.2.2:54614] Traceback (most recent call last):
[Fri Sep 02 08:30:00.830615 2016] [:error] [pid 2033:tid 139883284768512] [client 10.0.2.2:54614]   File "/usr/local/lib/python2.7/dist-packages/flask/app.py", line 2000, in __call__
[Fri Sep 02 08:30:00.831031 2016] [:error] [pid 2033:tid 139883284768512] [client 10.0.2.2:54614]     return self.wsgi_app(environ, start_response)
[Fri Sep 02 08:30:00.831105 2016] [:error] [pid 2033:tid 139883284768512] [client 10.0.2.2:54614]   File "/usr/local/lib/python2.7/dist-packages/flask/app.py", line 1991, in wsgi_app
[Fri Sep 02 08:30:00.831192 2016] [:error] [pid 2033:tid 139883284768512] [client 10.0.2.2:54614]     response = self.make_response(self.handle_exception(e))
[Fri Sep 02 08:30:00.831259 2016] [:error] [pid 2033:tid 139883284768512] [client 10.0.2.2:54614]   File "/usr/local/lib/python2.7/dist-packages/flask_restful/__init__.py", line 271, in error_router
[Fri Sep 02 08:30:00.831465 2016] [:error] [pid 2033:tid 139883284768512] [client 10.0.2.2:54614]     return original_handler(e)
[Fri Sep 02 08:30:00.831536 2016] [:error] [pid 2033:tid 139883284768512] [client 10.0.2.2:54614]   File "/usr/local/lib/python2.7/dist-packages/flask/app.py", line 1567, in handle_exception
[Fri Sep 02 08:30:00.831610 2016] [:error] [pid 2033:tid 139883284768512] [client 10.0.2.2:54614]     reraise(exc_type, exc_value, tb)
[Fri Sep 02 08:30:00.831675 2016] [:error] [pid 2033:tid 139883284768512] [client 10.0.2.2:54614]   File "/usr/local/lib/python2.7/dist-packages/flask_restful/__init__.py", line 268, in error_router
[Fri Sep 02 08:30:00.831757 2016] [:error] [pid 2033:tid 139883284768512] [client 10.0.2.2:54614]     return self.handle_error(e)
[Fri Sep 02 08:30:00.831823 2016] [:error] [pid 2033:tid 139883284768512] [client 10.0.2.2:54614]   File "/usr/local/lib/python2.7/dist-packages/flask/app.py", line 1988, in wsgi_app
[Fri Sep 02 08:30:00.831897 2016] [:error] [pid 2033:tid 139883284768512] [client 10.0.2.2:54614]     response = self.full_dispatch_request()
[Fri Sep 02 08:30:00.831968 2016] [:error] [pid 2033:tid 139883284768512] [client 10.0.2.2:54614]   File "/usr/local/lib/python2.7/dist-packages/flask/app.py", line 1641, in full_dispatch_request
[Fri Sep 02 08:30:00.832044 2016] [:error] [pid 2033:tid 139883284768512] [client 10.0.2.2:54614]     rv = self.handle_user_exception(e)
[Fri Sep 02 08:30:00.832113 2016] [:error] [pid 2033:tid 139883284768512] [client 10.0.2.2:54614]   File "/usr/local/lib/python2.7/dist-packages/flask_restful/__init__.py", line 271, in error_router
[Fri Sep 02 08:30:00.832235 2016] [:error] [pid 2033:tid 139883284768512] [client 10.0.2.2:54614]     return original_handler(e)
[Fri Sep 02 08:30:00.832305 2016] [:error] [pid 2033:tid 139883284768512] [client 10.0.2.2:54614]   File "/usr/local/lib/python2.7/dist-packages/flask/app.py", line 1544, in handle_user_exception
[Fri Sep 02 08:30:00.832379 2016] [:error] [pid 2033:tid 139883284768512] [client 10.0.2.2:54614]     reraise(exc_type, exc_value, tb)
[Fri Sep 02 08:30:00.832445 2016] [:error] [pid 2033:tid 139883284768512] [client 10.0.2.2:54614]   File "/usr/local/lib/python2.7/dist-packages/flask_restful/__init__.py", line 268, in error_router
[Fri Sep 02 08:30:00.832517 2016] [:error] [pid 2033:tid 139883284768512] [client 10.0.2.2:54614]     return self.handle_error(e)
[Fri Sep 02 08:30:00.832582 2016] [:error] [pid 2033:tid 139883284768512] [client 10.0.2.2:54614]   File "/usr/local/lib/python2.7/dist-packages/flask/app.py", line 1639, in full_dispatch_request
[Fri Sep 02 08:30:00.832655 2016] [:error] [pid 2033:tid 139883284768512] [client 10.0.2.2:54614]     rv = self.dispatch_request()
[Fri Sep 02 08:30:00.832722 2016] [:error] [pid 2033:tid 139883284768512] [client 10.0.2.2:54614]   File "/usr/local/lib/python2.7/dist-packages/flask/app.py", line 1625, in dispatch_request
[Fri Sep 02 08:30:00.832796 2016] [:error] [pid 2033:tid 139883284768512] [client 10.0.2.2:54614]     return self.view_functions[rule.endpoint](**req.view_args)
[Fri Sep 02 08:30:00.832863 2016] [:error] [pid 2033:tid 139883284768512] [client 10.0.2.2:54614]   File "/usr/local/lib/python2.7/dist-packages/flask_restful/__init__.py", line 477, in wrapper
[Fri Sep 02 08:30:00.832935 2016] [:error] [pid 2033:tid 139883284768512] [client 10.0.2.2:54614]     resp = resource(*args, **kwargs)
[Fri Sep 02 08:30:00.833000 2016] [:error] [pid 2033:tid 139883284768512] [client 10.0.2.2:54614]   File "/usr/local/lib/python2.7/dist-packages/flask/views.py", line 84, in view
[Fri Sep 02 08:30:00.833120 2016] [:error] [pid 2033:tid 139883284768512] [client 10.0.2.2:54614]     return self.dispatch_request(*args, **kwargs)
[Fri Sep 02 08:30:00.833196 2016] [:error] [pid 2033:tid 139883284768512] [client 10.0.2.2:54614]   File "/usr/local/lib/python2.7/dist-packages/flask_restful/__init__.py", line 587, in dispatch_request
[Fri Sep 02 08:30:00.833272 2016] [:error] [pid 2033:tid 139883284768512] [client 10.0.2.2:54614]     resp = meth(*args, **kwargs)
[Fri Sep 02 08:30:00.833338 2016] [:error] [pid 2033:tid 139883284768512] [client 10.0.2.2:54614]   File "/var/www/virginia/resources/monologue.py", line 65, in post
[Fri Sep 02 08:30:00.834428 2016] [:error] [pid 2033:tid 139883284768512] [client 10.0.2.2:54614]     response = make_response(json.dumps(plot.processor().process(plot, json_data['monologue'])))
[Fri Sep 02 08:30:00.834512 2016] [:error] [pid 2033:tid 139883284768512] [client 10.0.2.2:54614] TypeError: processor() takes no arguments (1 given)
[Fri Sep 02 08:31:53.957533 2016] [ssl:warn] [pid 1938:tid 139883512928128] AH01909: RSA certificate configured for default:443 does NOT include an ID which matches the server name
[Fri Sep 02 08:31:58.028723 2016] [:error] [pid 2117:tid 139883404580608] [client 10.0.2.2:54772] mod_wsgi (pid=2117): Exception occurred processing WSGI script '/var/www/virginia/server.wsgi'.
[Fri Sep 02 08:31:58.028827 2016] [:error] [pid 2117:tid 139883404580608] [client 10.0.2.2:54772] Traceback (most recent call last):
[Fri Sep 02 08:31:58.029006 2016] [:error] [pid 2117:tid 139883404580608] [client 10.0.2.2:54772]   File "/usr/local/lib/python2.7/dist-packages/flask/app.py", line 2000, in __call__
[Fri Sep 02 08:31:58.029475 2016] [:error] [pid 2117:tid 139883404580608] [client 10.0.2.2:54772]     return self.wsgi_app(environ, start_response)
[Fri Sep 02 08:31:58.029549 2016] [:error] [pid 2117:tid 139883404580608] [client 10.0.2.2:54772]   File "/usr/local/lib/python2.7/dist-packages/flask/app.py", line 1991, in wsgi_app
[Fri Sep 02 08:31:58.029633 2016] [:error] [pid 2117:tid 139883404580608] [client 10.0.2.2:54772]     response = self.make_response(self.handle_exception(e))
[Fri Sep 02 08:31:58.029701 2016] [:error] [pid 2117:tid 139883404580608] [client 10.0.2.2:54772]   File "/usr/local/lib/python2.7/dist-packages/flask_restful/__init__.py", line 271, in error_router
[Fri Sep 02 08:31:58.029907 2016] [:error] [pid 2117:tid 139883404580608] [client 10.0.2.2:54772]     return original_handler(e)
[Fri Sep 02 08:31:58.029977 2016] [:error] [pid 2117:tid 139883404580608] [client 10.0.2.2:54772]   File "/usr/local/lib/python2.7/dist-packages/flask/app.py", line 1567, in handle_exception
[Fri Sep 02 08:31:58.030051 2016] [:error] [pid 2117:tid 139883404580608] [client 10.0.2.2:54772]     reraise(exc_type, exc_value, tb)
[Fri Sep 02 08:31:58.030117 2016] [:error] [pid 2117:tid 139883404580608] [client 10.0.2.2:54772]   File "/usr/local/lib/python2.7/dist-packages/flask_restful/__init__.py", line 268, in error_router
[Fri Sep 02 08:31:58.030189 2016] [:error] [pid 2117:tid 139883404580608] [client 10.0.2.2:54772]     return self.handle_error(e)
[Fri Sep 02 08:31:58.030255 2016] [:error] [pid 2117:tid 139883404580608] [client 10.0.2.2:54772]   File "/usr/local/lib/python2.7/dist-packages/flask/app.py", line 1988, in wsgi_app
[Fri Sep 02 08:31:58.030327 2016] [:error] [pid 2117:tid 139883404580608] [client 10.0.2.2:54772]     response = self.full_dispatch_request()
[Fri Sep 02 08:31:58.030394 2016] [:error] [pid 2117:tid 139883404580608] [client 10.0.2.2:54772]   File "/usr/local/lib/python2.7/dist-packages/flask/app.py", line 1641, in full_dispatch_request
[Fri Sep 02 08:31:58.030466 2016] [:error] [pid 2117:tid 139883404580608] [client 10.0.2.2:54772]     rv = self.handle_user_exception(e)
[Fri Sep 02 08:31:58.030533 2016] [:error] [pid 2117:tid 139883404580608] [client 10.0.2.2:54772]   File "/usr/local/lib/python2.7/dist-packages/flask_restful/__init__.py", line 271, in error_router
[Fri Sep 02 08:31:58.030615 2016] [:error] [pid 2117:tid 139883404580608] [client 10.0.2.2:54772]     return original_handler(e)
[Fri Sep 02 08:31:58.030684 2016] [:error] [pid 2117:tid 139883404580608] [client 10.0.2.2:54772]   File "/usr/local/lib/python2.7/dist-packages/flask/app.py", line 1544, in handle_user_exception
[Fri Sep 02 08:31:58.030758 2016] [:error] [pid 2117:tid 139883404580608] [client 10.0.2.2:54772]     reraise(exc_type, exc_value, tb)
[Fri Sep 02 08:31:58.030824 2016] [:error] [pid 2117:tid 139883404580608] [client 10.0.2.2:54772]   File "/usr/local/lib/python2.7/dist-packages/flask_restful/__init__.py", line 268, in error_router
[Fri Sep 02 08:31:58.030896 2016] [:error] [pid 2117:tid 139883404580608] [client 10.0.2.2:54772]     return self.handle_error(e)
[Fri Sep 02 08:31:58.030961 2016] [:error] [pid 2117:tid 139883404580608] [client 10.0.2.2:54772]   File "/usr/local/lib/python2.7/dist-packages/flask/app.py", line 1639, in full_dispatch_request
[Fri Sep 02 08:31:58.031033 2016] [:error] [pid 2117:tid 139883404580608] [client 10.0.2.2:54772]     rv = self.dispatch_request()
[Fri Sep 02 08:31:58.031107 2016] [:error] [pid 2117:tid 139883404580608] [client 10.0.2.2:54772]   File "/usr/local/lib/python2.7/dist-packages/flask/app.py", line 1625, in dispatch_request
[Fri Sep 02 08:31:58.031181 2016] [:error] [pid 2117:tid 139883404580608] [client 10.0.2.2:54772]     return self.view_functions[rule.endpoint](**req.view_args)
[Fri Sep 02 08:31:58.031247 2016] [:error] [pid 2117:tid 139883404580608] [client 10.0.2.2:54772]   File "/usr/local/lib/python2.7/dist-packages/flask_restful/__init__.py", line 477, in wrapper
[Fri Sep 02 08:31:58.031406 2016] [:error] [pid 2117:tid 139883404580608] [client 10.0.2.2:54772]     resp = resource(*args, **kwargs)
[Fri Sep 02 08:31:58.031487 2016] [:error] [pid 2117:tid 139883404580608] [client 10.0.2.2:54772]   File "/usr/local/lib/python2.7/dist-packages/flask/views.py", line 84, in view
[Fri Sep 02 08:31:58.031625 2016] [:error] [pid 2117:tid 139883404580608] [client 10.0.2.2:54772]     return self.dispatch_request(*args, **kwargs)
[Fri Sep 02 08:31:58.031697 2016] [:error] [pid 2117:tid 139883404580608] [client 10.0.2.2:54772]   File "/usr/local/lib/python2.7/dist-packages/flask_restful/__init__.py", line 587, in dispatch_request
[Fri Sep 02 08:31:58.031772 2016] [:error] [pid 2117:tid 139883404580608] [client 10.0.2.2:54772]     resp = meth(*args, **kwargs)
[Fri Sep 02 08:31:58.031838 2016] [:error] [pid 2117:tid 139883404580608] [client 10.0.2.2:54772]   File "/var/www/virginia/resources/monologue.py", line 66, in post
[Fri Sep 02 08:31:58.033153 2016] [:error] [pid 2117:tid 139883404580608] [client 10.0.2.2:54772]     processor = plot.processor()
[Fri Sep 02 08:31:58.033246 2016] [:error] [pid 2117:tid 139883404580608] [client 10.0.2.2:54772] TypeError: processor() takes no arguments (1 given)
[Fri Sep 02 08:32:34.794383 2016] [ssl:warn] [pid 1938:tid 139883512928128] AH01909: RSA certificate configured for default:443 does NOT include an ID which matches the server name
[Fri Sep 02 08:34:35.007102 2016] [:error] [pid 2227:tid 139883326732032] [client 10.0.2.2:54934] mod_wsgi (pid=2227): Exception occurred processing WSGI script '/var/www/virginia/server.wsgi'.
[Fri Sep 02 08:34:35.007301 2016] [:error] [pid 2227:tid 139883326732032] [client 10.0.2.2:54934] Traceback (most recent call last):
[Fri Sep 02 08:34:35.007505 2016] [:error] [pid 2227:tid 139883326732032] [client 10.0.2.2:54934]   File "/usr/local/lib/python2.7/dist-packages/flask/app.py", line 2000, in __call__
[Fri Sep 02 08:34:35.007979 2016] [:error] [pid 2227:tid 139883326732032] [client 10.0.2.2:54934]     return self.wsgi_app(environ, start_response)
[Fri Sep 02 08:34:35.008187 2016] [:error] [pid 2227:tid 139883326732032] [client 10.0.2.2:54934]   File "/usr/local/lib/python2.7/dist-packages/flask/app.py", line 1991, in wsgi_app
[Fri Sep 02 08:34:35.008282 2016] [:error] [pid 2227:tid 139883326732032] [client 10.0.2.2:54934]     response = self.make_response(self.handle_exception(e))
[Fri Sep 02 08:34:35.008356 2016] [:error] [pid 2227:tid 139883326732032] [client 10.0.2.2:54934]   File "/usr/local/lib/python2.7/dist-packages/flask_restful/__init__.py", line 271, in error_router
[Fri Sep 02 08:34:35.008573 2016] [:error] [pid 2227:tid 139883326732032] [client 10.0.2.2:54934]     return original_handler(e)
[Fri Sep 02 08:34:35.008645 2016] [:error] [pid 2227:tid 139883326732032] [client 10.0.2.2:54934]   File "/usr/local/lib/python2.7/dist-packages/flask/app.py", line 1567, in handle_exception
[Fri Sep 02 08:34:35.008721 2016] [:error] [pid 2227:tid 139883326732032] [client 10.0.2.2:54934]     reraise(exc_type, exc_value, tb)
[Fri Sep 02 08:34:35.008789 2016] [:error] [pid 2227:tid 139883326732032] [client 10.0.2.2:54934]   File "/usr/local/lib/python2.7/dist-packages/flask_restful/__init__.py", line 268, in error_router
[Fri Sep 02 08:34:35.008863 2016] [:error] [pid 2227:tid 139883326732032] [client 10.0.2.2:54934]     return self.handle_error(e)
[Fri Sep 02 08:34:35.008929 2016] [:error] [pid 2227:tid 139883326732032] [client 10.0.2.2:54934]   File "/usr/local/lib/python2.7/dist-packages/flask/app.py", line 1988, in wsgi_app
[Fri Sep 02 08:34:35.009003 2016] [:error] [pid 2227:tid 139883326732032] [client 10.0.2.2:54934]     response = self.full_dispatch_request()
[Fri Sep 02 08:34:35.009071 2016] [:error] [pid 2227:tid 139883326732032] [client 10.0.2.2:54934]   File "/usr/local/lib/python2.7/dist-packages/flask/app.py", line 1641, in full_dispatch_request
[Fri Sep 02 08:34:35.009144 2016] [:error] [pid 2227:tid 139883326732032] [client 10.0.2.2:54934]     rv = self.handle_user_exception(e)
[Fri Sep 02 08:34:35.009293 2016] [:error] [pid 2227:tid 139883326732032] [client 10.0.2.2:54934]   File "/usr/local/lib/python2.7/dist-packages/flask_restful/__init__.py", line 271, in error_router
[Fri Sep 02 08:34:35.009394 2016] [:error] [pid 2227:tid 139883326732032] [client 10.0.2.2:54934]     return original_handler(e)
[Fri Sep 02 08:34:35.009488 2016] [:error] [pid 2227:tid 139883326732032] [client 10.0.2.2:54934]   File "/usr/local/lib/python2.7/dist-packages/flask/app.py", line 1544, in handle_user_exception
[Fri Sep 02 08:34:35.009562 2016] [:error] [pid 2227:tid 139883326732032] [client 10.0.2.2:54934]     reraise(exc_type, exc_value, tb)
[Fri Sep 02 08:34:35.009629 2016] [:error] [pid 2227:tid 139883326732032] [client 10.0.2.2:54934]   File "/usr/local/lib/python2.7/dist-packages/flask_restful/__init__.py", line 268, in error_router
[Fri Sep 02 08:34:35.009712 2016] [:error] [pid 2227:tid 139883326732032] [client 10.0.2.2:54934]     return self.handle_error(e)
[Fri Sep 02 08:34:35.009779 2016] [:error] [pid 2227:tid 139883326732032] [client 10.0.2.2:54934]   File "/usr/local/lib/python2.7/dist-packages/flask/app.py", line 1639, in full_dispatch_request
[Fri Sep 02 08:34:35.009853 2016] [:error] [pid 2227:tid 139883326732032] [client 10.0.2.2:54934]     rv = self.dispatch_request()
[Fri Sep 02 08:34:35.009919 2016] [:error] [pid 2227:tid 139883326732032] [client 10.0.2.2:54934]   File "/usr/local/lib/python2.7/dist-packages/flask/app.py", line 1625, in dispatch_request
[Fri Sep 02 08:34:35.009992 2016] [:error] [pid 2227:tid 139883326732032] [client 10.0.2.2:54934]     return self.view_functions[rule.endpoint](**req.view_args)
[Fri Sep 02 08:34:35.010060 2016] [:error] [pid 2227:tid 139883326732032] [client 10.0.2.2:54934]   File "/usr/local/lib/python2.7/dist-packages/flask_restful/__init__.py", line 477, in wrapper
[Fri Sep 02 08:34:35.010133 2016] [:error] [pid 2227:tid 139883326732032] [client 10.0.2.2:54934]     resp = resource(*args, **kwargs)
[Fri Sep 02 08:34:35.010213 2016] [:error] [pid 2227:tid 139883326732032] [client 10.0.2.2:54934]   File "/usr/local/lib/python2.7/dist-packages/flask/views.py", line 84, in view
[Fri Sep 02 08:34:35.010341 2016] [:error] [pid 2227:tid 139883326732032] [client 10.0.2.2:54934]     return self.dispatch_request(*args, **kwargs)
[Fri Sep 02 08:34:35.010412 2016] [:error] [pid 2227:tid 139883326732032] [client 10.0.2.2:54934]   File "/usr/local/lib/python2.7/dist-packages/flask_restful/__init__.py", line 587, in dispatch_request
[Fri Sep 02 08:34:35.010488 2016] [:error] [pid 2227:tid 139883326732032] [client 10.0.2.2:54934]     resp = meth(*args, **kwargs)
[Fri Sep 02 08:34:35.010557 2016] [:error] [pid 2227:tid 139883326732032] [client 10.0.2.2:54934]   File "/var/www/virginia/resources/monologue.py", line 67, in post
[Fri Sep 02 08:34:35.013165 2016] [:error] [pid 2227:tid 139883326732032] [client 10.0.2.2:54934]     response = make_response(json.dumps(processor.process(plot, json_data['monologue'])))
[Fri Sep 02 08:34:35.013660 2016] [:error] [pid 2227:tid 139883326732032] [client 10.0.2.2:54934]   File "/var/www/virginia/processors/ctakes_processor.py", line 43, in process
[Fri Sep 02 08:34:35.019113 2016] [:error] [pid 2227:tid 139883326732032] [client 10.0.2.2:54934]     self.__processingPreflight(monologue)
[Fri Sep 02 08:34:35.019502 2016] [:error] [pid 2227:tid 139883326732032] [client 10.0.2.2:54934]   File "/var/www/virginia/processors/ctakes_processor.py", line 19, in __processingPreflight
[Fri Sep 02 08:34:35.021115 2016] [:error] [pid 2227:tid 139883326732032] [client 10.0.2.2:54934]     self.__updateprocessorContext()
[Fri Sep 02 08:34:35.021341 2016] [:error] [pid 2227:tid 139883326732032] [client 10.0.2.2:54934]   File "/var/www/virginia/processors/ctakes_processor.py", line 40, in __updateprocessorContext
[Fri Sep 02 08:34:35.021695 2016] [:error] [pid 2227:tid 139883326732032] [client 10.0.2.2:54934]     self._context.create(self.tokens,entities,[])
[Fri Sep 02 08:34:35.021800 2016] [:error] [pid 2227:tid 139883326732032] [client 10.0.2.2:54934] AttributeError: CTakesProcessor instance has no attribute 'tokens'
[Fri Sep 02 08:35:30.579398 2016] [ssl:warn] [pid 1938:tid 139883512928128] AH01909: RSA certificate configured for default:443 does NOT include an ID which matches the server name
[Fri Sep 02 08:35:35.488671 2016] [:error] [pid 2298:tid 139883404580608] [client 10.0.2.2:54941] mod_wsgi (pid=2298): Exception occurred processing WSGI script '/var/www/virginia/server.wsgi'.
[Fri Sep 02 08:35:35.489184 2016] [:error] [pid 2298:tid 139883404580608] [client 10.0.2.2:54941] Traceback (most recent call last):
[Fri Sep 02 08:35:35.489329 2016] [:error] [pid 2298:tid 139883404580608] [client 10.0.2.2:54941]   File "/usr/local/lib/python2.7/dist-packages/flask/app.py", line 2000, in __call__
[Fri Sep 02 08:35:35.489891 2016] [:error] [pid 2298:tid 139883404580608] [client 10.0.2.2:54941]     return self.wsgi_app(environ, start_response)
[Fri Sep 02 08:35:35.490290 2016] [:error] [pid 2298:tid 139883404580608] [client 10.0.2.2:54941]   File "/usr/local/lib/python2.7/dist-packages/flask/app.py", line 1991, in wsgi_app
[Fri Sep 02 08:35:35.490802 2016] [:error] [pid 2298:tid 139883404580608] [client 10.0.2.2:54941]     response = self.make_response(self.handle_exception(e))
[Fri Sep 02 08:35:35.491293 2016] [:error] [pid 2298:tid 139883404580608] [client 10.0.2.2:54941]   File "/usr/local/lib/python2.7/dist-packages/flask_restful/__init__.py", line 271, in error_router
[Fri Sep 02 08:35:35.491954 2016] [:error] [pid 2298:tid 139883404580608] [client 10.0.2.2:54941]     return original_handler(e)
[Fri Sep 02 08:35:35.492075 2016] [:error] [pid 2298:tid 139883404580608] [client 10.0.2.2:54941]   File "/usr/local/lib/python2.7/dist-packages/flask/app.py", line 1567, in handle_exception
[Fri Sep 02 08:35:35.492265 2016] [:error] [pid 2298:tid 139883404580608] [client 10.0.2.2:54941]     reraise(exc_type, exc_value, tb)
[Fri Sep 02 08:35:35.492371 2016] [:error] [pid 2298:tid 139883404580608] [client 10.0.2.2:54941]   File "/usr/local/lib/python2.7/dist-packages/flask_restful/__init__.py", line 268, in error_router
[Fri Sep 02 08:35:35.492478 2016] [:error] [pid 2298:tid 139883404580608] [client 10.0.2.2:54941]     return self.handle_error(e)
[Fri Sep 02 08:35:35.492591 2016] [:error] [pid 2298:tid 139883404580608] [client 10.0.2.2:54941]   File "/usr/local/lib/python2.7/dist-packages/flask/app.py", line 1988, in wsgi_app
[Fri Sep 02 08:35:35.492693 2016] [:error] [pid 2298:tid 139883404580608] [client 10.0.2.2:54941]     response = self.full_dispatch_request()
[Fri Sep 02 08:35:35.492785 2016] [:error] [pid 2298:tid 139883404580608] [client 10.0.2.2:54941]   File "/usr/local/lib/python2.7/dist-packages/flask/app.py", line 1641, in full_dispatch_request
[Fri Sep 02 08:35:35.492904 2016] [:error] [pid 2298:tid 139883404580608] [client 10.0.2.2:54941]     rv = self.handle_user_exception(e)
[Fri Sep 02 08:35:35.493008 2016] [:error] [pid 2298:tid 139883404580608] [client 10.0.2.2:54941]   File "/usr/local/lib/python2.7/dist-packages/flask_restful/__init__.py", line 271, in error_router
[Fri Sep 02 08:35:35.493096 2016] [:error] [pid 2298:tid 139883404580608] [client 10.0.2.2:54941]     return original_handler(e)
[Fri Sep 02 08:35:35.493163 2016] [:error] [pid 2298:tid 139883404580608] [client 10.0.2.2:54941]   File "/usr/local/lib/python2.7/dist-packages/flask/app.py", line 1544, in handle_user_exception
[Fri Sep 02 08:35:35.493247 2016] [:error] [pid 2298:tid 139883404580608] [client 10.0.2.2:54941]     reraise(exc_type, exc_value, tb)
[Fri Sep 02 08:35:35.493313 2016] [:error] [pid 2298:tid 139883404580608] [client 10.0.2.2:54941]   File "/usr/local/lib/python2.7/dist-packages/flask_restful/__init__.py", line 268, in error_router
[Fri Sep 02 08:35:35.493386 2016] [:error] [pid 2298:tid 139883404580608] [client 10.0.2.2:54941]     return self.handle_error(e)
[Fri Sep 02 08:35:35.493453 2016] [:error] [pid 2298:tid 139883404580608] [client 10.0.2.2:54941]   File "/usr/local/lib/python2.7/dist-packages/flask/app.py", line 1639, in full_dispatch_request
[Fri Sep 02 08:35:35.493531 2016] [:error] [pid 2298:tid 139883404580608] [client 10.0.2.2:54941]     rv = self.dispatch_request()
[Fri Sep 02 08:35:35.493606 2016] [:error] [pid 2298:tid 139883404580608] [client 10.0.2.2:54941]   File "/usr/local/lib/python2.7/dist-packages/flask/app.py", line 1625, in dispatch_request
[Fri Sep 02 08:35:35.493680 2016] [:error] [pid 2298:tid 139883404580608] [client 10.0.2.2:54941]     return self.view_functions[rule.endpoint](**req.view_args)
[Fri Sep 02 08:35:35.493754 2016] [:error] [pid 2298:tid 139883404580608] [client 10.0.2.2:54941]   File "/usr/local/lib/python2.7/dist-packages/flask_restful/__init__.py", line 477, in wrapper
[Fri Sep 02 08:35:35.493827 2016] [:error] [pid 2298:tid 139883404580608] [client 10.0.2.2:54941]     resp = resource(*args, **kwargs)
[Fri Sep 02 08:35:35.493899 2016] [:error] [pid 2298:tid 139883404580608] [client 10.0.2.2:54941]   File "/usr/local/lib/python2.7/dist-packages/flask/views.py", line 84, in view
[Fri Sep 02 08:35:35.494046 2016] [:error] [pid 2298:tid 139883404580608] [client 10.0.2.2:54941]     return self.dispatch_request(*args, **kwargs)
[Fri Sep 02 08:35:35.494120 2016] [:error] [pid 2298:tid 139883404580608] [client 10.0.2.2:54941]   File "/usr/local/lib/python2.7/dist-packages/flask_restful/__init__.py", line 587, in dispatch_request
[Fri Sep 02 08:35:35.494196 2016] [:error] [pid 2298:tid 139883404580608] [client 10.0.2.2:54941]     resp = meth(*args, **kwargs)
[Fri Sep 02 08:35:35.494272 2016] [:error] [pid 2298:tid 139883404580608] [client 10.0.2.2:54941]   File "/var/www/virginia/resources/monologue.py", line 67, in post
[Fri Sep 02 08:35:35.496499 2016] [:error] [pid 2298:tid 139883404580608] [client 10.0.2.2:54941]     response = make_response(json.dumps(processor.process(plot, json_data['monologue'])))
[Fri Sep 02 08:35:35.496582 2016] [:error] [pid 2298:tid 139883404580608] [client 10.0.2.2:54941]   File "/var/www/virginia/processors/ctakes_processor.py", line 44, in process
[Fri Sep 02 08:35:35.498121 2016] [:error] [pid 2298:tid 139883404580608] [client 10.0.2.2:54941]     self.result['out'] = self._strategy.apply(plot,self._context)
[Fri Sep 02 08:35:35.498211 2016] [:error] [pid 2298:tid 139883404580608] [client 10.0.2.2:54941]   File "/var/www/virginia/strategy/aggregated_match.py", line 23, in apply
[Fri Sep 02 08:35:35.499395 2016] [:error] [pid 2298:tid 139883404580608] [client 10.0.2.2:54941]     self.__process()
[Fri Sep 02 08:35:35.499480 2016] [:error] [pid 2298:tid 139883404580608] [client 10.0.2.2:54941]   File "/var/www/virginia/strategy/aggregated_match.py", line 39, in __process
[Fri Sep 02 08:35:35.499833 2016] [:error] [pid 2298:tid 139883404580608] [client 10.0.2.2:54941]     new_match = {'for':self._pipeline['remaining'][idx][0],'match':','.join(result), 'possiblities':[]}
[Fri Sep 02 08:35:35.499938 2016] [:error] [pid 2298:tid 139883404580608] [client 10.0.2.2:54941] TypeError: sequence item 0: expected string, tuple found
[Fri Sep 02 08:42:44.336168 2016] [ssl:warn] [pid 1938:tid 139883512928128] AH01909: RSA certificate configured for default:443 does NOT include an ID which matches the server name
[Fri Sep 02 08:42:49.947343 2016] [:error] [pid 2512:tid 139883284768512] [client 10.0.2.2:55239] mod_wsgi (pid=2512): Exception occurred processing WSGI script '/var/www/virginia/server.wsgi'.
[Fri Sep 02 08:42:49.947477 2016] [:error] [pid 2512:tid 139883284768512] [client 10.0.2.2:55239] Traceback (most recent call last):
[Fri Sep 02 08:42:49.947628 2016] [:error] [pid 2512:tid 139883284768512] [client 10.0.2.2:55239]   File "/usr/local/lib/python2.7/dist-packages/flask/app.py", line 2000, in __call__
[Fri Sep 02 08:42:49.948121 2016] [:error] [pid 2512:tid 139883284768512] [client 10.0.2.2:55239]     return self.wsgi_app(environ, start_response)
[Fri Sep 02 08:42:49.949045 2016] [:error] [pid 2512:tid 139883284768512] [client 10.0.2.2:55239]   File "/usr/local/lib/python2.7/dist-packages/flask/app.py", line 1991, in wsgi_app
[Fri Sep 02 08:42:49.949133 2016] [:error] [pid 2512:tid 139883284768512] [client 10.0.2.2:55239]     response = self.make_response(self.handle_exception(e))
[Fri Sep 02 08:42:49.949291 2016] [:error] [pid 2512:tid 139883284768512] [client 10.0.2.2:55239]   File "/usr/local/lib/python2.7/dist-packages/flask_restful/__init__.py", line 271, in error_router
[Fri Sep 02 08:42:49.949525 2016] [:error] [pid 2512:tid 139883284768512] [client 10.0.2.2:55239]     return original_handler(e)
[Fri Sep 02 08:42:49.949609 2016] [:error] [pid 2512:tid 139883284768512] [client 10.0.2.2:55239]   File "/usr/local/lib/python2.7/dist-packages/flask/app.py", line 1567, in handle_exception
[Fri Sep 02 08:42:49.949695 2016] [:error] [pid 2512:tid 139883284768512] [client 10.0.2.2:55239]     reraise(exc_type, exc_value, tb)
[Fri Sep 02 08:42:49.949764 2016] [:error] [pid 2512:tid 139883284768512] [client 10.0.2.2:55239]   File "/usr/local/lib/python2.7/dist-packages/flask_restful/__init__.py", line 268, in error_router
[Fri Sep 02 08:42:49.949840 2016] [:error] [pid 2512:tid 139883284768512] [client 10.0.2.2:55239]     return self.handle_error(e)
[Fri Sep 02 08:42:49.949908 2016] [:error] [pid 2512:tid 139883284768512] [client 10.0.2.2:55239]   File "/usr/local/lib/python2.7/dist-packages/flask/app.py", line 1988, in wsgi_app
[Fri Sep 02 08:42:49.949983 2016] [:error] [pid 2512:tid 139883284768512] [client 10.0.2.2:55239]     response = self.full_dispatch_request()
[Fri Sep 02 08:42:49.950052 2016] [:error] [pid 2512:tid 139883284768512] [client 10.0.2.2:55239]   File "/usr/local/lib/python2.7/dist-packages/flask/app.py", line 1641, in full_dispatch_request
[Fri Sep 02 08:42:49.950130 2016] [:error] [pid 2512:tid 139883284768512] [client 10.0.2.2:55239]     rv = self.handle_user_exception(e)
[Fri Sep 02 08:42:49.950317 2016] [:error] [pid 2512:tid 139883284768512] [client 10.0.2.2:55239]   File "/usr/local/lib/python2.7/dist-packages/flask_restful/__init__.py", line 271, in error_router
[Fri Sep 02 08:42:49.950400 2016] [:error] [pid 2512:tid 139883284768512] [client 10.0.2.2:55239]     return original_handler(e)
[Fri Sep 02 08:42:49.950498 2016] [:error] [pid 2512:tid 139883284768512] [client 10.0.2.2:55239]   File "/usr/local/lib/python2.7/dist-packages/flask/app.py", line 1544, in handle_user_exception
[Fri Sep 02 08:42:49.950574 2016] [:error] [pid 2512:tid 139883284768512] [client 10.0.2.2:55239]     reraise(exc_type, exc_value, tb)
[Fri Sep 02 08:42:49.950662 2016] [:error] [pid 2512:tid 139883284768512] [client 10.0.2.2:55239]   File "/usr/local/lib/python2.7/dist-packages/flask_restful/__init__.py", line 268, in error_router
[Fri Sep 02 08:42:49.950754 2016] [:error] [pid 2512:tid 139883284768512] [client 10.0.2.2:55239]     return self.handle_error(e)
[Fri Sep 02 08:42:49.950837 2016] [:error] [pid 2512:tid 139883284768512] [client 10.0.2.2:55239]   File "/usr/local/lib/python2.7/dist-packages/flask/app.py", line 1639, in full_dispatch_request
[Fri Sep 02 08:42:49.950926 2016] [:error] [pid 2512:tid 139883284768512] [client 10.0.2.2:55239]     rv = self.dispatch_request()
[Fri Sep 02 08:42:49.950993 2016] [:error] [pid 2512:tid 139883284768512] [client 10.0.2.2:55239]   File "/usr/local/lib/python2.7/dist-packages/flask/app.py", line 1625, in dispatch_request
[Fri Sep 02 08:42:49.951067 2016] [:error] [pid 2512:tid 139883284768512] [client 10.0.2.2:55239]     return self.view_functions[rule.endpoint](**req.view_args)
[Fri Sep 02 08:42:49.951137 2016] [:error] [pid 2512:tid 139883284768512] [client 10.0.2.2:55239]   File "/usr/local/lib/python2.7/dist-packages/flask_restful/__init__.py", line 477, in wrapper
[Fri Sep 02 08:42:49.951227 2016] [:error] [pid 2512:tid 139883284768512] [client 10.0.2.2:55239]     resp = resource(*args, **kwargs)
[Fri Sep 02 08:42:49.951314 2016] [:error] [pid 2512:tid 139883284768512] [client 10.0.2.2:55239]   File "/usr/local/lib/python2.7/dist-packages/flask/views.py", line 84, in view
[Fri Sep 02 08:42:49.951450 2016] [:error] [pid 2512:tid 139883284768512] [client 10.0.2.2:55239]     return self.dispatch_request(*args, **kwargs)
[Fri Sep 02 08:42:49.951538 2016] [:error] [pid 2512:tid 139883284768512] [client 10.0.2.2:55239]   File "/usr/local/lib/python2.7/dist-packages/flask_restful/__init__.py", line 587, in dispatch_request
[Fri Sep 02 08:42:49.951688 2016] [:error] [pid 2512:tid 139883284768512] [client 10.0.2.2:55239]     resp = meth(*args, **kwargs)
[Fri Sep 02 08:42:49.951777 2016] [:error] [pid 2512:tid 139883284768512] [client 10.0.2.2:55239]   File "/var/www/virginia/resources/monologue.py", line 67, in post
[Fri Sep 02 08:42:49.953464 2016] [:error] [pid 2512:tid 139883284768512] [client 10.0.2.2:55239]     response = make_response(json.dumps(processor.process(plot, json_data['monologue'])))
[Fri Sep 02 08:42:49.953556 2016] [:error] [pid 2512:tid 139883284768512] [client 10.0.2.2:55239]   File "/var/www/virginia/processors/ctakes_processor.py", line 44, in process
[Fri Sep 02 08:42:49.954841 2016] [:error] [pid 2512:tid 139883284768512] [client 10.0.2.2:55239]     self.result['out'] = self._strategy.apply(plot,self._context)
[Fri Sep 02 08:42:49.954929 2016] [:error] [pid 2512:tid 139883284768512] [client 10.0.2.2:55239]   File "/var/www/virginia/strategy/aggregated_match.py", line 23, in apply
[Fri Sep 02 08:42:49.956192 2016] [:error] [pid 2512:tid 139883284768512] [client 10.0.2.2:55239]     self.__process()
[Fri Sep 02 08:42:49.956281 2016] [:error] [pid 2512:tid 139883284768512] [client 10.0.2.2:55239]   File "/var/www/virginia/strategy/aggregated_match.py", line 39, in __process
[Fri Sep 02 08:42:49.956625 2016] [:error] [pid 2512:tid 139883284768512] [client 10.0.2.2:55239]     new_match = {'for':self._pipeline['remaining'][idx][0],'match':','.join(result[1]), 'possiblities':[]}
[Fri Sep 02 08:42:49.956732 2016] [:error] [pid 2512:tid 139883284768512] [client 10.0.2.2:55239] IndexError: list index out of range
[Fri Sep 02 08:47:51.931316 2016] [ssl:warn] [pid 1938:tid 139883512928128] AH01909: RSA certificate configured for default:443 does NOT include an ID which matches the server name
[Fri Sep 02 09:09:42.080616 2016] [ssl:warn] [pid 1938:tid 139883512928128] AH01909: RSA certificate configured for default:443 does NOT include an ID which matches the server name
[Fri Sep 02 09:11:40.758693 2016] [ssl:warn] [pid 1938:tid 139883512928128] AH01909: RSA certificate configured for default:443 does NOT include an ID which matches the server name
[Fri Sep 02 09:11:45.034410 2016] [:error] [pid 2943:tid 139883404580608] [client 10.0.2.2:56581] mod_wsgi (pid=2943): Exception occurred processing WSGI script '/var/www/virginia/server.wsgi'.
[Fri Sep 02 09:11:45.034531 2016] [:error] [pid 2943:tid 139883404580608] [client 10.0.2.2:56581] Traceback (most recent call last):
[Fri Sep 02 09:11:45.034617 2016] [:error] [pid 2943:tid 139883404580608] [client 10.0.2.2:56581]   File "/usr/local/lib/python2.7/dist-packages/flask/app.py", line 2000, in __call__
[Fri Sep 02 09:11:45.035063 2016] [:error] [pid 2943:tid 139883404580608] [client 10.0.2.2:56581]     return self.wsgi_app(environ, start_response)
[Fri Sep 02 09:11:45.035142 2016] [:error] [pid 2943:tid 139883404580608] [client 10.0.2.2:56581]   File "/usr/local/lib/python2.7/dist-packages/flask/app.py", line 1991, in wsgi_app
[Fri Sep 02 09:11:45.035221 2016] [:error] [pid 2943:tid 139883404580608] [client 10.0.2.2:56581]     response = self.make_response(self.handle_exception(e))
[Fri Sep 02 09:11:45.035293 2016] [:error] [pid 2943:tid 139883404580608] [client 10.0.2.2:56581]   File "/usr/local/lib/python2.7/dist-packages/flask_restful/__init__.py", line 271, in error_router
[Fri Sep 02 09:11:45.035515 2016] [:error] [pid 2943:tid 139883404580608] [client 10.0.2.2:56581]     return original_handler(e)
[Fri Sep 02 09:11:45.035587 2016] [:error] [pid 2943:tid 139883404580608] [client 10.0.2.2:56581]   File "/usr/local/lib/python2.7/dist-packages/flask/app.py", line 1567, in handle_exception
[Fri Sep 02 09:11:45.035662 2016] [:error] [pid 2943:tid 139883404580608] [client 10.0.2.2:56581]     reraise(exc_type, exc_value, tb)
[Fri Sep 02 09:11:45.035729 2016] [:error] [pid 2943:tid 139883404580608] [client 10.0.2.2:56581]   File "/usr/local/lib/python2.7/dist-packages/flask_restful/__init__.py", line 268, in error_router
[Fri Sep 02 09:11:45.035806 2016] [:error] [pid 2943:tid 139883404580608] [client 10.0.2.2:56581]     return self.handle_error(e)
[Fri Sep 02 09:11:45.035888 2016] [:error] [pid 2943:tid 139883404580608] [client 10.0.2.2:56581]   File "/usr/local/lib/python2.7/dist-packages/flask/app.py", line 1988, in wsgi_app
[Fri Sep 02 09:11:45.035973 2016] [:error] [pid 2943:tid 139883404580608] [client 10.0.2.2:56581]     response = self.full_dispatch_request()
[Fri Sep 02 09:11:45.036193 2016] [:error] [pid 2943:tid 139883404580608] [client 10.0.2.2:56581]   File "/usr/local/lib/python2.7/dist-packages/flask/app.py", line 1641, in full_dispatch_request
[Fri Sep 02 09:11:45.036267 2016] [:error] [pid 2943:tid 139883404580608] [client 10.0.2.2:56581]     rv = self.handle_user_exception(e)
[Fri Sep 02 09:11:45.036333 2016] [:error] [pid 2943:tid 139883404580608] [client 10.0.2.2:56581]   File "/usr/local/lib/python2.7/dist-packages/flask_restful/__init__.py", line 271, in error_router
[Fri Sep 02 09:11:45.036406 2016] [:error] [pid 2943:tid 139883404580608] [client 10.0.2.2:56581]     return original_handler(e)
[Fri Sep 02 09:11:45.036471 2016] [:error] [pid 2943:tid 139883404580608] [client 10.0.2.2:56581]   File "/usr/local/lib/python2.7/dist-packages/flask/app.py", line 1544, in handle_user_exception
[Fri Sep 02 09:11:45.036544 2016] [:error] [pid 2943:tid 139883404580608] [client 10.0.2.2:56581]     reraise(exc_type, exc_value, tb)
[Fri Sep 02 09:11:45.036613 2016] [:error] [pid 2943:tid 139883404580608] [client 10.0.2.2:56581]   File "/usr/local/lib/python2.7/dist-packages/flask_restful/__init__.py", line 268, in error_router
[Fri Sep 02 09:11:45.036685 2016] [:error] [pid 2943:tid 139883404580608] [client 10.0.2.2:56581]     return self.handle_error(e)
[Fri Sep 02 09:11:45.036754 2016] [:error] [pid 2943:tid 139883404580608] [client 10.0.2.2:56581]   File "/usr/local/lib/python2.7/dist-packages/flask/app.py", line 1639, in full_dispatch_request
[Fri Sep 02 09:11:45.036828 2016] [:error] [pid 2943:tid 139883404580608] [client 10.0.2.2:56581]     rv = self.dispatch_request()
[Fri Sep 02 09:11:45.036894 2016] [:error] [pid 2943:tid 139883404580608] [client 10.0.2.2:56581]   File "/usr/local/lib/python2.7/dist-packages/flask/app.py", line 1625, in dispatch_request
[Fri Sep 02 09:11:45.036968 2016] [:error] [pid 2943:tid 139883404580608] [client 10.0.2.2:56581]     return self.view_functions[rule.endpoint](**req.view_args)
[Fri Sep 02 09:11:45.037053 2016] [:error] [pid 2943:tid 139883404580608] [client 10.0.2.2:56581]   File "/usr/local/lib/python2.7/dist-packages/flask_restful/__init__.py", line 477, in wrapper
[Fri Sep 02 09:11:45.037130 2016] [:error] [pid 2943:tid 139883404580608] [client 10.0.2.2:56581]     resp = resource(*args, **kwargs)
[Fri Sep 02 09:11:45.037198 2016] [:error] [pid 2943:tid 139883404580608] [client 10.0.2.2:56581]   File "/usr/local/lib/python2.7/dist-packages/flask/views.py", line 84, in view
[Fri Sep 02 09:11:45.037318 2016] [:error] [pid 2943:tid 139883404580608] [client 10.0.2.2:56581]     return self.dispatch_request(*args, **kwargs)
[Fri Sep 02 09:11:45.037392 2016] [:error] [pid 2943:tid 139883404580608] [client 10.0.2.2:56581]   File "/usr/local/lib/python2.7/dist-packages/flask_restful/__init__.py", line 587, in dispatch_request
[Fri Sep 02 09:11:45.037466 2016] [:error] [pid 2943:tid 139883404580608] [client 10.0.2.2:56581]     resp = meth(*args, **kwargs)
[Fri Sep 02 09:11:45.037534 2016] [:error] [pid 2943:tid 139883404580608] [client 10.0.2.2:56581]   File "/var/www/virginia/resources/monologue.py", line 61, in post
[Fri Sep 02 09:11:45.038493 2016] [:error] [pid 2943:tid 139883404580608] [client 10.0.2.2:56581]     plot = self.__generatePlot(json_data)
[Fri Sep 02 09:11:45.038570 2016] [:error] [pid 2943:tid 139883404580608] [client 10.0.2.2:56581]   File "/var/www/virginia/resources/monologue.py", line 75, in __generatePlot
[Fri Sep 02 09:11:45.038880 2016] [:error] [pid 2943:tid 139883404580608] [client 10.0.2.2:56581]     return Plot(data['seed'])
[Fri Sep 02 09:11:45.038953 2016] [:error] [pid 2943:tid 139883404580608] [client 10.0.2.2:56581]   File "/var/www/virginia/narrative/plot.py", line 42, in __init__
[Fri Sep 02 09:11:45.040210 2016] [:error] [pid 2943:tid 139883404580608] [client 10.0.2.2:56581]     self._processor = ProcessorFactory.getProcessor(self.__underlyingPlot['processor'])
[Fri Sep 02 09:11:45.040283 2016] [:error] [pid 2943:tid 139883404580608] [client 10.0.2.2:56581]   File "/var/www/virginia/processors/processor_factory.py", line 17, in getProcessor
[Fri Sep 02 09:11:45.041296 2016] [:error] [pid 2943:tid 139883404580608] [client 10.0.2.2:56581]     processor = ProcessorFactory.processors[processor_type]()
[Fri Sep 02 09:11:45.041369 2016] [:error] [pid 2943:tid 139883404580608] [client 10.0.2.2:56581]   File "/var/www/virginia/processors/ctakes_processor.py", line 13, in __init__
[Fri Sep 02 09:11:45.042383 2016] [:error] [pid 2943:tid 139883404580608] [client 10.0.2.2:56581]     self.__loadConfiguration()
[Fri Sep 02 09:11:45.042461 2016] [:error] [pid 2943:tid 139883404580608] [client 10.0.2.2:56581]   File "/var/www/virginia/processors/ctakes_processor.py", line 20, in __loadConfiguration
[Fri Sep 02 09:11:45.042756 2016] [:error] [pid 2943:tid 139883404580608] [client 10.0.2.2:56581]     if not self.__svcURL.endsWith('/'):
[Fri Sep 02 09:11:45.042839 2016] [:error] [pid 2943:tid 139883404580608] [client 10.0.2.2:56581] AttributeError: 'str' object has no attribute 'endsWith'
[Fri Sep 02 09:12:16.952305 2016] [ssl:warn] [pid 1938:tid 139883512928128] AH01909: RSA certificate configured for default:443 does NOT include an ID which matches the server name
[Fri Sep 02 09:15:14.172539 2016] [ssl:warn] [pid 1938:tid 139883512928128] AH01909: RSA certificate configured for default:443 does NOT include an ID which matches the server name
[Fri Sep 02 09:15:22.220032 2016] [:error] [pid 3086:tid 139883259590400] [client 10.0.2.2:56929] mod_wsgi (pid=3086): Exception occurred processing WSGI script '/var/www/virginia/server.wsgi'.
[Fri Sep 02 09:15:22.220151 2016] [:error] [pid 3086:tid 139883259590400] [client 10.0.2.2:56929] Traceback (most recent call last):
[Fri Sep 02 09:15:22.220272 2016] [:error] [pid 3086:tid 139883259590400] [client 10.0.2.2:56929]   File "/usr/local/lib/python2.7/dist-packages/flask/app.py", line 2000, in __call__
[Fri Sep 02 09:15:22.220693 2016] [:error] [pid 3086:tid 139883259590400] [client 10.0.2.2:56929]     return self.wsgi_app(environ, start_response)
[Fri Sep 02 09:15:22.220767 2016] [:error] [pid 3086:tid 139883259590400] [client 10.0.2.2:56929]   File "/usr/local/lib/python2.7/dist-packages/flask/app.py", line 1991, in wsgi_app
[Fri Sep 02 09:15:22.220844 2016] [:error] [pid 3086:tid 139883259590400] [client 10.0.2.2:56929]     response = self.make_response(self.handle_exception(e))
[Fri Sep 02 09:15:22.220911 2016] [:error] [pid 3086:tid 139883259590400] [client 10.0.2.2:56929]   File "/usr/local/lib/python2.7/dist-packages/flask_restful/__init__.py", line 271, in error_router
[Fri Sep 02 09:15:22.221119 2016] [:error] [pid 3086:tid 139883259590400] [client 10.0.2.2:56929]     return original_handler(e)
[Fri Sep 02 09:15:22.221189 2016] [:error] [pid 3086:tid 139883259590400] [client 10.0.2.2:56929]   File "/usr/local/lib/python2.7/dist-packages/flask/app.py", line 1567, in handle_exception
[Fri Sep 02 09:15:22.221263 2016] [:error] [pid 3086:tid 139883259590400] [client 10.0.2.2:56929]     reraise(exc_type, exc_value, tb)
[Fri Sep 02 09:15:22.221344 2016] [:error] [pid 3086:tid 139883259590400] [client 10.0.2.2:56929]   File "/usr/local/lib/python2.7/dist-packages/flask_restful/__init__.py", line 268, in error_router
[Fri Sep 02 09:15:22.221417 2016] [:error] [pid 3086:tid 139883259590400] [client 10.0.2.2:56929]     return self.handle_error(e)
[Fri Sep 02 09:15:22.221483 2016] [:error] [pid 3086:tid 139883259590400] [client 10.0.2.2:56929]   File "/usr/local/lib/python2.7/dist-packages/flask/app.py", line 1988, in wsgi_app
[Fri Sep 02 09:15:22.221555 2016] [:error] [pid 3086:tid 139883259590400] [client 10.0.2.2:56929]     response = self.full_dispatch_request()
[Fri Sep 02 09:15:22.221667 2016] [:error] [pid 3086:tid 139883259590400] [client 10.0.2.2:56929]   File "/usr/local/lib/python2.7/dist-packages/flask/app.py", line 1641, in full_dispatch_request
[Fri Sep 02 09:15:22.221757 2016] [:error] [pid 3086:tid 139883259590400] [client 10.0.2.2:56929]     rv = self.handle_user_exception(e)
[Fri Sep 02 09:15:22.221839 2016] [:error] [pid 3086:tid 139883259590400] [client 10.0.2.2:56929]   File "/usr/local/lib/python2.7/dist-packages/flask_restful/__init__.py", line 271, in error_router
[Fri Sep 02 09:15:22.221925 2016] [:error] [pid 3086:tid 139883259590400] [client 10.0.2.2:56929]     return original_handler(e)
[Fri Sep 02 09:15:22.221991 2016] [:error] [pid 3086:tid 139883259590400] [client 10.0.2.2:56929]   File "/usr/local/lib/python2.7/dist-packages/flask/app.py", line 1544, in handle_user_exception
[Fri Sep 02 09:15:22.222076 2016] [:error] [pid 3086:tid 139883259590400] [client 10.0.2.2:56929]     reraise(exc_type, exc_value, tb)
[Fri Sep 02 09:15:22.222141 2016] [:error] [pid 3086:tid 139883259590400] [client 10.0.2.2:56929]   File "/usr/local/lib/python2.7/dist-packages/flask_restful/__init__.py", line 268, in error_router
[Fri Sep 02 09:15:22.222226 2016] [:error] [pid 3086:tid 139883259590400] [client 10.0.2.2:56929]     return self.handle_error(e)
[Fri Sep 02 09:15:22.222298 2016] [:error] [pid 3086:tid 139883259590400] [client 10.0.2.2:56929]   File "/usr/local/lib/python2.7/dist-packages/flask/app.py", line 1639, in full_dispatch_request
[Fri Sep 02 09:15:22.222384 2016] [:error] [pid 3086:tid 139883259590400] [client 10.0.2.2:56929]     rv = self.dispatch_request()
[Fri Sep 02 09:15:22.222449 2016] [:error] [pid 3086:tid 139883259590400] [client 10.0.2.2:56929]   File "/usr/local/lib/python2.7/dist-packages/flask/app.py", line 1625, in dispatch_request
[Fri Sep 02 09:15:22.222535 2016] [:error] [pid 3086:tid 139883259590400] [client 10.0.2.2:56929]     return self.view_functions[rule.endpoint](**req.view_args)
[Fri Sep 02 09:15:22.222602 2016] [:error] [pid 3086:tid 139883259590400] [client 10.0.2.2:56929]   File "/usr/local/lib/python2.7/dist-packages/flask_restful/__init__.py", line 477, in wrapper
[Fri Sep 02 09:15:22.222687 2016] [:error] [pid 3086:tid 139883259590400] [client 10.0.2.2:56929]     resp = resource(*args, **kwargs)
[Fri Sep 02 09:15:22.222753 2016] [:error] [pid 3086:tid 139883259590400] [client 10.0.2.2:56929]   File "/usr/local/lib/python2.7/dist-packages/flask/views.py", line 84, in view
[Fri Sep 02 09:15:22.222889 2016] [:error] [pid 3086:tid 139883259590400] [client 10.0.2.2:56929]     return self.dispatch_request(*args, **kwargs)
[Fri Sep 02 09:15:22.222960 2016] [:error] [pid 3086:tid 139883259590400] [client 10.0.2.2:56929]   File "/usr/local/lib/python2.7/dist-packages/flask_restful/__init__.py", line 587, in dispatch_request
[Fri Sep 02 09:15:22.223034 2016] [:error] [pid 3086:tid 139883259590400] [client 10.0.2.2:56929]     resp = meth(*args, **kwargs)
[Fri Sep 02 09:15:22.223100 2016] [:error] [pid 3086:tid 139883259590400] [client 10.0.2.2:56929]   File "/var/www/virginia/resources/monologue.py", line 61, in post
[Fri Sep 02 09:15:22.224273 2016] [:error] [pid 3086:tid 139883259590400] [client 10.0.2.2:56929]     plot = self.__generatePlot(json_data)
[Fri Sep 02 09:15:22.224348 2016] [:error] [pid 3086:tid 139883259590400] [client 10.0.2.2:56929]   File "/var/www/virginia/resources/monologue.py", line 75, in __generatePlot
[Fri Sep 02 09:15:22.224650 2016] [:error] [pid 3086:tid 139883259590400] [client 10.0.2.2:56929]     return Plot(data['seed'])
[Fri Sep 02 09:15:22.224723 2016] [:error] [pid 3086:tid 139883259590400] [client 10.0.2.2:56929]   File "/var/www/virginia/narrative/plot.py", line 42, in __init__
[Fri Sep 02 09:15:22.225765 2016] [:error] [pid 3086:tid 139883259590400] [client 10.0.2.2:56929]     self._processor = ProcessorFactory.getProcessor(self.__underlyingPlot['processor'])
[Fri Sep 02 09:15:22.225834 2016] [:error] [pid 3086:tid 139883259590400] [client 10.0.2.2:56929]   File "/var/www/virginia/processors/processor_factory.py", line 17, in getProcessor
[Fri Sep 02 09:15:22.227040 2016] [:error] [pid 3086:tid 139883259590400] [client 10.0.2.2:56929]     processor = ProcessorFactory.processors[processor_type]()
[Fri Sep 02 09:15:22.227124 2016] [:error] [pid 3086:tid 139883259590400] [client 10.0.2.2:56929]   File "/var/www/virginia/processors/stanford_processor.py", line 21, in __init__
[Fri Sep 02 09:15:22.228271 2016] [:error] [pid 3086:tid 139883259590400] [client 10.0.2.2:56929]     self.__loadConfiguration()
[Fri Sep 02 09:15:22.228343 2016] [:error] [pid 3086:tid 139883259590400] [client 10.0.2.2:56929]   File "/var/www/virginia/processors/stanford_processor.py", line 30, in __loadConfiguration
[Fri Sep 02 09:15:22.228648 2016] [:error] [pid 3086:tid 139883259590400] [client 10.0.2.2:56929]     self.__nerSvcURL += 'ner'
[Fri Sep 02 09:15:22.228733 2016] [:error] [pid 3086:tid 139883259590400] [client 10.0.2.2:56929] AttributeError: StanfordProcessor instance has no attribute '_StanfordProcessor__nerSvcURL'
[Fri Sep 02 09:15:56.523266 2016] [ssl:warn] [pid 1938:tid 139883512928128] AH01909: RSA certificate configured for default:443 does NOT include an ID which matches the server name
