[Sat Sep 03 13:34:03.877738 2016] [ssl:warn] [pid 2950:tid 140392741906304] AH01909: RSA certificate configured for default:443 does NOT include an ID which matches the server name
[Sat Sep 03 13:34:03.889653 2016] [ssl:warn] [pid 2951:tid 140392741906304] AH01909: RSA certificate configured for default:443 does NOT include an ID which matches the server name
[Sat Sep 03 13:34:10.611200 2016] [:error] [pid 2955:tid 140392633558784] [client 10.0.2.2:51967] mod_wsgi (pid=2955): Target WSGI script '/var/www/virginia/server.wsgi' cannot be loaded as Python module.
[Sat Sep 03 13:34:10.611320 2016] [:error] [pid 2955:tid 140392633558784] [client 10.0.2.2:51967] mod_wsgi (pid=2955): Exception occurred processing WSGI script '/var/www/virginia/server.wsgi'.
[Sat Sep 03 13:34:10.611457 2016] [:error] [pid 2955:tid 140392633558784] [client 10.0.2.2:51967] Traceback (most recent call last):
[Sat Sep 03 13:34:10.611546 2016] [:error] [pid 2955:tid 140392633558784] [client 10.0.2.2:51967]   File "/var/www/virginia/server.wsgi", line 14, in <module>
[Sat Sep 03 13:34:10.612738 2016] [:error] [pid 2955:tid 140392633558784] [client 10.0.2.2:51967]     from virginia import monologue_svc as application
[Sat Sep 03 13:34:10.612854 2016] [:error] [pid 2955:tid 140392633558784] [client 10.0.2.2:51967]   File "/var/www/virginia/virginia.py", line 9, in <module>
[Sat Sep 03 13:34:10.614406 2016] [:error] [pid 2955:tid 140392633558784] [client 10.0.2.2:51967]     from applogging.virginia_logger import Logger
[Sat Sep 03 13:34:10.614501 2016] [:error] [pid 2955:tid 140392633558784] [client 10.0.2.2:51967]   File "/var/www/virginia/applogging/virginia_logger.py", line 3, in <module>
[Sat Sep 03 13:34:10.615871 2016] [:error] [pid 2955:tid 140392633558784] [client 10.0.2.2:51967]     class Logger:
[Sat Sep 03 13:34:10.615975 2016] [:error] [pid 2955:tid 140392633558784] [client 10.0.2.2:51967]   File "/var/www/virginia/applogging/virginia_logger.py", line 7, in Logger
[Sat Sep 03 13:34:10.616277 2016] [:error] [pid 2955:tid 140392633558784] [client 10.0.2.2:51967]     @stat
[Sat Sep 03 13:34:10.616366 2016] [:error] [pid 2955:tid 140392633558784] [client 10.0.2.2:51967] NameError: name 'stat' is not defined
[Sat Sep 03 13:34:49.923583 2016] [ssl:warn] [pid 2951:tid 140392741906304] AH01909: RSA certificate configured for default:443 does NOT include an ID which matches the server name
[Sat Sep 03 13:34:54.363477 2016] [:error] [pid 3044:tid 140392633558784] [client 10.0.2.2:52017] mod_wsgi (pid=3044): Exception occurred processing WSGI script '/var/www/virginia/server.wsgi'.
[Sat Sep 03 13:34:54.363653 2016] [:error] [pid 3044:tid 140392633558784] [client 10.0.2.2:52017] Traceback (most recent call last):
[Sat Sep 03 13:34:54.363807 2016] [:error] [pid 3044:tid 140392633558784] [client 10.0.2.2:52017]   File "/usr/local/lib/python2.7/dist-packages/flask/app.py", line 2000, in __call__
[Sat Sep 03 13:34:54.364218 2016] [:error] [pid 3044:tid 140392633558784] [client 10.0.2.2:52017]     return self.wsgi_app(environ, start_response)
[Sat Sep 03 13:34:54.364359 2016] [:error] [pid 3044:tid 140392633558784] [client 10.0.2.2:52017]   File "/usr/local/lib/python2.7/dist-packages/flask/app.py", line 1991, in wsgi_app
[Sat Sep 03 13:34:54.364494 2016] [:error] [pid 3044:tid 140392633558784] [client 10.0.2.2:52017]     response = self.make_response(self.handle_exception(e))
[Sat Sep 03 13:34:54.364628 2016] [:error] [pid 3044:tid 140392633558784] [client 10.0.2.2:52017]   File "/usr/local/lib/python2.7/dist-packages/flask_restful/__init__.py", line 271, in error_router
[Sat Sep 03 13:34:54.364885 2016] [:error] [pid 3044:tid 140392633558784] [client 10.0.2.2:52017]     return original_handler(e)
[Sat Sep 03 13:34:54.365002 2016] [:error] [pid 3044:tid 140392633558784] [client 10.0.2.2:52017]   File "/usr/local/lib/python2.7/dist-packages/flask/app.py", line 1567, in handle_exception
[Sat Sep 03 13:34:54.365122 2016] [:error] [pid 3044:tid 140392633558784] [client 10.0.2.2:52017]     reraise(exc_type, exc_value, tb)
[Sat Sep 03 13:34:54.365197 2016] [:error] [pid 3044:tid 140392633558784] [client 10.0.2.2:52017]   File "/usr/local/lib/python2.7/dist-packages/flask/app.py", line 1988, in wsgi_app
[Sat Sep 03 13:34:54.365386 2016] [:error] [pid 3044:tid 140392633558784] [client 10.0.2.2:52017]     response = self.full_dispatch_request()
[Sat Sep 03 13:34:54.365467 2016] [:error] [pid 3044:tid 140392633558784] [client 10.0.2.2:52017]   File "/usr/local/lib/python2.7/dist-packages/flask/app.py", line 1641, in full_dispatch_request
[Sat Sep 03 13:34:54.365546 2016] [:error] [pid 3044:tid 140392633558784] [client 10.0.2.2:52017]     rv = self.handle_user_exception(e)
[Sat Sep 03 13:34:54.365613 2016] [:error] [pid 3044:tid 140392633558784] [client 10.0.2.2:52017]   File "/usr/local/lib/python2.7/dist-packages/flask_restful/__init__.py", line 271, in error_router
[Sat Sep 03 13:34:54.365686 2016] [:error] [pid 3044:tid 140392633558784] [client 10.0.2.2:52017]     return original_handler(e)
[Sat Sep 03 13:34:54.365752 2016] [:error] [pid 3044:tid 140392633558784] [client 10.0.2.2:52017]   File "/usr/local/lib/python2.7/dist-packages/flask/app.py", line 1544, in handle_user_exception
[Sat Sep 03 13:34:54.365966 2016] [:error] [pid 3044:tid 140392633558784] [client 10.0.2.2:52017]     reraise(exc_type, exc_value, tb)
[Sat Sep 03 13:34:54.366039 2016] [:error] [pid 3044:tid 140392633558784] [client 10.0.2.2:52017]   File "/usr/local/lib/python2.7/dist-packages/flask/app.py", line 1639, in full_dispatch_request
[Sat Sep 03 13:34:54.366111 2016] [:error] [pid 3044:tid 140392633558784] [client 10.0.2.2:52017]     rv = self.dispatch_request()
[Sat Sep 03 13:34:54.366177 2016] [:error] [pid 3044:tid 140392633558784] [client 10.0.2.2:52017]   File "/usr/local/lib/python2.7/dist-packages/flask/app.py", line 1625, in dispatch_request
[Sat Sep 03 13:34:54.366249 2016] [:error] [pid 3044:tid 140392633558784] [client 10.0.2.2:52017]     return self.view_functions[rule.endpoint](**req.view_args)
[Sat Sep 03 13:34:54.366315 2016] [:error] [pid 3044:tid 140392633558784] [client 10.0.2.2:52017]   File "/var/www/virginia/virginia.py", line 28, in ocr
[Sat Sep 03 13:34:54.367670 2016] [:error] [pid 3044:tid 140392633558784] [client 10.0.2.2:52017]     Logger.getLogger().info('received ocr request...')
[Sat Sep 03 13:34:54.367748 2016] [:error] [pid 3044:tid 140392633558784] [client 10.0.2.2:52017]   File "/var/www/virginia/applogging/virginia_logger.py", line 9, in getLogger
[Sat Sep 03 13:34:54.368920 2016] [:error] [pid 3044:tid 140392633558784] [client 10.0.2.2:52017]     return logger
[Sat Sep 03 13:34:54.369016 2016] [:error] [pid 3044:tid 140392633558784] [client 10.0.2.2:52017] NameError: global name 'logger' is not defined
[Sat Sep 03 13:36:15.103473 2016] [ssl:warn] [pid 2951:tid 140392741906304] AH01909: RSA certificate configured for default:443 does NOT include an ID which matches the server name
[Sat Sep 03 13:38:06.595335 2016] [ssl:warn] [pid 2951:tid 140392741906304] AH01909: RSA certificate configured for default:443 does NOT include an ID which matches the server name
[Sat Sep 03 13:42:42.137104 2016] [:error] [pid 3128:tid 140392633558784] [client 10.0.2.2:52110] mod_wsgi (pid=3128): Exception occurred processing WSGI script '/var/www/virginia/server.wsgi'.
[Sat Sep 03 13:42:42.137534 2016] [:error] [pid 3128:tid 140392633558784] [client 10.0.2.2:52110] Traceback (most recent call last):
[Sat Sep 03 13:42:42.137858 2016] [:error] [pid 3128:tid 140392633558784] [client 10.0.2.2:52110]   File "/usr/local/lib/python2.7/dist-packages/flask/app.py", line 2000, in __call__
[Sat Sep 03 13:42:42.139124 2016] [:error] [pid 3128:tid 140392633558784] [client 10.0.2.2:52110]     return self.wsgi_app(environ, start_response)
[Sat Sep 03 13:42:42.139403 2016] [:error] [pid 3128:tid 140392633558784] [client 10.0.2.2:52110]   File "/usr/local/lib/python2.7/dist-packages/flask/app.py", line 1991, in wsgi_app
[Sat Sep 03 13:42:42.139688 2016] [:error] [pid 3128:tid 140392633558784] [client 10.0.2.2:52110]     response = self.make_response(self.handle_exception(e))
[Sat Sep 03 13:42:42.139909 2016] [:error] [pid 3128:tid 140392633558784] [client 10.0.2.2:52110]   File "/usr/local/lib/python2.7/dist-packages/flask_restful/__init__.py", line 271, in error_router
[Sat Sep 03 13:42:42.140695 2016] [:error] [pid 3128:tid 140392633558784] [client 10.0.2.2:52110]     return original_handler(e)
[Sat Sep 03 13:42:42.140955 2016] [:error] [pid 3128:tid 140392633558784] [client 10.0.2.2:52110]   File "/usr/local/lib/python2.7/dist-packages/flask/app.py", line 1567, in handle_exception
[Sat Sep 03 13:42:42.141222 2016] [:error] [pid 3128:tid 140392633558784] [client 10.0.2.2:52110]     reraise(exc_type, exc_value, tb)
[Sat Sep 03 13:42:42.141457 2016] [:error] [pid 3128:tid 140392633558784] [client 10.0.2.2:52110]   File "/usr/local/lib/python2.7/dist-packages/flask/app.py", line 1988, in wsgi_app
[Sat Sep 03 13:42:42.141708 2016] [:error] [pid 3128:tid 140392633558784] [client 10.0.2.2:52110]     response = self.full_dispatch_request()
[Sat Sep 03 13:42:42.141998 2016] [:error] [pid 3128:tid 140392633558784] [client 10.0.2.2:52110]   File "/usr/local/lib/python2.7/dist-packages/flask/app.py", line 1641, in full_dispatch_request
[Sat Sep 03 13:42:42.142247 2016] [:error] [pid 3128:tid 140392633558784] [client 10.0.2.2:52110]     rv = self.handle_user_exception(e)
[Sat Sep 03 13:42:42.142492 2016] [:error] [pid 3128:tid 140392633558784] [client 10.0.2.2:52110]   File "/usr/local/lib/python2.7/dist-packages/flask_restful/__init__.py", line 271, in error_router
[Sat Sep 03 13:42:42.142739 2016] [:error] [pid 3128:tid 140392633558784] [client 10.0.2.2:52110]     return original_handler(e)
[Sat Sep 03 13:42:42.142996 2016] [:error] [pid 3128:tid 140392633558784] [client 10.0.2.2:52110]   File "/usr/local/lib/python2.7/dist-packages/flask/app.py", line 1544, in handle_user_exception
[Sat Sep 03 13:42:42.143258 2016] [:error] [pid 3128:tid 140392633558784] [client 10.0.2.2:52110]     reraise(exc_type, exc_value, tb)
[Sat Sep 03 13:42:42.143492 2016] [:error] [pid 3128:tid 140392633558784] [client 10.0.2.2:52110]   File "/usr/local/lib/python2.7/dist-packages/flask/app.py", line 1639, in full_dispatch_request
[Sat Sep 03 13:42:42.143739 2016] [:error] [pid 3128:tid 140392633558784] [client 10.0.2.2:52110]     rv = self.dispatch_request()
[Sat Sep 03 13:42:42.143984 2016] [:error] [pid 3128:tid 140392633558784] [client 10.0.2.2:52110]   File "/usr/local/lib/python2.7/dist-packages/flask/app.py", line 1625, in dispatch_request
[Sat Sep 03 13:42:42.144231 2016] [:error] [pid 3128:tid 140392633558784] [client 10.0.2.2:52110]     return self.view_functions[rule.endpoint](**req.view_args)
[Sat Sep 03 13:42:42.144463 2016] [:error] [pid 3128:tid 140392633558784] [client 10.0.2.2:52110]   File "/var/www/virginia/virginia.py", line 37, in ocr
[Sat Sep 03 13:42:42.148154 2016] [:error] [pid 3128:tid 140392633558784] [client 10.0.2.2:52110]     annotated_text = vision_api_client.detect_text(file_list)
[Sat Sep 03 13:42:42.148406 2016] [:error] [pid 3128:tid 140392633558784] [client 10.0.2.2:52110]   File "/var/www/virginia/utils/vision.py", line 44, in detect_text
[Sat Sep 03 13:42:42.152062 2016] [:error] [pid 3128:tid 140392633558784] [client 10.0.2.2:52110]     responses = request.execute(num_retries=num_retries)
[Sat Sep 03 13:42:42.152297 2016] [:error] [pid 3128:tid 140392633558784] [client 10.0.2.2:52110]   File "/usr/local/lib/python2.7/dist-packages/oauth2client/util.py", line 137, in positional_wrapper
[Sat Sep 03 13:42:42.152703 2016] [:error] [pid 3128:tid 140392633558784] [client 10.0.2.2:52110]     return wrapped(*args, **kwargs)
[Sat Sep 03 13:42:42.152937 2016] [:error] [pid 3128:tid 140392633558784] [client 10.0.2.2:52110]   File "/usr/local/lib/python2.7/dist-packages/googleapiclient/http.py", line 833, in execute
[Sat Sep 03 13:42:42.153860 2016] [:error] [pid 3128:tid 140392633558784] [client 10.0.2.2:52110]     method=str(self.method), body=self.body, headers=self.headers)
[Sat Sep 03 13:42:42.154186 2016] [:error] [pid 3128:tid 140392633558784] [client 10.0.2.2:52110]   File "/usr/local/lib/python2.7/dist-packages/googleapiclient/http.py", line 160, in _retry_request
[Sat Sep 03 13:42:42.154589 2016] [:error] [pid 3128:tid 140392633558784] [client 10.0.2.2:52110]     resp, content = http.request(uri, method, *args, **kwargs)
[Sat Sep 03 13:42:42.154821 2016] [:error] [pid 3128:tid 140392633558784] [client 10.0.2.2:52110]   File "/usr/local/lib/python2.7/dist-packages/oauth2client/transport.py", line 153, in new_request
[Sat Sep 03 13:42:42.155300 2016] [:error] [pid 3128:tid 140392633558784] [client 10.0.2.2:52110]     credentials._refresh(orig_request_method)
[Sat Sep 03 13:42:42.155539 2016] [:error] [pid 3128:tid 140392633558784] [client 10.0.2.2:52110]   File "/usr/local/lib/python2.7/dist-packages/oauth2client/client.py", line 765, in _refresh
[Sat Sep 03 13:42:42.156781 2016] [:error] [pid 3128:tid 140392633558784] [client 10.0.2.2:52110]     self._do_refresh_request(http_request)
[Sat Sep 03 13:42:42.156933 2016] [:error] [pid 3128:tid 140392633558784] [client 10.0.2.2:52110]   File "/usr/local/lib/python2.7/dist-packages/oauth2client/client.py", line 797, in _do_refresh_request
[Sat Sep 03 13:42:42.157096 2016] [:error] [pid 3128:tid 140392633558784] [client 10.0.2.2:52110]     self.token_uri, method='POST', body=body, headers=headers)
[Sat Sep 03 13:42:42.157254 2016] [:error] [pid 3128:tid 140392633558784] [client 10.0.2.2:52110]   File "/usr/lib/python2.7/dist-packages/httplib2/__init__.py", line 1569, in request
[Sat Sep 03 13:42:42.157857 2016] [:error] [pid 3128:tid 140392633558784] [client 10.0.2.2:52110]     (response, content) = self._request(conn, authority, uri, request_uri, method, body, headers, redirections, cachekey)
[Sat Sep 03 13:42:42.158060 2016] [:error] [pid 3128:tid 140392633558784] [client 10.0.2.2:52110]   File "/usr/lib/python2.7/dist-packages/httplib2/__init__.py", line 1316, in _request
[Sat Sep 03 13:42:42.158221 2016] [:error] [pid 3128:tid 140392633558784] [client 10.0.2.2:52110]     (response, content) = self._conn_request(conn, request_uri, method, body, headers)
[Sat Sep 03 13:42:42.158368 2016] [:error] [pid 3128:tid 140392633558784] [client 10.0.2.2:52110]   File "/usr/lib/python2.7/dist-packages/httplib2/__init__.py", line 1285, in _conn_request
[Sat Sep 03 13:42:42.158497 2016] [:error] [pid 3128:tid 140392633558784] [client 10.0.2.2:52110]     response = conn.getresponse()
[Sat Sep 03 13:42:42.158614 2016] [:error] [pid 3128:tid 140392633558784] [client 10.0.2.2:52110]   File "/usr/lib/python2.7/httplib.py", line 1039, in getresponse
[Sat Sep 03 13:42:42.159146 2016] [:error] [pid 3128:tid 140392633558784] [client 10.0.2.2:52110]     raise ResponseNotReady()
[Sat Sep 03 13:42:42.159291 2016] [:error] [pid 3128:tid 140392633558784] [client 10.0.2.2:52110] ResponseNotReady
[Sat Sep 03 13:44:36.724935 2016] [:error] [pid 3217:tid 140392389330688] [client 10.0.2.2:52520] mod_wsgi (pid=3217): Exception occurred processing WSGI script '/var/www/virginia/server.wsgi'.
[Sat Sep 03 13:44:36.726198 2016] [:error] [pid 3217:tid 140392389330688] [client 10.0.2.2:52520] Traceback (most recent call last):
[Sat Sep 03 13:44:36.726545 2016] [:error] [pid 3217:tid 140392389330688] [client 10.0.2.2:52520]   File "/usr/local/lib/python2.7/dist-packages/flask/app.py", line 2000, in __call__
[Sat Sep 03 13:44:36.727705 2016] [:error] [pid 3217:tid 140392389330688] [client 10.0.2.2:52520]     return self.wsgi_app(environ, start_response)
[Sat Sep 03 13:44:36.727923 2016] [:error] [pid 3217:tid 140392389330688] [client 10.0.2.2:52520]   File "/usr/local/lib/python2.7/dist-packages/flask/app.py", line 1991, in wsgi_app
[Sat Sep 03 13:44:36.728143 2016] [:error] [pid 3217:tid 140392389330688] [client 10.0.2.2:52520]     response = self.make_response(self.handle_exception(e))
[Sat Sep 03 13:44:36.728360 2016] [:error] [pid 3217:tid 140392389330688] [client 10.0.2.2:52520]   File "/usr/local/lib/python2.7/dist-packages/flask_restful/__init__.py", line 271, in error_router
[Sat Sep 03 13:44:36.728884 2016] [:error] [pid 3217:tid 140392389330688] [client 10.0.2.2:52520]     return original_handler(e)
[Sat Sep 03 13:44:36.729086 2016] [:error] [pid 3217:tid 140392389330688] [client 10.0.2.2:52520]   File "/usr/local/lib/python2.7/dist-packages/flask/app.py", line 1567, in handle_exception
[Sat Sep 03 13:44:36.729295 2016] [:error] [pid 3217:tid 140392389330688] [client 10.0.2.2:52520]     reraise(exc_type, exc_value, tb)
[Sat Sep 03 13:44:36.729508 2016] [:error] [pid 3217:tid 140392389330688] [client 10.0.2.2:52520]   File "/usr/local/lib/python2.7/dist-packages/flask/app.py", line 1988, in wsgi_app
[Sat Sep 03 13:44:36.729711 2016] [:error] [pid 3217:tid 140392389330688] [client 10.0.2.2:52520]     response = self.full_dispatch_request()
[Sat Sep 03 13:44:36.729974 2016] [:error] [pid 3217:tid 140392389330688] [client 10.0.2.2:52520]   File "/usr/local/lib/python2.7/dist-packages/flask/app.py", line 1641, in full_dispatch_request
[Sat Sep 03 13:44:36.730175 2016] [:error] [pid 3217:tid 140392389330688] [client 10.0.2.2:52520]     rv = self.handle_user_exception(e)
[Sat Sep 03 13:44:36.730359 2016] [:error] [pid 3217:tid 140392389330688] [client 10.0.2.2:52520]   File "/usr/local/lib/python2.7/dist-packages/flask_restful/__init__.py", line 271, in error_router
[Sat Sep 03 13:44:36.730572 2016] [:error] [pid 3217:tid 140392389330688] [client 10.0.2.2:52520]     return original_handler(e)
[Sat Sep 03 13:44:36.730756 2016] [:error] [pid 3217:tid 140392389330688] [client 10.0.2.2:52520]   File "/usr/local/lib/python2.7/dist-packages/flask/app.py", line 1544, in handle_user_exception
[Sat Sep 03 13:44:36.730955 2016] [:error] [pid 3217:tid 140392389330688] [client 10.0.2.2:52520]     reraise(exc_type, exc_value, tb)
[Sat Sep 03 13:44:36.731138 2016] [:error] [pid 3217:tid 140392389330688] [client 10.0.2.2:52520]   File "/usr/local/lib/python2.7/dist-packages/flask/app.py", line 1639, in full_dispatch_request
[Sat Sep 03 13:44:36.731336 2016] [:error] [pid 3217:tid 140392389330688] [client 10.0.2.2:52520]     rv = self.dispatch_request()
[Sat Sep 03 13:44:36.731602 2016] [:error] [pid 3217:tid 140392389330688] [client 10.0.2.2:52520]   File "/usr/local/lib/python2.7/dist-packages/flask/app.py", line 1625, in dispatch_request
[Sat Sep 03 13:44:36.731834 2016] [:error] [pid 3217:tid 140392389330688] [client 10.0.2.2:52520]     return self.view_functions[rule.endpoint](**req.view_args)
[Sat Sep 03 13:44:36.731993 2016] [:error] [pid 3217:tid 140392389330688] [client 10.0.2.2:52520]   File "/var/www/virginia/virginia.py", line 37, in ocr
[Sat Sep 03 13:44:36.734922 2016] [:error] [pid 3217:tid 140392389330688] [client 10.0.2.2:52520]     annotated_text = vision_api_client.detect_text(file_list)
[Sat Sep 03 13:44:36.735115 2016] [:error] [pid 3217:tid 140392389330688] [client 10.0.2.2:52520]   File "/var/www/virginia/utils/vision.py", line 44, in detect_text
[Sat Sep 03 13:44:36.738007 2016] [:error] [pid 3217:tid 140392389330688] [client 10.0.2.2:52520]     responses = request.execute(num_retries=num_retries)
[Sat Sep 03 13:44:36.738233 2016] [:error] [pid 3217:tid 140392389330688] [client 10.0.2.2:52520]   File "/usr/local/lib/python2.7/dist-packages/oauth2client/util.py", line 137, in positional_wrapper
[Sat Sep 03 13:44:36.738529 2016] [:error] [pid 3217:tid 140392389330688] [client 10.0.2.2:52520]     return wrapped(*args, **kwargs)
[Sat Sep 03 13:44:36.738738 2016] [:error] [pid 3217:tid 140392389330688] [client 10.0.2.2:52520]   File "/usr/local/lib/python2.7/dist-packages/googleapiclient/http.py", line 833, in execute
[Sat Sep 03 13:44:36.739513 2016] [:error] [pid 3217:tid 140392389330688] [client 10.0.2.2:52520]     method=str(self.method), body=self.body, headers=self.headers)
[Sat Sep 03 13:44:36.739673 2016] [:error] [pid 3217:tid 140392389330688] [client 10.0.2.2:52520]   File "/usr/local/lib/python2.7/dist-packages/googleapiclient/http.py", line 160, in _retry_request
[Sat Sep 03 13:44:36.739878 2016] [:error] [pid 3217:tid 140392389330688] [client 10.0.2.2:52520]     resp, content = http.request(uri, method, *args, **kwargs)
[Sat Sep 03 13:44:36.740027 2016] [:error] [pid 3217:tid 140392389330688] [client 10.0.2.2:52520]   File "/usr/local/lib/python2.7/dist-packages/oauth2client/transport.py", line 153, in new_request
[Sat Sep 03 13:44:36.740326 2016] [:error] [pid 3217:tid 140392389330688] [client 10.0.2.2:52520]     credentials._refresh(orig_request_method)
[Sat Sep 03 13:44:36.740518 2016] [:error] [pid 3217:tid 140392389330688] [client 10.0.2.2:52520]   File "/usr/local/lib/python2.7/dist-packages/oauth2client/client.py", line 765, in _refresh
[Sat Sep 03 13:44:36.741392 2016] [:error] [pid 3217:tid 140392389330688] [client 10.0.2.2:52520]     self._do_refresh_request(http_request)
[Sat Sep 03 13:44:36.741661 2016] [:error] [pid 3217:tid 140392389330688] [client 10.0.2.2:52520]   File "/usr/local/lib/python2.7/dist-packages/oauth2client/client.py", line 797, in _do_refresh_request
[Sat Sep 03 13:44:36.742023 2016] [:error] [pid 3217:tid 140392389330688] [client 10.0.2.2:52520]     self.token_uri, method='POST', body=body, headers=headers)
[Sat Sep 03 13:44:36.742254 2016] [:error] [pid 3217:tid 140392389330688] [client 10.0.2.2:52520]   File "/usr/lib/python2.7/dist-packages/httplib2/__init__.py", line 1569, in request
[Sat Sep 03 13:44:36.743144 2016] [:error] [pid 3217:tid 140392389330688] [client 10.0.2.2:52520]     (response, content) = self._request(conn, authority, uri, request_uri, method, body, headers, redirections, cachekey)
[Sat Sep 03 13:44:36.743384 2016] [:error] [pid 3217:tid 140392389330688] [client 10.0.2.2:52520]   File "/usr/lib/python2.7/dist-packages/httplib2/__init__.py", line 1316, in _request
[Sat Sep 03 13:44:36.743626 2016] [:error] [pid 3217:tid 140392389330688] [client 10.0.2.2:52520]     (response, content) = self._conn_request(conn, request_uri, method, body, headers)
[Sat Sep 03 13:44:36.743840 2016] [:error] [pid 3217:tid 140392389330688] [client 10.0.2.2:52520]   File "/usr/lib/python2.7/dist-packages/httplib2/__init__.py", line 1285, in _conn_request
[Sat Sep 03 13:44:36.744075 2016] [:error] [pid 3217:tid 140392389330688] [client 10.0.2.2:52520]     response = conn.getresponse()
[Sat Sep 03 13:44:36.744294 2016] [:error] [pid 3217:tid 140392389330688] [client 10.0.2.2:52520]   File "/usr/lib/python2.7/httplib.py", line 1039, in getresponse
[Sat Sep 03 13:44:36.744997 2016] [:error] [pid 3217:tid 140392389330688] [client 10.0.2.2:52520]     raise ResponseNotReady()
[Sat Sep 03 13:44:36.745213 2016] [:error] [pid 3217:tid 140392389330688] [client 10.0.2.2:52520] ResponseNotReady
[Sat Sep 03 13:46:17.853166 2016] [ssl:warn] [pid 2951:tid 140392741906304] AH01909: RSA certificate configured for default:443 does NOT include an ID which matches the server name
[Sat Sep 03 13:49:15.205477 2016] [ssl:warn] [pid 2951:tid 140392741906304] AH01909: RSA certificate configured for default:443 does NOT include an ID which matches the server name
[Sat Sep 03 13:50:15.709946 2016] [ssl:warn] [pid 2951:tid 140392741906304] AH01909: RSA certificate configured for default:443 does NOT include an ID which matches the server name
[Sat Sep 03 13:52:18.268366 2016] [ssl:warn] [pid 3718:tid 139955955099520] AH01909: RSA certificate configured for default:443 does NOT include an ID which matches the server name
[Sat Sep 03 13:52:18.280962 2016] [ssl:warn] [pid 3719:tid 139955955099520] AH01909: RSA certificate configured for default:443 does NOT include an ID which matches the server name
[Sat Sep 03 13:54:58.568428 2016] [ssl:warn] [pid 3719:tid 139955955099520] AH01909: RSA certificate configured for default:443 does NOT include an ID which matches the server name
[Sat Sep 03 13:56:35.816301 2016] [ssl:warn] [pid 3955:tid 140509158123392] AH01909: RSA certificate configured for default:443 does NOT include an ID which matches the server name
[Sat Sep 03 13:56:35.829083 2016] [ssl:warn] [pid 3956:tid 140509158123392] AH01909: RSA certificate configured for default:443 does NOT include an ID which matches the server name
[Sat Sep 03 13:56:40.603010 2016] [:error] [pid 3959:tid 140509032990464] [client 10.0.2.2:54381] mod_wsgi (pid=3959): Target WSGI script '/var/www/virginia/server.wsgi' cannot be loaded as Python module.
[Sat Sep 03 13:56:40.603295 2016] [:error] [pid 3959:tid 140509032990464] [client 10.0.2.2:54381] mod_wsgi (pid=3959): Exception occurred processing WSGI script '/var/www/virginia/server.wsgi'.
[Sat Sep 03 13:56:40.603707 2016] [:error] [pid 3959:tid 140509032990464] [client 10.0.2.2:54381] Traceback (most recent call last):
[Sat Sep 03 13:56:40.603947 2016] [:error] [pid 3959:tid 140509032990464] [client 10.0.2.2:54381]   File "/var/www/virginia/server.wsgi", line 14, in <module>
[Sat Sep 03 13:56:40.606884 2016] [:error] [pid 3959:tid 140509032990464] [client 10.0.2.2:54381]     from virginia import monologue_svc as application
[Sat Sep 03 13:56:40.607482 2016] [:error] [pid 3959:tid 140509032990464] [client 10.0.2.2:54381]   File "/var/www/virginia/virginia.py", line 10
[Sat Sep 03 13:56:40.607688 2016] [:error] [pid 3959:tid 140509032990464] [client 10.0.2.2:54381]     from applogging.virginia_logger import Logger.log
[Sat Sep 03 13:56:40.607865 2016] [:error] [pid 3959:tid 140509032990464] [client 10.0.2.2:54381]                                                  ^
[Sat Sep 03 13:56:40.608036 2016] [:error] [pid 3959:tid 140509032990464] [client 10.0.2.2:54381] SyntaxError: invalid syntax
[Sat Sep 03 14:00:31.510981 2016] [ssl:warn] [pid 3956:tid 140509158123392] AH01909: RSA certificate configured for default:443 does NOT include an ID which matches the server name
[Sat Sep 03 14:00:34.942367 2016] [:error] [pid 4062:tid 140509049775872] [client 10.0.2.2:55054] mod_wsgi (pid=4062): Target WSGI script '/var/www/virginia/server.wsgi' cannot be loaded as Python module.
[Sat Sep 03 14:00:34.942537 2016] [:error] [pid 4062:tid 140509049775872] [client 10.0.2.2:55054] mod_wsgi (pid=4062): Exception occurred processing WSGI script '/var/www/virginia/server.wsgi'.
[Sat Sep 03 14:00:34.942652 2016] [:error] [pid 4062:tid 140509049775872] [client 10.0.2.2:55054] Traceback (most recent call last):
[Sat Sep 03 14:00:34.942769 2016] [:error] [pid 4062:tid 140509049775872] [client 10.0.2.2:55054]   File "/var/www/virginia/server.wsgi", line 14, in <module>
[Sat Sep 03 14:00:34.944153 2016] [:error] [pid 4062:tid 140509049775872] [client 10.0.2.2:55054]     from virginia import monologue_svc as application
[Sat Sep 03 14:00:34.944314 2016] [:error] [pid 4062:tid 140509049775872] [client 10.0.2.2:55054]   File "/var/www/virginia/virginia.py", line 10
[Sat Sep 03 14:00:34.944498 2016] [:error] [pid 4062:tid 140509049775872] [client 10.0.2.2:55054]     from applogging.virginia_logger import Logger.log
[Sat Sep 03 14:00:34.944593 2016] [:error] [pid 4062:tid 140509049775872] [client 10.0.2.2:55054]                                                  ^
[Sat Sep 03 14:00:34.944685 2016] [:error] [pid 4062:tid 140509049775872] [client 10.0.2.2:55054] SyntaxError: invalid syntax
[Sat Sep 03 14:00:57.885769 2016] [ssl:warn] [pid 3956:tid 140509158123392] AH01909: RSA certificate configured for default:443 does NOT include an ID which matches the server name
[Sat Sep 03 14:02:58.270353 2016] [ssl:warn] [pid 3956:tid 140509158123392] AH01909: RSA certificate configured for default:443 does NOT include an ID which matches the server name
[Sat Sep 03 14:04:20.507195 2016] [ssl:warn] [pid 3956:tid 140509158123392] AH01909: RSA certificate configured for default:443 does NOT include an ID which matches the server name
[Sat Sep 03 14:07:26.425994 2016] [:error] [pid 4144:tid 140509032990464] [client 10.0.2.2:55088] mod_wsgi (pid=4144): Exception occurred processing WSGI script '/var/www/virginia/server.wsgi'.
[Sat Sep 03 14:07:26.426498 2016] [:error] [pid 4144:tid 140509032990464] [client 10.0.2.2:55088] Traceback (most recent call last):
[Sat Sep 03 14:07:26.426811 2016] [:error] [pid 4144:tid 140509032990464] [client 10.0.2.2:55088]   File "/usr/local/lib/python2.7/dist-packages/flask/app.py", line 2000, in __call__
[Sat Sep 03 14:07:26.428118 2016] [:error] [pid 4144:tid 140509032990464] [client 10.0.2.2:55088]     return self.wsgi_app(environ, start_response)
[Sat Sep 03 14:07:26.428384 2016] [:error] [pid 4144:tid 140509032990464] [client 10.0.2.2:55088]   File "/usr/local/lib/python2.7/dist-packages/flask/app.py", line 1991, in wsgi_app
[Sat Sep 03 14:07:26.428801 2016] [:error] [pid 4144:tid 140509032990464] [client 10.0.2.2:55088]     response = self.make_response(self.handle_exception(e))
[Sat Sep 03 14:07:26.429081 2016] [:error] [pid 4144:tid 140509032990464] [client 10.0.2.2:55088]   File "/usr/local/lib/python2.7/dist-packages/flask_restful/__init__.py", line 271, in error_router
[Sat Sep 03 14:07:26.429751 2016] [:error] [pid 4144:tid 140509032990464] [client 10.0.2.2:55088]     return original_handler(e)
[Sat Sep 03 14:07:26.430040 2016] [:error] [pid 4144:tid 140509032990464] [client 10.0.2.2:55088]   File "/usr/local/lib/python2.7/dist-packages/flask/app.py", line 1567, in handle_exception
[Sat Sep 03 14:07:26.430300 2016] [:error] [pid 4144:tid 140509032990464] [client 10.0.2.2:55088]     reraise(exc_type, exc_value, tb)
[Sat Sep 03 14:07:26.430564 2016] [:error] [pid 4144:tid 140509032990464] [client 10.0.2.2:55088]   File "/usr/local/lib/python2.7/dist-packages/flask/app.py", line 1988, in wsgi_app
[Sat Sep 03 14:07:26.430823 2016] [:error] [pid 4144:tid 140509032990464] [client 10.0.2.2:55088]     response = self.full_dispatch_request()
[Sat Sep 03 14:07:26.431082 2016] [:error] [pid 4144:tid 140509032990464] [client 10.0.2.2:55088]   File "/usr/local/lib/python2.7/dist-packages/flask/app.py", line 1641, in full_dispatch_request
[Sat Sep 03 14:07:26.431336 2016] [:error] [pid 4144:tid 140509032990464] [client 10.0.2.2:55088]     rv = self.handle_user_exception(e)
[Sat Sep 03 14:07:26.431575 2016] [:error] [pid 4144:tid 140509032990464] [client 10.0.2.2:55088]   File "/usr/local/lib/python2.7/dist-packages/flask_restful/__init__.py", line 271, in error_router
[Sat Sep 03 14:07:26.431832 2016] [:error] [pid 4144:tid 140509032990464] [client 10.0.2.2:55088]     return original_handler(e)
[Sat Sep 03 14:07:26.432070 2016] [:error] [pid 4144:tid 140509032990464] [client 10.0.2.2:55088]   File "/usr/local/lib/python2.7/dist-packages/flask/app.py", line 1544, in handle_user_exception
[Sat Sep 03 14:07:26.432394 2016] [:error] [pid 4144:tid 140509032990464] [client 10.0.2.2:55088]     reraise(exc_type, exc_value, tb)
[Sat Sep 03 14:07:26.432653 2016] [:error] [pid 4144:tid 140509032990464] [client 10.0.2.2:55088]   File "/usr/local/lib/python2.7/dist-packages/flask/app.py", line 1639, in full_dispatch_request
[Sat Sep 03 14:07:26.432907 2016] [:error] [pid 4144:tid 140509032990464] [client 10.0.2.2:55088]     rv = self.dispatch_request()
[Sat Sep 03 14:07:26.433149 2016] [:error] [pid 4144:tid 140509032990464] [client 10.0.2.2:55088]   File "/usr/local/lib/python2.7/dist-packages/flask/app.py", line 1625, in dispatch_request
[Sat Sep 03 14:07:26.433403 2016] [:error] [pid 4144:tid 140509032990464] [client 10.0.2.2:55088]     return self.view_functions[rule.endpoint](**req.view_args)
[Sat Sep 03 14:07:26.433645 2016] [:error] [pid 4144:tid 140509032990464] [client 10.0.2.2:55088]   File "/var/www/virginia/virginia.py", line 38, in ocr
[Sat Sep 03 14:07:26.437191 2016] [:error] [pid 4144:tid 140509032990464] [client 10.0.2.2:55088]     annotated_text = ''
[Sat Sep 03 14:07:26.437436 2016] [:error] [pid 4144:tid 140509032990464] [client 10.0.2.2:55088]   File "/var/www/virginia/utils/vision.py", line 44, in detect_text
[Sat Sep 03 14:07:26.441059 2016] [:error] [pid 4144:tid 140509032990464] [client 10.0.2.2:55088]     
[Sat Sep 03 14:07:26.441326 2016] [:error] [pid 4144:tid 140509032990464] [client 10.0.2.2:55088]   File "/usr/local/lib/python2.7/dist-packages/oauth2client/util.py", line 137, in positional_wrapper
[Sat Sep 03 14:07:26.441769 2016] [:error] [pid 4144:tid 140509032990464] [client 10.0.2.2:55088]     return wrapped(*args, **kwargs)
[Sat Sep 03 14:07:26.442065 2016] [:error] [pid 4144:tid 140509032990464] [client 10.0.2.2:55088]   File "/usr/local/lib/python2.7/dist-packages/googleapiclient/http.py", line 833, in execute
[Sat Sep 03 14:07:26.443065 2016] [:error] [pid 4144:tid 140509032990464] [client 10.0.2.2:55088]     method=str(self.method), body=self.body, headers=self.headers)
[Sat Sep 03 14:07:26.443451 2016] [:error] [pid 4144:tid 140509032990464] [client 10.0.2.2:55088]   File "/usr/local/lib/python2.7/dist-packages/googleapiclient/http.py", line 160, in _retry_request
[Sat Sep 03 14:07:26.443748 2016] [:error] [pid 4144:tid 140509032990464] [client 10.0.2.2:55088]     resp, content = http.request(uri, method, *args, **kwargs)
[Sat Sep 03 14:07:26.443982 2016] [:error] [pid 4144:tid 140509032990464] [client 10.0.2.2:55088]   File "/usr/local/lib/python2.7/dist-packages/oauth2client/transport.py", line 153, in new_request
[Sat Sep 03 14:07:26.444420 2016] [:error] [pid 4144:tid 140509032990464] [client 10.0.2.2:55088]     credentials._refresh(orig_request_method)
[Sat Sep 03 14:07:26.444661 2016] [:error] [pid 4144:tid 140509032990464] [client 10.0.2.2:55088]   File "/usr/local/lib/python2.7/dist-packages/oauth2client/client.py", line 765, in _refresh
[Sat Sep 03 14:07:26.445860 2016] [:error] [pid 4144:tid 140509032990464] [client 10.0.2.2:55088]     self._do_refresh_request(http_request)
[Sat Sep 03 14:07:26.446219 2016] [:error] [pid 4144:tid 140509032990464] [client 10.0.2.2:55088]   File "/usr/local/lib/python2.7/dist-packages/oauth2client/client.py", line 797, in _do_refresh_request
[Sat Sep 03 14:07:26.446477 2016] [:error] [pid 4144:tid 140509032990464] [client 10.0.2.2:55088]     self.token_uri, method='POST', body=body, headers=headers)
[Sat Sep 03 14:07:26.446739 2016] [:error] [pid 4144:tid 140509032990464] [client 10.0.2.2:55088]   File "/usr/lib/python2.7/dist-packages/httplib2/__init__.py", line 1569, in request
[Sat Sep 03 14:07:26.447831 2016] [:error] [pid 4144:tid 140509032990464] [client 10.0.2.2:55088]     (response, content) = self._request(conn, authority, uri, request_uri, method, body, headers, redirections, cachekey)
[Sat Sep 03 14:07:26.448081 2016] [:error] [pid 4144:tid 140509032990464] [client 10.0.2.2:55088]   File "/usr/lib/python2.7/dist-packages/httplib2/__init__.py", line 1316, in _request
[Sat Sep 03 14:07:26.448341 2016] [:error] [pid 4144:tid 140509032990464] [client 10.0.2.2:55088]     (response, content) = self._conn_request(conn, request_uri, method, body, headers)
[Sat Sep 03 14:07:26.448576 2016] [:error] [pid 4144:tid 140509032990464] [client 10.0.2.2:55088]   File "/usr/lib/python2.7/dist-packages/httplib2/__init__.py", line 1285, in _conn_request
[Sat Sep 03 14:07:26.448831 2016] [:error] [pid 4144:tid 140509032990464] [client 10.0.2.2:55088]     response = conn.getresponse()
[Sat Sep 03 14:07:26.449066 2016] [:error] [pid 4144:tid 140509032990464] [client 10.0.2.2:55088]   File "/usr/lib/python2.7/httplib.py", line 1039, in getresponse
[Sat Sep 03 14:07:26.449651 2016] [:error] [pid 4144:tid 140509032990464] [client 10.0.2.2:55088]     raise ResponseNotReady()
[Sat Sep 03 14:07:26.449816 2016] [:error] [pid 4144:tid 140509032990464] [client 10.0.2.2:55088] ResponseNotReady
[Sat Sep 03 14:17:29.949213 2016] [ssl:warn] [pid 4557:tid 140663797176192] AH01909: RSA certificate configured for default:443 does NOT include an ID which matches the server name
[Sat Sep 03 14:17:29.961137 2016] [ssl:warn] [pid 4558:tid 140663797176192] AH01909: RSA certificate configured for default:443 does NOT include an ID which matches the server name
[Sat Sep 03 14:19:17.946138 2016] [ssl:warn] [pid 4558:tid 140663797176192] AH01909: RSA certificate configured for default:443 does NOT include an ID which matches the server name
[Sat Sep 03 14:22:06.440874 2016] [ssl:warn] [pid 4759:tid 140639317301120] AH01909: RSA certificate configured for default:443 does NOT include an ID which matches the server name
[Sat Sep 03 14:22:06.452919 2016] [ssl:warn] [pid 4760:tid 140639317301120] AH01909: RSA certificate configured for default:443 does NOT include an ID which matches the server name
[Sat Sep 03 14:23:26.064872 2016] [ssl:warn] [pid 4760:tid 140639317301120] AH01909: RSA certificate configured for default:443 does NOT include an ID which matches the server name
